INFO:werkzeug: * Running on http://0.0.0.0:8888/ (Press CTRL+C to quit)
INFO:werkzeug: * Running on http://0.0.0.0:8888/ (Press CTRL+C to quit)
INFO:werkzeug:127.0.0.1 - - [07/Nov/2020 15:24:04] "[37mGET / HTTP/1.1[0m" 200 -
INFO:werkzeug:127.0.0.1 - - [07/Nov/2020 15:24:04] "[33mGET /favicon.ico HTTP/1.1[0m" 404 -
INFO:werkzeug:127.0.0.1 - - [07/Nov/2020 15:24:10] "[37mGET /scisat/ HTTP/1.1[0m" 200 -
INFO:werkzeug:127.0.0.1 - - [07/Nov/2020 15:24:11] "[37mGET /scisat/assets/compiled.css?m=1595963752.208345 HTTP/1.1[0m" 200 -
INFO:werkzeug:127.0.0.1 - - [07/Nov/2020 15:24:11] "[37mGET /scisat/_dash-component-suites/dash_renderer/polyfill@7.v1_5_1m1593873890.8.7.min.js HTTP/1.1[0m" 200 -
INFO:werkzeug:127.0.0.1 - - [07/Nov/2020 15:24:11] "[37mGET /scisat/_dash-component-suites/dash_renderer/react@16.v1_5_1m1593873890.13.0.min.js HTTP/1.1[0m" 200 -
INFO:werkzeug:127.0.0.1 - - [07/Nov/2020 15:24:11] "[37mGET /scisat/_dash-component-suites/dash_renderer/react-dom@16.v1_5_1m1593873890.13.0.min.js HTTP/1.1[0m" 200 -
INFO:werkzeug:127.0.0.1 - - [07/Nov/2020 15:24:11] "[37mGET /scisat/_dash-component-suites/dash_renderer/prop-types@15.v1_5_1m1593873890.7.2.min.js HTTP/1.1[0m" 200 -
INFO:werkzeug:127.0.0.1 - - [07/Nov/2020 15:24:11] "[37mGET /scisat/_dash-component-suites/dash_html_components/dash_html_components.v1_0_3m1593873891.min.js HTTP/1.1[0m" 200 -
INFO:werkzeug:127.0.0.1 - - [07/Nov/2020 15:24:11] "[37mGET /scisat/_dash-component-suites/dash_core_components/dash_core_components.v1_10_1m1593873890.min.js HTTP/1.1[0m" 200 -
INFO:werkzeug:127.0.0.1 - - [07/Nov/2020 15:24:11] "[37mGET /scisat/_dash-component-suites/dash_core_components/dash_core_components-shared.v1_10_1m1593873890.js HTTP/1.1[0m" 200 -
INFO:werkzeug:127.0.0.1 - - [07/Nov/2020 15:24:11] "[37mGET /scisat/_dash-component-suites/dash_dangerously_set_inner_html/bundle.v0_0_2m1593870401.js HTTP/1.1[0m" 200 -
INFO:werkzeug:127.0.0.1 - - [07/Nov/2020 15:24:11] "[37mGET /scisat/_dash-component-suites/dash_renderer/dash_renderer.v1_5_1m1593873890.min.js HTTP/1.1[0m" 200 -
INFO:werkzeug:127.0.0.1 - - [07/Nov/2020 15:24:12] "[37mGET /scisat/_dash-layout HTTP/1.1[0m" 200 -
INFO:werkzeug:127.0.0.1 - - [07/Nov/2020 15:24:12] "[37mGET /scisat/_dash-dependencies HTTP/1.1[0m" 200 -
INFO:werkzeug:127.0.0.1 - - [07/Nov/2020 15:24:12] "[37mGET /scisat/_favicon.ico?v=1.16.3 HTTP/1.1[0m" 200 -
ERROR:scisat_app.scisat:Exception on /_dash-update-component [POST]
Traceback (most recent call last):
  File "C:\ProgramData\Anaconda3\lib\site-packages\flask\app.py", line 2446, in wsgi_app
    response = self.full_dispatch_request()
  File "C:\ProgramData\Anaconda3\lib\site-packages\flask\app.py", line 1951, in full_dispatch_request
    rv = self.handle_user_exception(e)
  File "C:\ProgramData\Anaconda3\lib\site-packages\flask\app.py", line 1820, in handle_user_exception
    reraise(exc_type, exc_value, tb)
  File "C:\ProgramData\Anaconda3\lib\site-packages\flask\_compat.py", line 39, in reraise
    raise value
  File "C:\ProgramData\Anaconda3\lib\site-packages\flask\app.py", line 1949, in full_dispatch_request
    rv = self.dispatch_request()
  File "C:\ProgramData\Anaconda3\lib\site-packages\flask\app.py", line 1935, in dispatch_request
    return self.view_functions[rule.endpoint](**req.view_args)
  File "C:\ProgramData\Anaconda3\lib\site-packages\dash\dash.py", line 1072, in dispatch
    response.set_data(func(*args, outputs_list=outputs_list))
  File "C:\ProgramData\Anaconda3\lib\site-packages\dash\dash.py", line 1007, in add_context
    output_value = func(*args, **kwargs)  # %% callback invoked %%
  File "C:\Users\joeda\OneDrive\Documents\GitHub\Scisat-App\scisat_app\scisat.py", line 667, in update_picker
    df =data_reader(gaz_list,r'data')
  File "C:\Users\joeda\OneDrive\Documents\GitHub\Scisat-App\scisat_app\scisat.py", line 75, in data_reader
    nc = netcdf.netcdf_file(name,'r')
  File "C:\ProgramData\Anaconda3\lib\site-packages\scipy\io\netcdf.py", line 249, in __init__
    self.fp = open(self.filename, '%sb' % omode)
FileNotFoundError: [Errno 2] No such file or directory: 'data//ACEFTS_L2_v4p1_O3.nc'
INFO:werkzeug:127.0.0.1 - - [07/Nov/2020 15:24:12] "[1m[35mPOST /scisat/_dash-update-component HTTP/1.1[0m" 500 -
ERROR:scisat_app.scisat:Exception on /_dash-update-component [POST]
Traceback (most recent call last):
  File "C:\ProgramData\Anaconda3\lib\site-packages\flask\app.py", line 2446, in wsgi_app
    response = self.full_dispatch_request()
  File "C:\ProgramData\Anaconda3\lib\site-packages\flask\app.py", line 1951, in full_dispatch_request
    rv = self.handle_user_exception(e)
  File "C:\ProgramData\Anaconda3\lib\site-packages\flask\app.py", line 1820, in handle_user_exception
    reraise(exc_type, exc_value, tb)
  File "C:\ProgramData\Anaconda3\lib\site-packages\flask\_compat.py", line 39, in reraise
    raise value
  File "C:\ProgramData\Anaconda3\lib\site-packages\flask\app.py", line 1949, in full_dispatch_request
    rv = self.dispatch_request()
  File "C:\ProgramData\Anaconda3\lib\site-packages\flask\app.py", line 1935, in dispatch_request
    return self.view_functions[rule.endpoint](**req.view_args)
  File "C:\ProgramData\Anaconda3\lib\site-packages\dash\dash.py", line 1072, in dispatch
    response.set_data(func(*args, outputs_list=outputs_list))
  File "C:\ProgramData\Anaconda3\lib\site-packages\dash\dash.py", line 1007, in add_context
    output_value = func(*args, **kwargs)  # %% callback invoked %%
  File "C:\Users\joeda\OneDrive\Documents\GitHub\Scisat-App\scisat_app\scisat.py", line 1673, in update_language_button
    language = session['language']
  File "C:\ProgramData\Anaconda3\lib\site-packages\werkzeug\local.py", line 378, in <lambda>
    __getitem__ = lambda x, i: x._get_current_object()[i]
  File "C:\ProgramData\Anaconda3\lib\site-packages\flask\sessions.py", line 84, in __getitem__
    return super(SecureCookieSession, self).__getitem__(key)
KeyError: 'language'
INFO:werkzeug:127.0.0.1 - - [07/Nov/2020 15:24:12] "[1m[35mPOST /scisat/_dash-update-component HTTP/1.1[0m" 500 -
INFO:werkzeug:127.0.0.1 - - [07/Nov/2020 15:24:12] "[37mPOST /scisat/_dash-update-component HTTP/1.1[0m" 200 -
INFO:werkzeug:127.0.0.1 - - [07/Nov/2020 15:24:12] "[37mPOST /scisat/_dash-update-component HTTP/1.1[0m" 200 -
INFO:werkzeug:127.0.0.1 - - [07/Nov/2020 15:24:12] "[37mGET /scisat/assets/csa-logo.png HTTP/1.1[0m" 200 -
INFO:werkzeug:127.0.0.1 - - [07/Nov/2020 15:24:12] "[37mGET /scisat/_dash-component-suites/dash_core_components/async-dropdown.v1_10_1m1592438751.js HTTP/1.1[0m" 200 -
INFO:werkzeug:127.0.0.1 - - [07/Nov/2020 15:24:12] "[37mGET /scisat/_dash-component-suites/dash_core_components/async-plotlyjs.v1_10_1m1592438751.js HTTP/1.1[0m" 200 -
INFO:werkzeug:127.0.0.1 - - [07/Nov/2020 15:24:12] "[37mGET /scisat/_dash-component-suites/dash_core_components/async-graph.v1_10_1m1592438751.js HTTP/1.1[0m" 200 -
INFO:werkzeug:127.0.0.1 - - [07/Nov/2020 15:24:12] "[37mGET /scisat/_dash-component-suites/dash_core_components/async-datepicker.v1_10_1m1592438751.js HTTP/1.1[0m" 200 -
INFO:werkzeug:127.0.0.1 - - [07/Nov/2020 15:24:12] "[37mGET /scisat/_dash-component-suites/dash_core_components/async-slider.v1_10_1m1592438751.js HTTP/1.1[0m" 200 -
INFO:werkzeug:127.0.0.1 - - [07/Nov/2020 15:24:13] "[37mPOST /scisat/_dash-update-component HTTP/1.1[0m" 200 -
INFO:werkzeug:127.0.0.1 - - [07/Nov/2020 15:24:14] "[37mPOST /scisat/_dash-update-component HTTP/1.1[0m" 200 -
ERROR:scisat_app.scisat:Exception on /_dash-update-component [POST]
Traceback (most recent call last):
  File "C:\ProgramData\Anaconda3\lib\site-packages\flask\app.py", line 2446, in wsgi_app
    response = self.full_dispatch_request()
  File "C:\ProgramData\Anaconda3\lib\site-packages\flask\app.py", line 1951, in full_dispatch_request
    rv = self.handle_user_exception(e)
  File "C:\ProgramData\Anaconda3\lib\site-packages\flask\app.py", line 1820, in handle_user_exception
    reraise(exc_type, exc_value, tb)
  File "C:\ProgramData\Anaconda3\lib\site-packages\flask\_compat.py", line 39, in reraise
    raise value
  File "C:\ProgramData\Anaconda3\lib\site-packages\flask\app.py", line 1949, in full_dispatch_request
    rv = self.dispatch_request()
  File "C:\ProgramData\Anaconda3\lib\site-packages\flask\app.py", line 1935, in dispatch_request
    return self.view_functions[rule.endpoint](**req.view_args)
  File "C:\ProgramData\Anaconda3\lib\site-packages\dash\dash.py", line 1072, in dispatch
    response.set_data(func(*args, outputs_list=outputs_list))
  File "C:\ProgramData\Anaconda3\lib\site-packages\dash\dash.py", line 1007, in add_context
    output_value = func(*args, **kwargs)  # %% callback invoked %%
  File "C:\Users\joeda\OneDrive\Documents\GitHub\Scisat-App\scisat_app\scisat.py", line 1186, in make_viz_chart
    df =data_reader(gaz_list,r'data',start_date,end_date,lat_min,lat_max,lon_min,lon_max,alt_range)
  File "C:\Users\joeda\OneDrive\Documents\GitHub\Scisat-App\scisat_app\scisat.py", line 75, in data_reader
    nc = netcdf.netcdf_file(name,'r')
  File "C:\ProgramData\Anaconda3\lib\site-packages\scipy\io\netcdf.py", line 249, in __init__
    self.fp = open(self.filename, '%sb' % omode)
FileNotFoundError: [Errno 2] No such file or directory: 'data//ACEFTS_L2_v4p1_O3.nc'
INFO:werkzeug:127.0.0.1 - - [07/Nov/2020 15:24:14] "[1m[35mPOST /scisat/_dash-update-component HTTP/1.1[0m" 500 -
ERROR:scisat_app.scisat:Exception on /_dash-update-component [POST]
Traceback (most recent call last):
  File "C:\ProgramData\Anaconda3\lib\site-packages\flask\app.py", line 2446, in wsgi_app
    response = self.full_dispatch_request()
  File "C:\ProgramData\Anaconda3\lib\site-packages\flask\app.py", line 1951, in full_dispatch_request
    rv = self.handle_user_exception(e)
  File "C:\ProgramData\Anaconda3\lib\site-packages\flask\app.py", line 1820, in handle_user_exception
    reraise(exc_type, exc_value, tb)
  File "C:\ProgramData\Anaconda3\lib\site-packages\flask\_compat.py", line 39, in reraise
    raise value
  File "C:\ProgramData\Anaconda3\lib\site-packages\flask\app.py", line 1949, in full_dispatch_request
    rv = self.dispatch_request()
  File "C:\ProgramData\Anaconda3\lib\site-packages\flask\app.py", line 1935, in dispatch_request
    return self.view_functions[rule.endpoint](**req.view_args)
  File "C:\ProgramData\Anaconda3\lib\site-packages\dash\dash.py", line 1072, in dispatch
    response.set_data(func(*args, outputs_list=outputs_list))
  File "C:\ProgramData\Anaconda3\lib\site-packages\dash\dash.py", line 1007, in add_context
    output_value = func(*args, **kwargs)  # %% callback invoked %%
  File "C:\Users\joeda\OneDrive\Documents\GitHub\Scisat-App\scisat_app\scisat.py", line 1071, in generate_geo_map
    df = data_reader(gaz_list,r'data',start_date,end_date,lat_min,lat_max,lon_min,lon_max,alt_range)
  File "C:\Users\joeda\OneDrive\Documents\GitHub\Scisat-App\scisat_app\scisat.py", line 75, in data_reader
    nc = netcdf.netcdf_file(name,'r')
  File "C:\ProgramData\Anaconda3\lib\site-packages\scipy\io\netcdf.py", line 249, in __init__
    self.fp = open(self.filename, '%sb' % omode)
FileNotFoundError: [Errno 2] No such file or directory: 'data//ACEFTS_L2_v4p1_O3.nc'
INFO:werkzeug:127.0.0.1 - - [07/Nov/2020 15:24:14] "[1m[35mPOST /scisat/_dash-update-component HTTP/1.1[0m" 500 -
ERROR:scisat_app.scisat:Exception on /_dash-update-component [POST]
Traceback (most recent call last):
  File "C:\ProgramData\Anaconda3\lib\site-packages\flask\app.py", line 2446, in wsgi_app
    response = self.full_dispatch_request()
  File "C:\ProgramData\Anaconda3\lib\site-packages\flask\app.py", line 1951, in full_dispatch_request
    rv = self.handle_user_exception(e)
  File "C:\ProgramData\Anaconda3\lib\site-packages\flask\app.py", line 1820, in handle_user_exception
    reraise(exc_type, exc_value, tb)
  File "C:\ProgramData\Anaconda3\lib\site-packages\flask\_compat.py", line 39, in reraise
    raise value
  File "C:\ProgramData\Anaconda3\lib\site-packages\flask\app.py", line 1949, in full_dispatch_request
    rv = self.dispatch_request()
  File "C:\ProgramData\Anaconda3\lib\site-packages\flask\app.py", line 1935, in dispatch_request
    return self.view_functions[rule.endpoint](**req.view_args)
  File "C:\ProgramData\Anaconda3\lib\site-packages\dash\dash.py", line 1072, in dispatch
    response.set_data(func(*args, outputs_list=outputs_list))
  File "C:\ProgramData\Anaconda3\lib\site-packages\dash\dash.py", line 1007, in add_context
    output_value = func(*args, **kwargs)  # %% callback invoked %%
  File "C:\Users\joeda\OneDrive\Documents\GitHub\Scisat-App\scisat_app\scisat.py", line 957, in make_count_figure
    df =data_reader(gaz_list,r'data',start_date,end_date,lat_min,lat_max,lon_min,lon_max,alt_range)
  File "C:\Users\joeda\OneDrive\Documents\GitHub\Scisat-App\scisat_app\scisat.py", line 75, in data_reader
    nc = netcdf.netcdf_file(name,'r')
  File "C:\ProgramData\Anaconda3\lib\site-packages\scipy\io\netcdf.py", line 249, in __init__
    self.fp = open(self.filename, '%sb' % omode)
FileNotFoundError: [Errno 2] No such file or directory: 'data//ACEFTS_L2_v4p1_O3.nc'
INFO:werkzeug:127.0.0.1 - - [07/Nov/2020 15:24:14] "[1m[35mPOST /scisat/_dash-update-component HTTP/1.1[0m" 500 -
INFO:werkzeug:127.0.0.1 - - [07/Nov/2020 15:24:14] "[37mPOST /scisat/_dash-update-component HTTP/1.1[0m" 200 -
ERROR:scisat_app.scisat:Exception on /_dash-update-component [POST]
Traceback (most recent call last):
  File "C:\ProgramData\Anaconda3\lib\site-packages\flask\app.py", line 2446, in wsgi_app
    response = self.full_dispatch_request()
  File "C:\ProgramData\Anaconda3\lib\site-packages\flask\app.py", line 1951, in full_dispatch_request
    rv = self.handle_user_exception(e)
  File "C:\ProgramData\Anaconda3\lib\site-packages\flask\app.py", line 1820, in handle_user_exception
    reraise(exc_type, exc_value, tb)
  File "C:\ProgramData\Anaconda3\lib\site-packages\flask\_compat.py", line 39, in reraise
    raise value
  File "C:\ProgramData\Anaconda3\lib\site-packages\flask\app.py", line 1949, in full_dispatch_request
    rv = self.dispatch_request()
  File "C:\ProgramData\Anaconda3\lib\site-packages\flask\app.py", line 1935, in dispatch_request
    return self.view_functions[rule.endpoint](**req.view_args)
  File "C:\ProgramData\Anaconda3\lib\site-packages\dash\dash.py", line 1072, in dispatch
    response.set_data(func(*args, outputs_list=outputs_list))
  File "C:\ProgramData\Anaconda3\lib\site-packages\dash\dash.py", line 1007, in add_context
    output_value = func(*args, **kwargs)  # %% callback invoked %%
  File "C:\Users\joeda\OneDrive\Documents\GitHub\Scisat-App\scisat_app\scisat.py", line 652, in update_filtering_text
    df =data_reader(gaz_list,r'data',start_date,end_date,lat_min,lat_max,lon_min,lon_max,alt_range)
  File "C:\Users\joeda\OneDrive\Documents\GitHub\Scisat-App\scisat_app\scisat.py", line 75, in data_reader
    nc = netcdf.netcdf_file(name,'r')
  File "C:\ProgramData\Anaconda3\lib\site-packages\scipy\io\netcdf.py", line 249, in __init__
    self.fp = open(self.filename, '%sb' % omode)
FileNotFoundError: [Errno 2] No such file or directory: 'data//ACEFTS_L2_v4p1_O3.nc'
INFO:werkzeug:127.0.0.1 - - [07/Nov/2020 15:24:14] "[1m[35mPOST /scisat/_dash-update-component HTTP/1.1[0m" 500 -
INFO:werkzeug: * Running on http://0.0.0.0:8888/ (Press CTRL+C to quit)
INFO:werkzeug:127.0.0.1 - - [09/Nov/2020 12:29:12] "[37mGET /scisat/ HTTP/1.1[0m" 200 -
INFO:werkzeug:127.0.0.1 - - [09/Nov/2020 12:29:12] "[37mGET /scisat/assets/compiled.css?m=1595963752.208345 HTTP/1.1[0m" 200 -
INFO:werkzeug:127.0.0.1 - - [09/Nov/2020 12:29:12] "[37mGET /scisat/_dash-component-suites/dash_renderer/polyfill@7.v1_5_1m1593873890.8.7.min.js HTTP/1.1[0m" 200 -
INFO:werkzeug:127.0.0.1 - - [09/Nov/2020 12:29:12] "[37mGET /scisat/_dash-component-suites/dash_renderer/react@16.v1_5_1m1593873890.13.0.min.js HTTP/1.1[0m" 200 -
INFO:werkzeug:127.0.0.1 - - [09/Nov/2020 12:29:12] "[37mGET /scisat/_dash-component-suites/dash_renderer/react-dom@16.v1_5_1m1593873890.13.0.min.js HTTP/1.1[0m" 200 -
INFO:werkzeug:127.0.0.1 - - [09/Nov/2020 12:29:12] "[37mGET /scisat/_dash-component-suites/dash_renderer/prop-types@15.v1_5_1m1593873890.7.2.min.js HTTP/1.1[0m" 200 -
INFO:werkzeug:127.0.0.1 - - [09/Nov/2020 12:29:12] "[37mGET /scisat/_dash-component-suites/dash_dangerously_set_inner_html/bundle.v0_0_2m1593870401.js HTTP/1.1[0m" 200 -
INFO:werkzeug:127.0.0.1 - - [09/Nov/2020 12:29:12] "[37mGET /scisat/_dash-component-suites/dash_html_components/dash_html_components.v1_0_3m1593873891.min.js HTTP/1.1[0m" 200 -
INFO:werkzeug:127.0.0.1 - - [09/Nov/2020 12:29:12] "[37mGET /scisat/_dash-component-suites/dash_core_components/dash_core_components.v1_10_1m1593873890.min.js HTTP/1.1[0m" 200 -
INFO:werkzeug:127.0.0.1 - - [09/Nov/2020 12:29:12] "[37mGET /scisat/_dash-component-suites/dash_core_components/dash_core_components-shared.v1_10_1m1593873890.js HTTP/1.1[0m" 200 -
INFO:werkzeug:127.0.0.1 - - [09/Nov/2020 12:29:12] "[37mGET /scisat/_dash-component-suites/dash_renderer/dash_renderer.v1_5_1m1593873890.min.js HTTP/1.1[0m" 200 -
INFO:werkzeug:127.0.0.1 - - [09/Nov/2020 12:29:12] "[37mGET /scisat/_dash-layout HTTP/1.1[0m" 200 -
INFO:werkzeug:127.0.0.1 - - [09/Nov/2020 12:29:12] "[37mGET /scisat/_dash-dependencies HTTP/1.1[0m" 200 -
ERROR:scisat_app.scisat:Exception on /_dash-update-component [POST]
Traceback (most recent call last):
  File "C:\ProgramData\Anaconda3\lib\site-packages\flask\app.py", line 2446, in wsgi_app
    response = self.full_dispatch_request()
  File "C:\ProgramData\Anaconda3\lib\site-packages\flask\app.py", line 1951, in full_dispatch_request
    rv = self.handle_user_exception(e)
  File "C:\ProgramData\Anaconda3\lib\site-packages\flask\app.py", line 1820, in handle_user_exception
    reraise(exc_type, exc_value, tb)
  File "C:\ProgramData\Anaconda3\lib\site-packages\flask\_compat.py", line 39, in reraise
    raise value
  File "C:\ProgramData\Anaconda3\lib\site-packages\flask\app.py", line 1949, in full_dispatch_request
    rv = self.dispatch_request()
  File "C:\ProgramData\Anaconda3\lib\site-packages\flask\app.py", line 1935, in dispatch_request
    return self.view_functions[rule.endpoint](**req.view_args)
  File "C:\ProgramData\Anaconda3\lib\site-packages\dash\dash.py", line 1072, in dispatch
    response.set_data(func(*args, outputs_list=outputs_list))
  File "C:\ProgramData\Anaconda3\lib\site-packages\dash\dash.py", line 1007, in add_context
    output_value = func(*args, **kwargs)  # %% callback invoked %%
  File "C:\Users\joeda\OneDrive\Documents\GitHub\Scisat-App\scisat_app\scisat.py", line 671, in update_picker
    df =data_reader(gaz_list,r'data')
  File "C:\Users\joeda\OneDrive\Documents\GitHub\Scisat-App\scisat_app\scisat.py", line 75, in data_reader
    nc = netcdf.netcdf_file(name,'r')
  File "C:\ProgramData\Anaconda3\lib\site-packages\scipy\io\netcdf.py", line 249, in __init__
    self.fp = open(self.filename, '%sb' % omode)
FileNotFoundError: [Errno 2] No such file or directory: 'data//ACEFTS_L2_v4p1_O3.nc'
INFO:werkzeug:127.0.0.1 - - [09/Nov/2020 12:29:12] "[1m[35mPOST /scisat/_dash-update-component HTTP/1.1[0m" 500 -
ERROR:scisat_app.scisat:Exception on /_dash-update-component [POST]
Traceback (most recent call last):
  File "C:\ProgramData\Anaconda3\lib\site-packages\flask\app.py", line 2446, in wsgi_app
    response = self.full_dispatch_request()
  File "C:\ProgramData\Anaconda3\lib\site-packages\flask\app.py", line 1951, in full_dispatch_request
    rv = self.handle_user_exception(e)
  File "C:\ProgramData\Anaconda3\lib\site-packages\flask\app.py", line 1820, in handle_user_exception
    reraise(exc_type, exc_value, tb)
  File "C:\ProgramData\Anaconda3\lib\site-packages\flask\_compat.py", line 39, in reraise
    raise value
  File "C:\ProgramData\Anaconda3\lib\site-packages\flask\app.py", line 1949, in full_dispatch_request
    rv = self.dispatch_request()
  File "C:\ProgramData\Anaconda3\lib\site-packages\flask\app.py", line 1935, in dispatch_request
    return self.view_functions[rule.endpoint](**req.view_args)
  File "C:\ProgramData\Anaconda3\lib\site-packages\dash\dash.py", line 1072, in dispatch
    response.set_data(func(*args, outputs_list=outputs_list))
  File "C:\ProgramData\Anaconda3\lib\site-packages\dash\dash.py", line 1007, in add_context
    output_value = func(*args, **kwargs)  # %% callback invoked %%
  File "C:\Users\joeda\OneDrive\Documents\GitHub\Scisat-App\scisat_app\scisat.py", line 1677, in update_language_button
    language = session['language']
  File "C:\ProgramData\Anaconda3\lib\site-packages\werkzeug\local.py", line 378, in <lambda>
    __getitem__ = lambda x, i: x._get_current_object()[i]
  File "C:\ProgramData\Anaconda3\lib\site-packages\flask\sessions.py", line 84, in __getitem__
    return super(SecureCookieSession, self).__getitem__(key)
KeyError: 'language'
INFO:werkzeug:127.0.0.1 - - [09/Nov/2020 12:29:12] "[1m[35mPOST /scisat/_dash-update-component HTTP/1.1[0m" 500 -
INFO:werkzeug:127.0.0.1 - - [09/Nov/2020 12:29:12] "[37mPOST /scisat/_dash-update-component HTTP/1.1[0m" 200 -
INFO:werkzeug:127.0.0.1 - - [09/Nov/2020 12:29:12] "[37mPOST /scisat/_dash-update-component HTTP/1.1[0m" 200 -
INFO:werkzeug:127.0.0.1 - - [09/Nov/2020 12:29:12] "[37mGET /scisat/assets/csa-logo.png HTTP/1.1[0m" 200 -
INFO:werkzeug:127.0.0.1 - - [09/Nov/2020 12:29:12] "[37mGET /scisat/_dash-component-suites/dash_core_components/async-dropdown.v1_10_1m1592438751.js HTTP/1.1[0m" 200 -
INFO:werkzeug:127.0.0.1 - - [09/Nov/2020 12:29:12] "[37mGET /scisat/_dash-component-suites/dash_core_components/async-plotlyjs.v1_10_1m1592438751.js HTTP/1.1[0m" 200 -
INFO:werkzeug:127.0.0.1 - - [09/Nov/2020 12:29:12] "[37mGET /scisat/_dash-component-suites/dash_core_components/async-graph.v1_10_1m1592438751.js HTTP/1.1[0m" 200 -
INFO:werkzeug:127.0.0.1 - - [09/Nov/2020 12:29:12] "[37mGET /scisat/_dash-component-suites/dash_core_components/async-datepicker.v1_10_1m1592438751.js HTTP/1.1[0m" 200 -
INFO:werkzeug:127.0.0.1 - - [09/Nov/2020 12:29:12] "[37mGET /scisat/_dash-component-suites/dash_core_components/async-slider.v1_10_1m1592438751.js HTTP/1.1[0m" 200 -
INFO:werkzeug:127.0.0.1 - - [09/Nov/2020 12:29:13] "[37mGET /scisat/_favicon.ico?v=1.16.3 HTTP/1.1[0m" 200 -
INFO:werkzeug:127.0.0.1 - - [09/Nov/2020 12:29:13] "[37mPOST /scisat/_dash-update-component HTTP/1.1[0m" 200 -
INFO:werkzeug:127.0.0.1 - - [09/Nov/2020 12:29:13] "[37mPOST /scisat/_dash-update-component HTTP/1.1[0m" 200 -
ERROR:scisat_app.scisat:Exception on /_dash-update-component [POST]
Traceback (most recent call last):
  File "C:\ProgramData\Anaconda3\lib\site-packages\flask\app.py", line 2446, in wsgi_app
    response = self.full_dispatch_request()
  File "C:\ProgramData\Anaconda3\lib\site-packages\flask\app.py", line 1951, in full_dispatch_request
    rv = self.handle_user_exception(e)
  File "C:\ProgramData\Anaconda3\lib\site-packages\flask\app.py", line 1820, in handle_user_exception
    reraise(exc_type, exc_value, tb)
  File "C:\ProgramData\Anaconda3\lib\site-packages\flask\_compat.py", line 39, in reraise
    raise value
  File "C:\ProgramData\Anaconda3\lib\site-packages\flask\app.py", line 1949, in full_dispatch_request
    rv = self.dispatch_request()
  File "C:\ProgramData\Anaconda3\lib\site-packages\flask\app.py", line 1935, in dispatch_request
    return self.view_functions[rule.endpoint](**req.view_args)
  File "C:\ProgramData\Anaconda3\lib\site-packages\dash\dash.py", line 1072, in dispatch
    response.set_data(func(*args, outputs_list=outputs_list))
  File "C:\ProgramData\Anaconda3\lib\site-packages\dash\dash.py", line 1007, in add_context
    output_value = func(*args, **kwargs)  # %% callback invoked %%
  File "C:\Users\joeda\OneDrive\Documents\GitHub\Scisat-App\scisat_app\scisat.py", line 1190, in make_viz_chart
    df =data_reader(gaz_list,r'data',start_date,end_date,lat_min,lat_max,lon_min,lon_max,alt_range)
  File "C:\Users\joeda\OneDrive\Documents\GitHub\Scisat-App\scisat_app\scisat.py", line 75, in data_reader
    nc = netcdf.netcdf_file(name,'r')
  File "C:\ProgramData\Anaconda3\lib\site-packages\scipy\io\netcdf.py", line 249, in __init__
    self.fp = open(self.filename, '%sb' % omode)
FileNotFoundError: [Errno 2] No such file or directory: 'data//ACEFTS_L2_v4p1_O3.nc'
INFO:werkzeug:127.0.0.1 - - [09/Nov/2020 12:29:13] "[1m[35mPOST /scisat/_dash-update-component HTTP/1.1[0m" 500 -
ERROR:scisat_app.scisat:Exception on /_dash-update-component [POST]
Traceback (most recent call last):
  File "C:\ProgramData\Anaconda3\lib\site-packages\flask\app.py", line 2446, in wsgi_app
    response = self.full_dispatch_request()
  File "C:\ProgramData\Anaconda3\lib\site-packages\flask\app.py", line 1951, in full_dispatch_request
    rv = self.handle_user_exception(e)
  File "C:\ProgramData\Anaconda3\lib\site-packages\flask\app.py", line 1820, in handle_user_exception
    reraise(exc_type, exc_value, tb)
  File "C:\ProgramData\Anaconda3\lib\site-packages\flask\_compat.py", line 39, in reraise
    raise value
  File "C:\ProgramData\Anaconda3\lib\site-packages\flask\app.py", line 1949, in full_dispatch_request
    rv = self.dispatch_request()
  File "C:\ProgramData\Anaconda3\lib\site-packages\flask\app.py", line 1935, in dispatch_request
    return self.view_functions[rule.endpoint](**req.view_args)
  File "C:\ProgramData\Anaconda3\lib\site-packages\dash\dash.py", line 1072, in dispatch
    response.set_data(func(*args, outputs_list=outputs_list))
  File "C:\ProgramData\Anaconda3\lib\site-packages\dash\dash.py", line 1007, in add_context
    output_value = func(*args, **kwargs)  # %% callback invoked %%
  File "C:\Users\joeda\OneDrive\Documents\GitHub\Scisat-App\scisat_app\scisat.py", line 1075, in generate_geo_map
    df = data_reader(gaz_list,r'data',start_date,end_date,lat_min,lat_max,lon_min,lon_max,alt_range)
  File "C:\Users\joeda\OneDrive\Documents\GitHub\Scisat-App\scisat_app\scisat.py", line 75, in data_reader
    nc = netcdf.netcdf_file(name,'r')
  File "C:\ProgramData\Anaconda3\lib\site-packages\scipy\io\netcdf.py", line 249, in __init__
    self.fp = open(self.filename, '%sb' % omode)
FileNotFoundError: [Errno 2] No such file or directory: 'data//ACEFTS_L2_v4p1_O3.nc'
INFO:werkzeug:127.0.0.1 - - [09/Nov/2020 12:29:13] "[1m[35mPOST /scisat/_dash-update-component HTTP/1.1[0m" 500 -
ERROR:scisat_app.scisat:Exception on /_dash-update-component [POST]
Traceback (most recent call last):
  File "C:\ProgramData\Anaconda3\lib\site-packages\flask\app.py", line 2446, in wsgi_app
    response = self.full_dispatch_request()
  File "C:\ProgramData\Anaconda3\lib\site-packages\flask\app.py", line 1951, in full_dispatch_request
    rv = self.handle_user_exception(e)
  File "C:\ProgramData\Anaconda3\lib\site-packages\flask\app.py", line 1820, in handle_user_exception
    reraise(exc_type, exc_value, tb)
  File "C:\ProgramData\Anaconda3\lib\site-packages\flask\_compat.py", line 39, in reraise
    raise value
  File "C:\ProgramData\Anaconda3\lib\site-packages\flask\app.py", line 1949, in full_dispatch_request
    rv = self.dispatch_request()
  File "C:\ProgramData\Anaconda3\lib\site-packages\flask\app.py", line 1935, in dispatch_request
    return self.view_functions[rule.endpoint](**req.view_args)
  File "C:\ProgramData\Anaconda3\lib\site-packages\dash\dash.py", line 1072, in dispatch
    response.set_data(func(*args, outputs_list=outputs_list))
  File "C:\ProgramData\Anaconda3\lib\site-packages\dash\dash.py", line 1007, in add_context
    output_value = func(*args, **kwargs)  # %% callback invoked %%
  File "C:\Users\joeda\OneDrive\Documents\GitHub\Scisat-App\scisat_app\scisat.py", line 961, in make_count_figure
    df =data_reader(gaz_list,r'data',start_date,end_date,lat_min,lat_max,lon_min,lon_max,alt_range)
  File "C:\Users\joeda\OneDrive\Documents\GitHub\Scisat-App\scisat_app\scisat.py", line 75, in data_reader
    nc = netcdf.netcdf_file(name,'r')
  File "C:\ProgramData\Anaconda3\lib\site-packages\scipy\io\netcdf.py", line 249, in __init__
    self.fp = open(self.filename, '%sb' % omode)
FileNotFoundError: [Errno 2] No such file or directory: 'data//ACEFTS_L2_v4p1_O3.nc'
INFO:werkzeug:127.0.0.1 - - [09/Nov/2020 12:29:13] "[1m[35mPOST /scisat/_dash-update-component HTTP/1.1[0m" 500 -
INFO:werkzeug:127.0.0.1 - - [09/Nov/2020 12:29:13] "[37mPOST /scisat/_dash-update-component HTTP/1.1[0m" 200 -
ERROR:scisat_app.scisat:Exception on /_dash-update-component [POST]
Traceback (most recent call last):
  File "C:\ProgramData\Anaconda3\lib\site-packages\flask\app.py", line 2446, in wsgi_app
    response = self.full_dispatch_request()
  File "C:\ProgramData\Anaconda3\lib\site-packages\flask\app.py", line 1951, in full_dispatch_request
    rv = self.handle_user_exception(e)
  File "C:\ProgramData\Anaconda3\lib\site-packages\flask\app.py", line 1820, in handle_user_exception
    reraise(exc_type, exc_value, tb)
  File "C:\ProgramData\Anaconda3\lib\site-packages\flask\_compat.py", line 39, in reraise
    raise value
  File "C:\ProgramData\Anaconda3\lib\site-packages\flask\app.py", line 1949, in full_dispatch_request
    rv = self.dispatch_request()
  File "C:\ProgramData\Anaconda3\lib\site-packages\flask\app.py", line 1935, in dispatch_request
    return self.view_functions[rule.endpoint](**req.view_args)
  File "C:\ProgramData\Anaconda3\lib\site-packages\dash\dash.py", line 1072, in dispatch
    response.set_data(func(*args, outputs_list=outputs_list))
  File "C:\ProgramData\Anaconda3\lib\site-packages\dash\dash.py", line 1007, in add_context
    output_value = func(*args, **kwargs)  # %% callback invoked %%
  File "C:\Users\joeda\OneDrive\Documents\GitHub\Scisat-App\scisat_app\scisat.py", line 656, in update_filtering_text
    df =data_reader(gaz_list,r'data',start_date,end_date,lat_min,lat_max,lon_min,lon_max,alt_range)
  File "C:\Users\joeda\OneDrive\Documents\GitHub\Scisat-App\scisat_app\scisat.py", line 75, in data_reader
    nc = netcdf.netcdf_file(name,'r')
  File "C:\ProgramData\Anaconda3\lib\site-packages\scipy\io\netcdf.py", line 249, in __init__
    self.fp = open(self.filename, '%sb' % omode)
FileNotFoundError: [Errno 2] No such file or directory: 'data//ACEFTS_L2_v4p1_O3.nc'
INFO:werkzeug:127.0.0.1 - - [09/Nov/2020 12:29:13] "[1m[35mPOST /scisat/_dash-update-component HTTP/1.1[0m" 500 -
INFO:werkzeug:127.0.0.1 - - [09/Nov/2020 12:32:16] "[37mGET /scisat/assets/compiled.css?m=1595963752.208345 HTTP/1.1[0m" 200 -
ERROR:scisat_app.scisat:Exception on /_dash-update-component [POST]
Traceback (most recent call last):
  File "C:\ProgramData\Anaconda3\lib\site-packages\flask\app.py", line 2446, in wsgi_app
    response = self.full_dispatch_request()
  File "C:\ProgramData\Anaconda3\lib\site-packages\flask\app.py", line 1951, in full_dispatch_request
    rv = self.handle_user_exception(e)
  File "C:\ProgramData\Anaconda3\lib\site-packages\flask\app.py", line 1820, in handle_user_exception
    reraise(exc_type, exc_value, tb)
  File "C:\ProgramData\Anaconda3\lib\site-packages\flask\_compat.py", line 39, in reraise
    raise value
  File "C:\ProgramData\Anaconda3\lib\site-packages\flask\app.py", line 1949, in full_dispatch_request
    rv = self.dispatch_request()
  File "C:\ProgramData\Anaconda3\lib\site-packages\flask\app.py", line 1935, in dispatch_request
    return self.view_functions[rule.endpoint](**req.view_args)
  File "C:\ProgramData\Anaconda3\lib\site-packages\dash\dash.py", line 1072, in dispatch
    response.set_data(func(*args, outputs_list=outputs_list))
  File "C:\ProgramData\Anaconda3\lib\site-packages\dash\dash.py", line 1007, in add_context
    output_value = func(*args, **kwargs)  # %% callback invoked %%
  File "C:\Users\joeda\OneDrive\Documents\GitHub\Scisat-App\scisat_app\scisat.py", line 671, in update_picker
    df =data_reader(gaz_list,r'data')
  File "C:\Users\joeda\OneDrive\Documents\GitHub\Scisat-App\scisat_app\scisat.py", line 75, in data_reader
    nc = netcdf.netcdf_file(name,'r')
  File "C:\ProgramData\Anaconda3\lib\site-packages\scipy\io\netcdf.py", line 249, in __init__
    self.fp = open(self.filename, '%sb' % omode)
FileNotFoundError: [Errno 2] No such file or directory: 'data//ACEFTS_L2_v4p1_NO2.nc'
INFO:werkzeug:127.0.0.1 - - [09/Nov/2020 12:32:30] "[1m[35mPOST /scisat/_dash-update-component HTTP/1.1[0m" 500 -
ERROR:scisat_app.scisat:Exception on /_dash-update-component [POST]
Traceback (most recent call last):
  File "C:\ProgramData\Anaconda3\lib\site-packages\flask\app.py", line 2446, in wsgi_app
    response = self.full_dispatch_request()
  File "C:\ProgramData\Anaconda3\lib\site-packages\flask\app.py", line 1951, in full_dispatch_request
    rv = self.handle_user_exception(e)
  File "C:\ProgramData\Anaconda3\lib\site-packages\flask\app.py", line 1820, in handle_user_exception
    reraise(exc_type, exc_value, tb)
  File "C:\ProgramData\Anaconda3\lib\site-packages\flask\_compat.py", line 39, in reraise
    raise value
  File "C:\ProgramData\Anaconda3\lib\site-packages\flask\app.py", line 1949, in full_dispatch_request
    rv = self.dispatch_request()
  File "C:\ProgramData\Anaconda3\lib\site-packages\flask\app.py", line 1935, in dispatch_request
    return self.view_functions[rule.endpoint](**req.view_args)
  File "C:\ProgramData\Anaconda3\lib\site-packages\dash\dash.py", line 1072, in dispatch
    response.set_data(func(*args, outputs_list=outputs_list))
  File "C:\ProgramData\Anaconda3\lib\site-packages\dash\dash.py", line 1007, in add_context
    output_value = func(*args, **kwargs)  # %% callback invoked %%
  File "C:\Users\joeda\OneDrive\Documents\GitHub\Scisat-App\scisat_app\scisat.py", line 1190, in make_viz_chart
    df =data_reader(gaz_list,r'data',start_date,end_date,lat_min,lat_max,lon_min,lon_max,alt_range)
  File "C:\Users\joeda\OneDrive\Documents\GitHub\Scisat-App\scisat_app\scisat.py", line 75, in data_reader
    nc = netcdf.netcdf_file(name,'r')
  File "C:\ProgramData\Anaconda3\lib\site-packages\scipy\io\netcdf.py", line 249, in __init__
    self.fp = open(self.filename, '%sb' % omode)
FileNotFoundError: [Errno 2] No such file or directory: 'data//ACEFTS_L2_v4p1_NO2.nc'
INFO:werkzeug:127.0.0.1 - - [09/Nov/2020 12:32:30] "[1m[35mPOST /scisat/_dash-update-component HTTP/1.1[0m" 500 -
ERROR:scisat_app.scisat:Exception on /_dash-update-component [POST]
Traceback (most recent call last):
  File "C:\ProgramData\Anaconda3\lib\site-packages\flask\app.py", line 2446, in wsgi_app
    response = self.full_dispatch_request()
  File "C:\ProgramData\Anaconda3\lib\site-packages\flask\app.py", line 1951, in full_dispatch_request
    rv = self.handle_user_exception(e)
  File "C:\ProgramData\Anaconda3\lib\site-packages\flask\app.py", line 1820, in handle_user_exception
    reraise(exc_type, exc_value, tb)
  File "C:\ProgramData\Anaconda3\lib\site-packages\flask\_compat.py", line 39, in reraise
    raise value
  File "C:\ProgramData\Anaconda3\lib\site-packages\flask\app.py", line 1949, in full_dispatch_request
    rv = self.dispatch_request()
  File "C:\ProgramData\Anaconda3\lib\site-packages\flask\app.py", line 1935, in dispatch_request
    return self.view_functions[rule.endpoint](**req.view_args)
  File "C:\ProgramData\Anaconda3\lib\site-packages\dash\dash.py", line 1072, in dispatch
    response.set_data(func(*args, outputs_list=outputs_list))
  File "C:\ProgramData\Anaconda3\lib\site-packages\dash\dash.py", line 1007, in add_context
    output_value = func(*args, **kwargs)  # %% callback invoked %%
  File "C:\Users\joeda\OneDrive\Documents\GitHub\Scisat-App\scisat_app\scisat.py", line 1075, in generate_geo_map
    df = data_reader(gaz_list,r'data',start_date,end_date,lat_min,lat_max,lon_min,lon_max,alt_range)
  File "C:\Users\joeda\OneDrive\Documents\GitHub\Scisat-App\scisat_app\scisat.py", line 75, in data_reader
    nc = netcdf.netcdf_file(name,'r')
  File "C:\ProgramData\Anaconda3\lib\site-packages\scipy\io\netcdf.py", line 249, in __init__
    self.fp = open(self.filename, '%sb' % omode)
FileNotFoundError: [Errno 2] No such file or directory: 'data//ACEFTS_L2_v4p1_NO2.nc'
INFO:werkzeug:127.0.0.1 - - [09/Nov/2020 12:32:30] "[1m[35mPOST /scisat/_dash-update-component HTTP/1.1[0m" 500 -
ERROR:scisat_app.scisat:Exception on /_dash-update-component [POST]
Traceback (most recent call last):
  File "C:\ProgramData\Anaconda3\lib\site-packages\flask\app.py", line 2446, in wsgi_app
    response = self.full_dispatch_request()
  File "C:\ProgramData\Anaconda3\lib\site-packages\flask\app.py", line 1951, in full_dispatch_request
    rv = self.handle_user_exception(e)
  File "C:\ProgramData\Anaconda3\lib\site-packages\flask\app.py", line 1820, in handle_user_exception
    reraise(exc_type, exc_value, tb)
  File "C:\ProgramData\Anaconda3\lib\site-packages\flask\_compat.py", line 39, in reraise
    raise value
  File "C:\ProgramData\Anaconda3\lib\site-packages\flask\app.py", line 1949, in full_dispatch_request
    rv = self.dispatch_request()
  File "C:\ProgramData\Anaconda3\lib\site-packages\flask\app.py", line 1935, in dispatch_request
    return self.view_functions[rule.endpoint](**req.view_args)
  File "C:\ProgramData\Anaconda3\lib\site-packages\dash\dash.py", line 1072, in dispatch
    response.set_data(func(*args, outputs_list=outputs_list))
  File "C:\ProgramData\Anaconda3\lib\site-packages\dash\dash.py", line 1007, in add_context
    output_value = func(*args, **kwargs)  # %% callback invoked %%
  File "C:\Users\joeda\OneDrive\Documents\GitHub\Scisat-App\scisat_app\scisat.py", line 961, in make_count_figure
    df =data_reader(gaz_list,r'data',start_date,end_date,lat_min,lat_max,lon_min,lon_max,alt_range)
  File "C:\Users\joeda\OneDrive\Documents\GitHub\Scisat-App\scisat_app\scisat.py", line 75, in data_reader
    nc = netcdf.netcdf_file(name,'r')
  File "C:\ProgramData\Anaconda3\lib\site-packages\scipy\io\netcdf.py", line 249, in __init__
    self.fp = open(self.filename, '%sb' % omode)
FileNotFoundError: [Errno 2] No such file or directory: 'data//ACEFTS_L2_v4p1_NO2.nc'
INFO:werkzeug:127.0.0.1 - - [09/Nov/2020 12:32:30] "[1m[35mPOST /scisat/_dash-update-component HTTP/1.1[0m" 500 -
INFO:werkzeug:127.0.0.1 - - [09/Nov/2020 12:32:30] "[37mPOST /scisat/_dash-update-component HTTP/1.1[0m" 200 -
ERROR:scisat_app.scisat:Exception on /_dash-update-component [POST]
Traceback (most recent call last):
  File "C:\ProgramData\Anaconda3\lib\site-packages\flask\app.py", line 2446, in wsgi_app
    response = self.full_dispatch_request()
  File "C:\ProgramData\Anaconda3\lib\site-packages\flask\app.py", line 1951, in full_dispatch_request
    rv = self.handle_user_exception(e)
  File "C:\ProgramData\Anaconda3\lib\site-packages\flask\app.py", line 1820, in handle_user_exception
    reraise(exc_type, exc_value, tb)
  File "C:\ProgramData\Anaconda3\lib\site-packages\flask\_compat.py", line 39, in reraise
    raise value
  File "C:\ProgramData\Anaconda3\lib\site-packages\flask\app.py", line 1949, in full_dispatch_request
    rv = self.dispatch_request()
  File "C:\ProgramData\Anaconda3\lib\site-packages\flask\app.py", line 1935, in dispatch_request
    return self.view_functions[rule.endpoint](**req.view_args)
  File "C:\ProgramData\Anaconda3\lib\site-packages\dash\dash.py", line 1072, in dispatch
    response.set_data(func(*args, outputs_list=outputs_list))
  File "C:\ProgramData\Anaconda3\lib\site-packages\dash\dash.py", line 1007, in add_context
    output_value = func(*args, **kwargs)  # %% callback invoked %%
  File "C:\Users\joeda\OneDrive\Documents\GitHub\Scisat-App\scisat_app\scisat.py", line 656, in update_filtering_text
    df =data_reader(gaz_list,r'data',start_date,end_date,lat_min,lat_max,lon_min,lon_max,alt_range)
  File "C:\Users\joeda\OneDrive\Documents\GitHub\Scisat-App\scisat_app\scisat.py", line 75, in data_reader
    nc = netcdf.netcdf_file(name,'r')
  File "C:\ProgramData\Anaconda3\lib\site-packages\scipy\io\netcdf.py", line 249, in __init__
    self.fp = open(self.filename, '%sb' % omode)
FileNotFoundError: [Errno 2] No such file or directory: 'data//ACEFTS_L2_v4p1_NO2.nc'
INFO:werkzeug:127.0.0.1 - - [09/Nov/2020 12:32:30] "[1m[35mPOST /scisat/_dash-update-component HTTP/1.1[0m" 500 -
ERROR:scisat_app.scisat:Exception on /_dash-update-component [POST]
Traceback (most recent call last):
  File "C:\ProgramData\Anaconda3\lib\site-packages\flask\app.py", line 2446, in wsgi_app
    response = self.full_dispatch_request()
  File "C:\ProgramData\Anaconda3\lib\site-packages\flask\app.py", line 1951, in full_dispatch_request
    rv = self.handle_user_exception(e)
  File "C:\ProgramData\Anaconda3\lib\site-packages\flask\app.py", line 1820, in handle_user_exception
    reraise(exc_type, exc_value, tb)
  File "C:\ProgramData\Anaconda3\lib\site-packages\flask\_compat.py", line 39, in reraise
    raise value
  File "C:\ProgramData\Anaconda3\lib\site-packages\flask\app.py", line 1949, in full_dispatch_request
    rv = self.dispatch_request()
  File "C:\ProgramData\Anaconda3\lib\site-packages\flask\app.py", line 1935, in dispatch_request
    return self.view_functions[rule.endpoint](**req.view_args)
  File "C:\ProgramData\Anaconda3\lib\site-packages\dash\dash.py", line 1072, in dispatch
    response.set_data(func(*args, outputs_list=outputs_list))
  File "C:\ProgramData\Anaconda3\lib\site-packages\dash\dash.py", line 1007, in add_context
    output_value = func(*args, **kwargs)  # %% callback invoked %%
  File "C:\Users\joeda\OneDrive\Documents\GitHub\Scisat-App\scisat_app\scisat.py", line 671, in update_picker
    df =data_reader(gaz_list,r'data')
  File "C:\Users\joeda\OneDrive\Documents\GitHub\Scisat-App\scisat_app\scisat.py", line 75, in data_reader
    nc = netcdf.netcdf_file(name,'r')
  File "C:\ProgramData\Anaconda3\lib\site-packages\scipy\io\netcdf.py", line 249, in __init__
    self.fp = open(self.filename, '%sb' % omode)
FileNotFoundError: [Errno 2] No such file or directory: 'data//ACEFTS_L2_v4p1_O3.nc'
INFO:werkzeug:127.0.0.1 - - [09/Nov/2020 12:32:45] "[1m[35mPOST /scisat/_dash-update-component HTTP/1.1[0m" 500 -
ERROR:scisat_app.scisat:Exception on /_dash-update-component [POST]
Traceback (most recent call last):
  File "C:\ProgramData\Anaconda3\lib\site-packages\flask\app.py", line 2446, in wsgi_app
    response = self.full_dispatch_request()
  File "C:\ProgramData\Anaconda3\lib\site-packages\flask\app.py", line 1951, in full_dispatch_request
    rv = self.handle_user_exception(e)
  File "C:\ProgramData\Anaconda3\lib\site-packages\flask\app.py", line 1820, in handle_user_exception
    reraise(exc_type, exc_value, tb)
  File "C:\ProgramData\Anaconda3\lib\site-packages\flask\_compat.py", line 39, in reraise
    raise value
  File "C:\ProgramData\Anaconda3\lib\site-packages\flask\app.py", line 1949, in full_dispatch_request
    rv = self.dispatch_request()
  File "C:\ProgramData\Anaconda3\lib\site-packages\flask\app.py", line 1935, in dispatch_request
    return self.view_functions[rule.endpoint](**req.view_args)
  File "C:\ProgramData\Anaconda3\lib\site-packages\dash\dash.py", line 1072, in dispatch
    response.set_data(func(*args, outputs_list=outputs_list))
  File "C:\ProgramData\Anaconda3\lib\site-packages\dash\dash.py", line 1007, in add_context
    output_value = func(*args, **kwargs)  # %% callback invoked %%
  File "C:\Users\joeda\OneDrive\Documents\GitHub\Scisat-App\scisat_app\scisat.py", line 1190, in make_viz_chart
    df =data_reader(gaz_list,r'data',start_date,end_date,lat_min,lat_max,lon_min,lon_max,alt_range)
  File "C:\Users\joeda\OneDrive\Documents\GitHub\Scisat-App\scisat_app\scisat.py", line 75, in data_reader
    nc = netcdf.netcdf_file(name,'r')
  File "C:\ProgramData\Anaconda3\lib\site-packages\scipy\io\netcdf.py", line 249, in __init__
    self.fp = open(self.filename, '%sb' % omode)
FileNotFoundError: [Errno 2] No such file or directory: 'data//ACEFTS_L2_v4p1_O3.nc'
INFO:werkzeug:127.0.0.1 - - [09/Nov/2020 12:32:45] "[1m[35mPOST /scisat/_dash-update-component HTTP/1.1[0m" 500 -
ERROR:scisat_app.scisat:Exception on /_dash-update-component [POST]
Traceback (most recent call last):
  File "C:\ProgramData\Anaconda3\lib\site-packages\flask\app.py", line 2446, in wsgi_app
    response = self.full_dispatch_request()
  File "C:\ProgramData\Anaconda3\lib\site-packages\flask\app.py", line 1951, in full_dispatch_request
    rv = self.handle_user_exception(e)
  File "C:\ProgramData\Anaconda3\lib\site-packages\flask\app.py", line 1820, in handle_user_exception
    reraise(exc_type, exc_value, tb)
  File "C:\ProgramData\Anaconda3\lib\site-packages\flask\_compat.py", line 39, in reraise
    raise value
  File "C:\ProgramData\Anaconda3\lib\site-packages\flask\app.py", line 1949, in full_dispatch_request
    rv = self.dispatch_request()
  File "C:\ProgramData\Anaconda3\lib\site-packages\flask\app.py", line 1935, in dispatch_request
    return self.view_functions[rule.endpoint](**req.view_args)
  File "C:\ProgramData\Anaconda3\lib\site-packages\dash\dash.py", line 1072, in dispatch
    response.set_data(func(*args, outputs_list=outputs_list))
  File "C:\ProgramData\Anaconda3\lib\site-packages\dash\dash.py", line 1007, in add_context
    output_value = func(*args, **kwargs)  # %% callback invoked %%
  File "C:\Users\joeda\OneDrive\Documents\GitHub\Scisat-App\scisat_app\scisat.py", line 1075, in generate_geo_map
    df = data_reader(gaz_list,r'data',start_date,end_date,lat_min,lat_max,lon_min,lon_max,alt_range)
  File "C:\Users\joeda\OneDrive\Documents\GitHub\Scisat-App\scisat_app\scisat.py", line 75, in data_reader
    nc = netcdf.netcdf_file(name,'r')
  File "C:\ProgramData\Anaconda3\lib\site-packages\scipy\io\netcdf.py", line 249, in __init__
    self.fp = open(self.filename, '%sb' % omode)
FileNotFoundError: [Errno 2] No such file or directory: 'data//ACEFTS_L2_v4p1_O3.nc'
INFO:werkzeug:127.0.0.1 - - [09/Nov/2020 12:32:45] "[1m[35mPOST /scisat/_dash-update-component HTTP/1.1[0m" 500 -
ERROR:scisat_app.scisat:Exception on /_dash-update-component [POST]
Traceback (most recent call last):
  File "C:\ProgramData\Anaconda3\lib\site-packages\flask\app.py", line 2446, in wsgi_app
    response = self.full_dispatch_request()
  File "C:\ProgramData\Anaconda3\lib\site-packages\flask\app.py", line 1951, in full_dispatch_request
    rv = self.handle_user_exception(e)
  File "C:\ProgramData\Anaconda3\lib\site-packages\flask\app.py", line 1820, in handle_user_exception
    reraise(exc_type, exc_value, tb)
  File "C:\ProgramData\Anaconda3\lib\site-packages\flask\_compat.py", line 39, in reraise
    raise value
  File "C:\ProgramData\Anaconda3\lib\site-packages\flask\app.py", line 1949, in full_dispatch_request
    rv = self.dispatch_request()
  File "C:\ProgramData\Anaconda3\lib\site-packages\flask\app.py", line 1935, in dispatch_request
    return self.view_functions[rule.endpoint](**req.view_args)
  File "C:\ProgramData\Anaconda3\lib\site-packages\dash\dash.py", line 1072, in dispatch
    response.set_data(func(*args, outputs_list=outputs_list))
  File "C:\ProgramData\Anaconda3\lib\site-packages\dash\dash.py", line 1007, in add_context
    output_value = func(*args, **kwargs)  # %% callback invoked %%
  File "C:\Users\joeda\OneDrive\Documents\GitHub\Scisat-App\scisat_app\scisat.py", line 961, in make_count_figure
    df =data_reader(gaz_list,r'data',start_date,end_date,lat_min,lat_max,lon_min,lon_max,alt_range)
  File "C:\Users\joeda\OneDrive\Documents\GitHub\Scisat-App\scisat_app\scisat.py", line 75, in data_reader
    nc = netcdf.netcdf_file(name,'r')
  File "C:\ProgramData\Anaconda3\lib\site-packages\scipy\io\netcdf.py", line 249, in __init__
    self.fp = open(self.filename, '%sb' % omode)
FileNotFoundError: [Errno 2] No such file or directory: 'data//ACEFTS_L2_v4p1_O3.nc'
INFO:werkzeug:127.0.0.1 - - [09/Nov/2020 12:32:45] "[1m[35mPOST /scisat/_dash-update-component HTTP/1.1[0m" 500 -
INFO:werkzeug:127.0.0.1 - - [09/Nov/2020 12:32:45] "[37mPOST /scisat/_dash-update-component HTTP/1.1[0m" 200 -
ERROR:scisat_app.scisat:Exception on /_dash-update-component [POST]
Traceback (most recent call last):
  File "C:\ProgramData\Anaconda3\lib\site-packages\flask\app.py", line 2446, in wsgi_app
    response = self.full_dispatch_request()
  File "C:\ProgramData\Anaconda3\lib\site-packages\flask\app.py", line 1951, in full_dispatch_request
    rv = self.handle_user_exception(e)
  File "C:\ProgramData\Anaconda3\lib\site-packages\flask\app.py", line 1820, in handle_user_exception
    reraise(exc_type, exc_value, tb)
  File "C:\ProgramData\Anaconda3\lib\site-packages\flask\_compat.py", line 39, in reraise
    raise value
  File "C:\ProgramData\Anaconda3\lib\site-packages\flask\app.py", line 1949, in full_dispatch_request
    rv = self.dispatch_request()
  File "C:\ProgramData\Anaconda3\lib\site-packages\flask\app.py", line 1935, in dispatch_request
    return self.view_functions[rule.endpoint](**req.view_args)
  File "C:\ProgramData\Anaconda3\lib\site-packages\dash\dash.py", line 1072, in dispatch
    response.set_data(func(*args, outputs_list=outputs_list))
  File "C:\ProgramData\Anaconda3\lib\site-packages\dash\dash.py", line 1007, in add_context
    output_value = func(*args, **kwargs)  # %% callback invoked %%
  File "C:\Users\joeda\OneDrive\Documents\GitHub\Scisat-App\scisat_app\scisat.py", line 656, in update_filtering_text
    df =data_reader(gaz_list,r'data',start_date,end_date,lat_min,lat_max,lon_min,lon_max,alt_range)
  File "C:\Users\joeda\OneDrive\Documents\GitHub\Scisat-App\scisat_app\scisat.py", line 75, in data_reader
    nc = netcdf.netcdf_file(name,'r')
  File "C:\ProgramData\Anaconda3\lib\site-packages\scipy\io\netcdf.py", line 249, in __init__
    self.fp = open(self.filename, '%sb' % omode)
FileNotFoundError: [Errno 2] No such file or directory: 'data//ACEFTS_L2_v4p1_O3.nc'
INFO:werkzeug:127.0.0.1 - - [09/Nov/2020 12:32:45] "[1m[35mPOST /scisat/_dash-update-component HTTP/1.1[0m" 500 -
ERROR:scisat_app.scisat:Exception on /_dash-update-component [POST]
Traceback (most recent call last):
  File "C:\ProgramData\Anaconda3\lib\site-packages\flask\app.py", line 2446, in wsgi_app
    response = self.full_dispatch_request()
  File "C:\ProgramData\Anaconda3\lib\site-packages\flask\app.py", line 1951, in full_dispatch_request
    rv = self.handle_user_exception(e)
  File "C:\ProgramData\Anaconda3\lib\site-packages\flask\app.py", line 1820, in handle_user_exception
    reraise(exc_type, exc_value, tb)
  File "C:\ProgramData\Anaconda3\lib\site-packages\flask\_compat.py", line 39, in reraise
    raise value
  File "C:\ProgramData\Anaconda3\lib\site-packages\flask\app.py", line 1949, in full_dispatch_request
    rv = self.dispatch_request()
  File "C:\ProgramData\Anaconda3\lib\site-packages\flask\app.py", line 1935, in dispatch_request
    return self.view_functions[rule.endpoint](**req.view_args)
  File "C:\ProgramData\Anaconda3\lib\site-packages\dash\dash.py", line 1072, in dispatch
    response.set_data(func(*args, outputs_list=outputs_list))
  File "C:\ProgramData\Anaconda3\lib\site-packages\dash\dash.py", line 1007, in add_context
    output_value = func(*args, **kwargs)  # %% callback invoked %%
  File "C:\Users\joeda\OneDrive\Documents\GitHub\Scisat-App\scisat_app\scisat.py", line 671, in update_picker
    df =data_reader(gaz_list,r'data')
  File "C:\Users\joeda\OneDrive\Documents\GitHub\Scisat-App\scisat_app\scisat.py", line 75, in data_reader
    nc = netcdf.netcdf_file(name,'r')
  File "C:\ProgramData\Anaconda3\lib\site-packages\scipy\io\netcdf.py", line 249, in __init__
    self.fp = open(self.filename, '%sb' % omode)
FileNotFoundError: [Errno 2] No such file or directory: 'data//ACEFTS_L2_v4p1_O2.nc'
INFO:werkzeug:127.0.0.1 - - [09/Nov/2020 12:32:54] "[1m[35mPOST /scisat/_dash-update-component HTTP/1.1[0m" 500 -
ERROR:scisat_app.scisat:Exception on /_dash-update-component [POST]
Traceback (most recent call last):
  File "C:\ProgramData\Anaconda3\lib\site-packages\flask\app.py", line 2446, in wsgi_app
    response = self.full_dispatch_request()
  File "C:\ProgramData\Anaconda3\lib\site-packages\flask\app.py", line 1951, in full_dispatch_request
    rv = self.handle_user_exception(e)
  File "C:\ProgramData\Anaconda3\lib\site-packages\flask\app.py", line 1820, in handle_user_exception
    reraise(exc_type, exc_value, tb)
  File "C:\ProgramData\Anaconda3\lib\site-packages\flask\_compat.py", line 39, in reraise
    raise value
  File "C:\ProgramData\Anaconda3\lib\site-packages\flask\app.py", line 1949, in full_dispatch_request
    rv = self.dispatch_request()
  File "C:\ProgramData\Anaconda3\lib\site-packages\flask\app.py", line 1935, in dispatch_request
    return self.view_functions[rule.endpoint](**req.view_args)
  File "C:\ProgramData\Anaconda3\lib\site-packages\dash\dash.py", line 1072, in dispatch
    response.set_data(func(*args, outputs_list=outputs_list))
  File "C:\ProgramData\Anaconda3\lib\site-packages\dash\dash.py", line 1007, in add_context
    output_value = func(*args, **kwargs)  # %% callback invoked %%
  File "C:\Users\joeda\OneDrive\Documents\GitHub\Scisat-App\scisat_app\scisat.py", line 1190, in make_viz_chart
    df =data_reader(gaz_list,r'data',start_date,end_date,lat_min,lat_max,lon_min,lon_max,alt_range)
  File "C:\Users\joeda\OneDrive\Documents\GitHub\Scisat-App\scisat_app\scisat.py", line 75, in data_reader
    nc = netcdf.netcdf_file(name,'r')
  File "C:\ProgramData\Anaconda3\lib\site-packages\scipy\io\netcdf.py", line 249, in __init__
    self.fp = open(self.filename, '%sb' % omode)
FileNotFoundError: [Errno 2] No such file or directory: 'data//ACEFTS_L2_v4p1_O2.nc'
INFO:werkzeug:127.0.0.1 - - [09/Nov/2020 12:32:54] "[1m[35mPOST /scisat/_dash-update-component HTTP/1.1[0m" 500 -
ERROR:scisat_app.scisat:Exception on /_dash-update-component [POST]
Traceback (most recent call last):
  File "C:\ProgramData\Anaconda3\lib\site-packages\flask\app.py", line 2446, in wsgi_app
    response = self.full_dispatch_request()
  File "C:\ProgramData\Anaconda3\lib\site-packages\flask\app.py", line 1951, in full_dispatch_request
    rv = self.handle_user_exception(e)
  File "C:\ProgramData\Anaconda3\lib\site-packages\flask\app.py", line 1820, in handle_user_exception
    reraise(exc_type, exc_value, tb)
  File "C:\ProgramData\Anaconda3\lib\site-packages\flask\_compat.py", line 39, in reraise
    raise value
  File "C:\ProgramData\Anaconda3\lib\site-packages\flask\app.py", line 1949, in full_dispatch_request
    rv = self.dispatch_request()
  File "C:\ProgramData\Anaconda3\lib\site-packages\flask\app.py", line 1935, in dispatch_request
    return self.view_functions[rule.endpoint](**req.view_args)
  File "C:\ProgramData\Anaconda3\lib\site-packages\dash\dash.py", line 1072, in dispatch
    response.set_data(func(*args, outputs_list=outputs_list))
  File "C:\ProgramData\Anaconda3\lib\site-packages\dash\dash.py", line 1007, in add_context
    output_value = func(*args, **kwargs)  # %% callback invoked %%
  File "C:\Users\joeda\OneDrive\Documents\GitHub\Scisat-App\scisat_app\scisat.py", line 1075, in generate_geo_map
    df = data_reader(gaz_list,r'data',start_date,end_date,lat_min,lat_max,lon_min,lon_max,alt_range)
  File "C:\Users\joeda\OneDrive\Documents\GitHub\Scisat-App\scisat_app\scisat.py", line 75, in data_reader
    nc = netcdf.netcdf_file(name,'r')
  File "C:\ProgramData\Anaconda3\lib\site-packages\scipy\io\netcdf.py", line 249, in __init__
    self.fp = open(self.filename, '%sb' % omode)
FileNotFoundError: [Errno 2] No such file or directory: 'data//ACEFTS_L2_v4p1_O2.nc'
INFO:werkzeug:127.0.0.1 - - [09/Nov/2020 12:32:54] "[1m[35mPOST /scisat/_dash-update-component HTTP/1.1[0m" 500 -
ERROR:scisat_app.scisat:Exception on /_dash-update-component [POST]
Traceback (most recent call last):
  File "C:\ProgramData\Anaconda3\lib\site-packages\flask\app.py", line 2446, in wsgi_app
    response = self.full_dispatch_request()
  File "C:\ProgramData\Anaconda3\lib\site-packages\flask\app.py", line 1951, in full_dispatch_request
    rv = self.handle_user_exception(e)
  File "C:\ProgramData\Anaconda3\lib\site-packages\flask\app.py", line 1820, in handle_user_exception
    reraise(exc_type, exc_value, tb)
  File "C:\ProgramData\Anaconda3\lib\site-packages\flask\_compat.py", line 39, in reraise
    raise value
  File "C:\ProgramData\Anaconda3\lib\site-packages\flask\app.py", line 1949, in full_dispatch_request
    rv = self.dispatch_request()
  File "C:\ProgramData\Anaconda3\lib\site-packages\flask\app.py", line 1935, in dispatch_request
    return self.view_functions[rule.endpoint](**req.view_args)
  File "C:\ProgramData\Anaconda3\lib\site-packages\dash\dash.py", line 1072, in dispatch
    response.set_data(func(*args, outputs_list=outputs_list))
  File "C:\ProgramData\Anaconda3\lib\site-packages\dash\dash.py", line 1007, in add_context
    output_value = func(*args, **kwargs)  # %% callback invoked %%
  File "C:\Users\joeda\OneDrive\Documents\GitHub\Scisat-App\scisat_app\scisat.py", line 961, in make_count_figure
    df =data_reader(gaz_list,r'data',start_date,end_date,lat_min,lat_max,lon_min,lon_max,alt_range)
  File "C:\Users\joeda\OneDrive\Documents\GitHub\Scisat-App\scisat_app\scisat.py", line 75, in data_reader
    nc = netcdf.netcdf_file(name,'r')
  File "C:\ProgramData\Anaconda3\lib\site-packages\scipy\io\netcdf.py", line 249, in __init__
    self.fp = open(self.filename, '%sb' % omode)
FileNotFoundError: [Errno 2] No such file or directory: 'data//ACEFTS_L2_v4p1_O2.nc'
INFO:werkzeug:127.0.0.1 - - [09/Nov/2020 12:32:54] "[1m[35mPOST /scisat/_dash-update-component HTTP/1.1[0m" 500 -
INFO:werkzeug:127.0.0.1 - - [09/Nov/2020 12:32:54] "[37mPOST /scisat/_dash-update-component HTTP/1.1[0m" 200 -
ERROR:scisat_app.scisat:Exception on /_dash-update-component [POST]
Traceback (most recent call last):
  File "C:\ProgramData\Anaconda3\lib\site-packages\flask\app.py", line 2446, in wsgi_app
    response = self.full_dispatch_request()
  File "C:\ProgramData\Anaconda3\lib\site-packages\flask\app.py", line 1951, in full_dispatch_request
    rv = self.handle_user_exception(e)
  File "C:\ProgramData\Anaconda3\lib\site-packages\flask\app.py", line 1820, in handle_user_exception
    reraise(exc_type, exc_value, tb)
  File "C:\ProgramData\Anaconda3\lib\site-packages\flask\_compat.py", line 39, in reraise
    raise value
  File "C:\ProgramData\Anaconda3\lib\site-packages\flask\app.py", line 1949, in full_dispatch_request
    rv = self.dispatch_request()
  File "C:\ProgramData\Anaconda3\lib\site-packages\flask\app.py", line 1935, in dispatch_request
    return self.view_functions[rule.endpoint](**req.view_args)
  File "C:\ProgramData\Anaconda3\lib\site-packages\dash\dash.py", line 1072, in dispatch
    response.set_data(func(*args, outputs_list=outputs_list))
  File "C:\ProgramData\Anaconda3\lib\site-packages\dash\dash.py", line 1007, in add_context
    output_value = func(*args, **kwargs)  # %% callback invoked %%
  File "C:\Users\joeda\OneDrive\Documents\GitHub\Scisat-App\scisat_app\scisat.py", line 656, in update_filtering_text
    df =data_reader(gaz_list,r'data',start_date,end_date,lat_min,lat_max,lon_min,lon_max,alt_range)
  File "C:\Users\joeda\OneDrive\Documents\GitHub\Scisat-App\scisat_app\scisat.py", line 75, in data_reader
    nc = netcdf.netcdf_file(name,'r')
  File "C:\ProgramData\Anaconda3\lib\site-packages\scipy\io\netcdf.py", line 249, in __init__
    self.fp = open(self.filename, '%sb' % omode)
FileNotFoundError: [Errno 2] No such file or directory: 'data//ACEFTS_L2_v4p1_O2.nc'
INFO:werkzeug:127.0.0.1 - - [09/Nov/2020 12:32:54] "[1m[35mPOST /scisat/_dash-update-component HTTP/1.1[0m" 500 -
INFO:werkzeug:127.0.0.1 - - [09/Nov/2020 12:32:57] "[37mGET /scisat/ HTTP/1.1[0m" 200 -
INFO:werkzeug:127.0.0.1 - - [09/Nov/2020 12:32:57] "[37mGET /scisat/_dash-layout HTTP/1.1[0m" 200 -
INFO:werkzeug:127.0.0.1 - - [09/Nov/2020 12:32:57] "[37mGET /scisat/_dash-dependencies HTTP/1.1[0m" 200 -
ERROR:scisat_app.scisat:Exception on /_dash-update-component [POST]
Traceback (most recent call last):
  File "C:\ProgramData\Anaconda3\lib\site-packages\flask\app.py", line 2446, in wsgi_app
    response = self.full_dispatch_request()
  File "C:\ProgramData\Anaconda3\lib\site-packages\flask\app.py", line 1951, in full_dispatch_request
    rv = self.handle_user_exception(e)
  File "C:\ProgramData\Anaconda3\lib\site-packages\flask\app.py", line 1820, in handle_user_exception
    reraise(exc_type, exc_value, tb)
  File "C:\ProgramData\Anaconda3\lib\site-packages\flask\_compat.py", line 39, in reraise
    raise value
  File "C:\ProgramData\Anaconda3\lib\site-packages\flask\app.py", line 1949, in full_dispatch_request
    rv = self.dispatch_request()
  File "C:\ProgramData\Anaconda3\lib\site-packages\flask\app.py", line 1935, in dispatch_request
    return self.view_functions[rule.endpoint](**req.view_args)
  File "C:\ProgramData\Anaconda3\lib\site-packages\dash\dash.py", line 1072, in dispatch
    response.set_data(func(*args, outputs_list=outputs_list))
  File "C:\ProgramData\Anaconda3\lib\site-packages\dash\dash.py", line 1007, in add_context
    output_value = func(*args, **kwargs)  # %% callback invoked %%
  File "C:\Users\joeda\OneDrive\Documents\GitHub\Scisat-App\scisat_app\scisat.py", line 671, in update_picker
    df =data_reader(gaz_list,r'data')
  File "C:\Users\joeda\OneDrive\Documents\GitHub\Scisat-App\scisat_app\scisat.py", line 75, in data_reader
    nc = netcdf.netcdf_file(name,'r')
  File "C:\ProgramData\Anaconda3\lib\site-packages\scipy\io\netcdf.py", line 249, in __init__
    self.fp = open(self.filename, '%sb' % omode)
FileNotFoundError: [Errno 2] No such file or directory: 'data//ACEFTS_L2_v4p1_O3.nc'
INFO:werkzeug:127.0.0.1 - - [09/Nov/2020 12:32:57] "[1m[35mPOST /scisat/_dash-update-component HTTP/1.1[0m" 500 -
ERROR:scisat_app.scisat:Exception on /_dash-update-component [POST]
Traceback (most recent call last):
  File "C:\ProgramData\Anaconda3\lib\site-packages\flask\app.py", line 2446, in wsgi_app
    response = self.full_dispatch_request()
  File "C:\ProgramData\Anaconda3\lib\site-packages\flask\app.py", line 1951, in full_dispatch_request
    rv = self.handle_user_exception(e)
  File "C:\ProgramData\Anaconda3\lib\site-packages\flask\app.py", line 1820, in handle_user_exception
    reraise(exc_type, exc_value, tb)
  File "C:\ProgramData\Anaconda3\lib\site-packages\flask\_compat.py", line 39, in reraise
    raise value
  File "C:\ProgramData\Anaconda3\lib\site-packages\flask\app.py", line 1949, in full_dispatch_request
    rv = self.dispatch_request()
  File "C:\ProgramData\Anaconda3\lib\site-packages\flask\app.py", line 1935, in dispatch_request
    return self.view_functions[rule.endpoint](**req.view_args)
  File "C:\ProgramData\Anaconda3\lib\site-packages\dash\dash.py", line 1072, in dispatch
    response.set_data(func(*args, outputs_list=outputs_list))
  File "C:\ProgramData\Anaconda3\lib\site-packages\dash\dash.py", line 1007, in add_context
    output_value = func(*args, **kwargs)  # %% callback invoked %%
  File "C:\Users\joeda\OneDrive\Documents\GitHub\Scisat-App\scisat_app\scisat.py", line 1677, in update_language_button
    language = session['language']
  File "C:\ProgramData\Anaconda3\lib\site-packages\werkzeug\local.py", line 378, in <lambda>
    __getitem__ = lambda x, i: x._get_current_object()[i]
  File "C:\ProgramData\Anaconda3\lib\site-packages\flask\sessions.py", line 84, in __getitem__
    return super(SecureCookieSession, self).__getitem__(key)
KeyError: 'language'
INFO:werkzeug:127.0.0.1 - - [09/Nov/2020 12:32:57] "[1m[35mPOST /scisat/_dash-update-component HTTP/1.1[0m" 500 -
INFO:werkzeug:127.0.0.1 - - [09/Nov/2020 12:32:57] "[37mPOST /scisat/_dash-update-component HTTP/1.1[0m" 200 -
INFO:werkzeug:127.0.0.1 - - [09/Nov/2020 12:32:57] "[37mPOST /scisat/_dash-update-component HTTP/1.1[0m" 200 -
INFO:werkzeug:127.0.0.1 - - [09/Nov/2020 12:32:57] "[37mGET /scisat/_dash-component-suites/dash_core_components/async-graph.v1_10_1m1592438751.js HTTP/1.1[0m" 200 -
INFO:werkzeug:127.0.0.1 - - [09/Nov/2020 12:32:57] "[37mGET /scisat/_dash-component-suites/dash_core_components/async-slider.v1_10_1m1592438751.js HTTP/1.1[0m" 200 -
INFO:werkzeug:127.0.0.1 - - [09/Nov/2020 12:32:58] "[37mGET /scisat/_favicon.ico?v=1.16.3 HTTP/1.1[0m" 200 -
INFO:werkzeug:127.0.0.1 - - [09/Nov/2020 12:32:58] "[37mPOST /scisat/_dash-update-component HTTP/1.1[0m" 200 -
INFO:werkzeug:127.0.0.1 - - [09/Nov/2020 12:32:58] "[37mPOST /scisat/_dash-update-component HTTP/1.1[0m" 200 -
ERROR:scisat_app.scisat:Exception on /_dash-update-component [POST]
Traceback (most recent call last):
  File "C:\ProgramData\Anaconda3\lib\site-packages\flask\app.py", line 2446, in wsgi_app
    response = self.full_dispatch_request()
  File "C:\ProgramData\Anaconda3\lib\site-packages\flask\app.py", line 1951, in full_dispatch_request
    rv = self.handle_user_exception(e)
  File "C:\ProgramData\Anaconda3\lib\site-packages\flask\app.py", line 1820, in handle_user_exception
    reraise(exc_type, exc_value, tb)
  File "C:\ProgramData\Anaconda3\lib\site-packages\flask\_compat.py", line 39, in reraise
    raise value
  File "C:\ProgramData\Anaconda3\lib\site-packages\flask\app.py", line 1949, in full_dispatch_request
    rv = self.dispatch_request()
  File "C:\ProgramData\Anaconda3\lib\site-packages\flask\app.py", line 1935, in dispatch_request
    return self.view_functions[rule.endpoint](**req.view_args)
  File "C:\ProgramData\Anaconda3\lib\site-packages\dash\dash.py", line 1072, in dispatch
    response.set_data(func(*args, outputs_list=outputs_list))
  File "C:\ProgramData\Anaconda3\lib\site-packages\dash\dash.py", line 1007, in add_context
    output_value = func(*args, **kwargs)  # %% callback invoked %%
  File "C:\Users\joeda\OneDrive\Documents\GitHub\Scisat-App\scisat_app\scisat.py", line 1190, in make_viz_chart
    df =data_reader(gaz_list,r'data',start_date,end_date,lat_min,lat_max,lon_min,lon_max,alt_range)
  File "C:\Users\joeda\OneDrive\Documents\GitHub\Scisat-App\scisat_app\scisat.py", line 75, in data_reader
    nc = netcdf.netcdf_file(name,'r')
  File "C:\ProgramData\Anaconda3\lib\site-packages\scipy\io\netcdf.py", line 249, in __init__
    self.fp = open(self.filename, '%sb' % omode)
FileNotFoundError: [Errno 2] No such file or directory: 'data//ACEFTS_L2_v4p1_O3.nc'
INFO:werkzeug:127.0.0.1 - - [09/Nov/2020 12:32:58] "[1m[35mPOST /scisat/_dash-update-component HTTP/1.1[0m" 500 -
ERROR:scisat_app.scisat:Exception on /_dash-update-component [POST]
Traceback (most recent call last):
  File "C:\ProgramData\Anaconda3\lib\site-packages\flask\app.py", line 2446, in wsgi_app
    response = self.full_dispatch_request()
  File "C:\ProgramData\Anaconda3\lib\site-packages\flask\app.py", line 1951, in full_dispatch_request
    rv = self.handle_user_exception(e)
  File "C:\ProgramData\Anaconda3\lib\site-packages\flask\app.py", line 1820, in handle_user_exception
    reraise(exc_type, exc_value, tb)
  File "C:\ProgramData\Anaconda3\lib\site-packages\flask\_compat.py", line 39, in reraise
    raise value
  File "C:\ProgramData\Anaconda3\lib\site-packages\flask\app.py", line 1949, in full_dispatch_request
    rv = self.dispatch_request()
  File "C:\ProgramData\Anaconda3\lib\site-packages\flask\app.py", line 1935, in dispatch_request
    return self.view_functions[rule.endpoint](**req.view_args)
  File "C:\ProgramData\Anaconda3\lib\site-packages\dash\dash.py", line 1072, in dispatch
    response.set_data(func(*args, outputs_list=outputs_list))
  File "C:\ProgramData\Anaconda3\lib\site-packages\dash\dash.py", line 1007, in add_context
    output_value = func(*args, **kwargs)  # %% callback invoked %%
  File "C:\Users\joeda\OneDrive\Documents\GitHub\Scisat-App\scisat_app\scisat.py", line 1075, in generate_geo_map
    df = data_reader(gaz_list,r'data',start_date,end_date,lat_min,lat_max,lon_min,lon_max,alt_range)
  File "C:\Users\joeda\OneDrive\Documents\GitHub\Scisat-App\scisat_app\scisat.py", line 75, in data_reader
    nc = netcdf.netcdf_file(name,'r')
  File "C:\ProgramData\Anaconda3\lib\site-packages\scipy\io\netcdf.py", line 249, in __init__
    self.fp = open(self.filename, '%sb' % omode)
FileNotFoundError: [Errno 2] No such file or directory: 'data//ACEFTS_L2_v4p1_O3.nc'
INFO:werkzeug:127.0.0.1 - - [09/Nov/2020 12:32:58] "[1m[35mPOST /scisat/_dash-update-component HTTP/1.1[0m" 500 -
ERROR:scisat_app.scisat:Exception on /_dash-update-component [POST]
Traceback (most recent call last):
  File "C:\ProgramData\Anaconda3\lib\site-packages\flask\app.py", line 2446, in wsgi_app
    response = self.full_dispatch_request()
  File "C:\ProgramData\Anaconda3\lib\site-packages\flask\app.py", line 1951, in full_dispatch_request
    rv = self.handle_user_exception(e)
  File "C:\ProgramData\Anaconda3\lib\site-packages\flask\app.py", line 1820, in handle_user_exception
    reraise(exc_type, exc_value, tb)
  File "C:\ProgramData\Anaconda3\lib\site-packages\flask\_compat.py", line 39, in reraise
    raise value
  File "C:\ProgramData\Anaconda3\lib\site-packages\flask\app.py", line 1949, in full_dispatch_request
    rv = self.dispatch_request()
  File "C:\ProgramData\Anaconda3\lib\site-packages\flask\app.py", line 1935, in dispatch_request
    return self.view_functions[rule.endpoint](**req.view_args)
  File "C:\ProgramData\Anaconda3\lib\site-packages\dash\dash.py", line 1072, in dispatch
    response.set_data(func(*args, outputs_list=outputs_list))
  File "C:\ProgramData\Anaconda3\lib\site-packages\dash\dash.py", line 1007, in add_context
    output_value = func(*args, **kwargs)  # %% callback invoked %%
  File "C:\Users\joeda\OneDrive\Documents\GitHub\Scisat-App\scisat_app\scisat.py", line 961, in make_count_figure
    df =data_reader(gaz_list,r'data',start_date,end_date,lat_min,lat_max,lon_min,lon_max,alt_range)
  File "C:\Users\joeda\OneDrive\Documents\GitHub\Scisat-App\scisat_app\scisat.py", line 75, in data_reader
    nc = netcdf.netcdf_file(name,'r')
  File "C:\ProgramData\Anaconda3\lib\site-packages\scipy\io\netcdf.py", line 249, in __init__
    self.fp = open(self.filename, '%sb' % omode)
FileNotFoundError: [Errno 2] No such file or directory: 'data//ACEFTS_L2_v4p1_O3.nc'
INFO:werkzeug:127.0.0.1 - - [09/Nov/2020 12:32:58] "[1m[35mPOST /scisat/_dash-update-component HTTP/1.1[0m" 500 -
INFO:werkzeug:127.0.0.1 - - [09/Nov/2020 12:32:58] "[37mPOST /scisat/_dash-update-component HTTP/1.1[0m" 200 -
ERROR:scisat_app.scisat:Exception on /_dash-update-component [POST]
Traceback (most recent call last):
  File "C:\ProgramData\Anaconda3\lib\site-packages\flask\app.py", line 2446, in wsgi_app
    response = self.full_dispatch_request()
  File "C:\ProgramData\Anaconda3\lib\site-packages\flask\app.py", line 1951, in full_dispatch_request
    rv = self.handle_user_exception(e)
  File "C:\ProgramData\Anaconda3\lib\site-packages\flask\app.py", line 1820, in handle_user_exception
    reraise(exc_type, exc_value, tb)
  File "C:\ProgramData\Anaconda3\lib\site-packages\flask\_compat.py", line 39, in reraise
    raise value
  File "C:\ProgramData\Anaconda3\lib\site-packages\flask\app.py", line 1949, in full_dispatch_request
    rv = self.dispatch_request()
  File "C:\ProgramData\Anaconda3\lib\site-packages\flask\app.py", line 1935, in dispatch_request
    return self.view_functions[rule.endpoint](**req.view_args)
  File "C:\ProgramData\Anaconda3\lib\site-packages\dash\dash.py", line 1072, in dispatch
    response.set_data(func(*args, outputs_list=outputs_list))
  File "C:\ProgramData\Anaconda3\lib\site-packages\dash\dash.py", line 1007, in add_context
    output_value = func(*args, **kwargs)  # %% callback invoked %%
  File "C:\Users\joeda\OneDrive\Documents\GitHub\Scisat-App\scisat_app\scisat.py", line 656, in update_filtering_text
    df =data_reader(gaz_list,r'data',start_date,end_date,lat_min,lat_max,lon_min,lon_max,alt_range)
  File "C:\Users\joeda\OneDrive\Documents\GitHub\Scisat-App\scisat_app\scisat.py", line 75, in data_reader
    nc = netcdf.netcdf_file(name,'r')
  File "C:\ProgramData\Anaconda3\lib\site-packages\scipy\io\netcdf.py", line 249, in __init__
    self.fp = open(self.filename, '%sb' % omode)
FileNotFoundError: [Errno 2] No such file or directory: 'data//ACEFTS_L2_v4p1_O3.nc'
INFO:werkzeug:127.0.0.1 - - [09/Nov/2020 12:32:58] "[1m[35mPOST /scisat/_dash-update-component HTTP/1.1[0m" 500 -
INFO:werkzeug: * Running on http://0.0.0.0:8888/ (Press CTRL+C to quit)
INFO:werkzeug:127.0.0.1 - - [09/Nov/2020 12:33:56] "[37mGET /scisat/ HTTP/1.1[0m" 200 -
INFO:werkzeug:127.0.0.1 - - [09/Nov/2020 12:33:56] "[37mGET /scisat/_dash-component-suites/dash_renderer/polyfill@7.v1_5_1m1593873890.8.7.min.js HTTP/1.1[0m" 200 -
INFO:werkzeug:127.0.0.1 - - [09/Nov/2020 12:33:56] "[37mGET /scisat/_dash-component-suites/dash_renderer/react@16.v1_5_1m1593873890.13.0.min.js HTTP/1.1[0m" 200 -
INFO:werkzeug:127.0.0.1 - - [09/Nov/2020 12:33:56] "[37mGET /scisat/_dash-component-suites/dash_renderer/react-dom@16.v1_5_1m1593873890.13.0.min.js HTTP/1.1[0m" 200 -
INFO:werkzeug:127.0.0.1 - - [09/Nov/2020 12:33:56] "[37mGET /scisat/_dash-component-suites/dash_renderer/prop-types@15.v1_5_1m1593873890.7.2.min.js HTTP/1.1[0m" 200 -
INFO:werkzeug:127.0.0.1 - - [09/Nov/2020 12:33:56] "[37mGET /scisat/_dash-component-suites/dash_dangerously_set_inner_html/bundle.v0_0_2m1593870401.js HTTP/1.1[0m" 200 -
INFO:werkzeug:127.0.0.1 - - [09/Nov/2020 12:33:56] "[37mGET /scisat/_dash-component-suites/dash_html_components/dash_html_components.v1_0_3m1593873891.min.js HTTP/1.1[0m" 200 -
INFO:werkzeug:127.0.0.1 - - [09/Nov/2020 12:33:56] "[37mGET /scisat/_dash-component-suites/dash_core_components/dash_core_components.v1_10_1m1593873890.min.js HTTP/1.1[0m" 200 -
INFO:werkzeug:127.0.0.1 - - [09/Nov/2020 12:33:56] "[37mGET /scisat/_dash-component-suites/dash_core_components/dash_core_components-shared.v1_10_1m1593873890.js HTTP/1.1[0m" 200 -
INFO:werkzeug:127.0.0.1 - - [09/Nov/2020 12:33:56] "[37mGET /scisat/_dash-component-suites/dash_renderer/dash_renderer.v1_5_1m1593873890.min.js HTTP/1.1[0m" 200 -
INFO:werkzeug:127.0.0.1 - - [09/Nov/2020 12:33:56] "[37mGET /scisat/_dash-layout HTTP/1.1[0m" 200 -
INFO:werkzeug:127.0.0.1 - - [09/Nov/2020 12:33:56] "[37mGET /scisat/_dash-dependencies HTTP/1.1[0m" 200 -
ERROR:scisat_app.scisat:Exception on /_dash-update-component [POST]
Traceback (most recent call last):
  File "C:\ProgramData\Anaconda3\lib\site-packages\flask\app.py", line 2446, in wsgi_app
    response = self.full_dispatch_request()
  File "C:\ProgramData\Anaconda3\lib\site-packages\flask\app.py", line 1951, in full_dispatch_request
    rv = self.handle_user_exception(e)
  File "C:\ProgramData\Anaconda3\lib\site-packages\flask\app.py", line 1820, in handle_user_exception
    reraise(exc_type, exc_value, tb)
  File "C:\ProgramData\Anaconda3\lib\site-packages\flask\_compat.py", line 39, in reraise
    raise value
  File "C:\ProgramData\Anaconda3\lib\site-packages\flask\app.py", line 1949, in full_dispatch_request
    rv = self.dispatch_request()
  File "C:\ProgramData\Anaconda3\lib\site-packages\flask\app.py", line 1935, in dispatch_request
    return self.view_functions[rule.endpoint](**req.view_args)
  File "C:\ProgramData\Anaconda3\lib\site-packages\dash\dash.py", line 1072, in dispatch
    response.set_data(func(*args, outputs_list=outputs_list))
  File "C:\ProgramData\Anaconda3\lib\site-packages\dash\dash.py", line 1007, in add_context
    output_value = func(*args, **kwargs)  # %% callback invoked %%
  File "C:\Users\joeda\OneDrive\Documents\GitHub\Scisat-App\scisat_app\scisat.py", line 671, in update_picker
    df =data_reader(gaz_list,r'data')
  File "C:\Users\joeda\OneDrive\Documents\GitHub\Scisat-App\scisat_app\scisat.py", line 75, in data_reader
    nc = netcdf.netcdf_file(name,'r')
  File "C:\ProgramData\Anaconda3\lib\site-packages\scipy\io\netcdf.py", line 249, in __init__
    self.fp = open(self.filename, '%sb' % omode)
FileNotFoundError: [Errno 2] No such file or directory: 'data//ACEFTS_L2_v4p1_O3.nc'
INFO:werkzeug:127.0.0.1 - - [09/Nov/2020 12:33:57] "[1m[35mPOST /scisat/_dash-update-component HTTP/1.1[0m" 500 -
ERROR:scisat_app.scisat:Exception on /_dash-update-component [POST]
Traceback (most recent call last):
  File "C:\ProgramData\Anaconda3\lib\site-packages\flask\app.py", line 2446, in wsgi_app
    response = self.full_dispatch_request()
  File "C:\ProgramData\Anaconda3\lib\site-packages\flask\app.py", line 1951, in full_dispatch_request
    rv = self.handle_user_exception(e)
  File "C:\ProgramData\Anaconda3\lib\site-packages\flask\app.py", line 1820, in handle_user_exception
    reraise(exc_type, exc_value, tb)
  File "C:\ProgramData\Anaconda3\lib\site-packages\flask\_compat.py", line 39, in reraise
    raise value
  File "C:\ProgramData\Anaconda3\lib\site-packages\flask\app.py", line 1949, in full_dispatch_request
    rv = self.dispatch_request()
  File "C:\ProgramData\Anaconda3\lib\site-packages\flask\app.py", line 1935, in dispatch_request
    return self.view_functions[rule.endpoint](**req.view_args)
  File "C:\ProgramData\Anaconda3\lib\site-packages\dash\dash.py", line 1072, in dispatch
    response.set_data(func(*args, outputs_list=outputs_list))
  File "C:\ProgramData\Anaconda3\lib\site-packages\dash\dash.py", line 1007, in add_context
    output_value = func(*args, **kwargs)  # %% callback invoked %%
  File "C:\Users\joeda\OneDrive\Documents\GitHub\Scisat-App\scisat_app\scisat.py", line 1677, in update_language_button
    language = session['language']
  File "C:\ProgramData\Anaconda3\lib\site-packages\werkzeug\local.py", line 378, in <lambda>
    __getitem__ = lambda x, i: x._get_current_object()[i]
  File "C:\ProgramData\Anaconda3\lib\site-packages\flask\sessions.py", line 84, in __getitem__
    return super(SecureCookieSession, self).__getitem__(key)
KeyError: 'language'
INFO:werkzeug:127.0.0.1 - - [09/Nov/2020 12:33:57] "[1m[35mPOST /scisat/_dash-update-component HTTP/1.1[0m" 500 -
INFO:werkzeug:127.0.0.1 - - [09/Nov/2020 12:33:57] "[37mPOST /scisat/_dash-update-component HTTP/1.1[0m" 200 -
INFO:werkzeug:127.0.0.1 - - [09/Nov/2020 12:33:57] "[37mPOST /scisat/_dash-update-component HTTP/1.1[0m" 200 -
INFO:werkzeug:127.0.0.1 - - [09/Nov/2020 12:33:57] "[37mGET /scisat/_dash-component-suites/dash_core_components/async-dropdown.v1_10_1m1592438751.js HTTP/1.1[0m" 200 -
INFO:werkzeug:127.0.0.1 - - [09/Nov/2020 12:33:57] "[37mGET /scisat/_dash-component-suites/dash_core_components/async-plotlyjs.v1_10_1m1592438751.js HTTP/1.1[0m" 200 -
INFO:werkzeug:127.0.0.1 - - [09/Nov/2020 12:33:57] "[37mGET /scisat/_dash-component-suites/dash_core_components/async-graph.v1_10_1m1592438751.js HTTP/1.1[0m" 200 -
INFO:werkzeug:127.0.0.1 - - [09/Nov/2020 12:33:57] "[37mGET /scisat/_dash-component-suites/dash_core_components/async-datepicker.v1_10_1m1592438751.js HTTP/1.1[0m" 200 -
INFO:werkzeug:127.0.0.1 - - [09/Nov/2020 12:33:57] "[37mGET /scisat/_dash-component-suites/dash_core_components/async-slider.v1_10_1m1592438751.js HTTP/1.1[0m" 200 -
INFO:werkzeug:127.0.0.1 - - [09/Nov/2020 12:33:57] "[37mGET /scisat/assets/csa-logo.png HTTP/1.1[0m" 200 -
INFO:werkzeug:127.0.0.1 - - [09/Nov/2020 12:33:58] "[37mPOST /scisat/_dash-update-component HTTP/1.1[0m" 200 -
INFO:werkzeug:127.0.0.1 - - [09/Nov/2020 12:33:58] "[37mPOST /scisat/_dash-update-component HTTP/1.1[0m" 200 -
ERROR:scisat_app.scisat:Exception on /_dash-update-component [POST]
Traceback (most recent call last):
  File "C:\ProgramData\Anaconda3\lib\site-packages\flask\app.py", line 2446, in wsgi_app
    response = self.full_dispatch_request()
  File "C:\ProgramData\Anaconda3\lib\site-packages\flask\app.py", line 1951, in full_dispatch_request
    rv = self.handle_user_exception(e)
  File "C:\ProgramData\Anaconda3\lib\site-packages\flask\app.py", line 1820, in handle_user_exception
    reraise(exc_type, exc_value, tb)
  File "C:\ProgramData\Anaconda3\lib\site-packages\flask\_compat.py", line 39, in reraise
    raise value
  File "C:\ProgramData\Anaconda3\lib\site-packages\flask\app.py", line 1949, in full_dispatch_request
    rv = self.dispatch_request()
  File "C:\ProgramData\Anaconda3\lib\site-packages\flask\app.py", line 1935, in dispatch_request
    return self.view_functions[rule.endpoint](**req.view_args)
  File "C:\ProgramData\Anaconda3\lib\site-packages\dash\dash.py", line 1072, in dispatch
    response.set_data(func(*args, outputs_list=outputs_list))
  File "C:\ProgramData\Anaconda3\lib\site-packages\dash\dash.py", line 1007, in add_context
    output_value = func(*args, **kwargs)  # %% callback invoked %%
  File "C:\Users\joeda\OneDrive\Documents\GitHub\Scisat-App\scisat_app\scisat.py", line 1190, in make_viz_chart
    df =data_reader(gaz_list,r'data',start_date,end_date,lat_min,lat_max,lon_min,lon_max,alt_range)
  File "C:\Users\joeda\OneDrive\Documents\GitHub\Scisat-App\scisat_app\scisat.py", line 75, in data_reader
    nc = netcdf.netcdf_file(name,'r')
  File "C:\ProgramData\Anaconda3\lib\site-packages\scipy\io\netcdf.py", line 249, in __init__
    self.fp = open(self.filename, '%sb' % omode)
FileNotFoundError: [Errno 2] No such file or directory: 'data//ACEFTS_L2_v4p1_O3.nc'
INFO:werkzeug:127.0.0.1 - - [09/Nov/2020 12:33:58] "[1m[35mPOST /scisat/_dash-update-component HTTP/1.1[0m" 500 -
ERROR:scisat_app.scisat:Exception on /_dash-update-component [POST]
Traceback (most recent call last):
  File "C:\ProgramData\Anaconda3\lib\site-packages\flask\app.py", line 2446, in wsgi_app
    response = self.full_dispatch_request()
  File "C:\ProgramData\Anaconda3\lib\site-packages\flask\app.py", line 1951, in full_dispatch_request
    rv = self.handle_user_exception(e)
  File "C:\ProgramData\Anaconda3\lib\site-packages\flask\app.py", line 1820, in handle_user_exception
    reraise(exc_type, exc_value, tb)
  File "C:\ProgramData\Anaconda3\lib\site-packages\flask\_compat.py", line 39, in reraise
    raise value
  File "C:\ProgramData\Anaconda3\lib\site-packages\flask\app.py", line 1949, in full_dispatch_request
    rv = self.dispatch_request()
  File "C:\ProgramData\Anaconda3\lib\site-packages\flask\app.py", line 1935, in dispatch_request
    return self.view_functions[rule.endpoint](**req.view_args)
  File "C:\ProgramData\Anaconda3\lib\site-packages\dash\dash.py", line 1072, in dispatch
    response.set_data(func(*args, outputs_list=outputs_list))
  File "C:\ProgramData\Anaconda3\lib\site-packages\dash\dash.py", line 1007, in add_context
    output_value = func(*args, **kwargs)  # %% callback invoked %%
  File "C:\Users\joeda\OneDrive\Documents\GitHub\Scisat-App\scisat_app\scisat.py", line 1075, in generate_geo_map
    df = data_reader(gaz_list,r'data',start_date,end_date,lat_min,lat_max,lon_min,lon_max,alt_range)
  File "C:\Users\joeda\OneDrive\Documents\GitHub\Scisat-App\scisat_app\scisat.py", line 75, in data_reader
    nc = netcdf.netcdf_file(name,'r')
  File "C:\ProgramData\Anaconda3\lib\site-packages\scipy\io\netcdf.py", line 249, in __init__
    self.fp = open(self.filename, '%sb' % omode)
FileNotFoundError: [Errno 2] No such file or directory: 'data//ACEFTS_L2_v4p1_O3.nc'
INFO:werkzeug:127.0.0.1 - - [09/Nov/2020 12:33:58] "[1m[35mPOST /scisat/_dash-update-component HTTP/1.1[0m" 500 -
ERROR:scisat_app.scisat:Exception on /_dash-update-component [POST]
Traceback (most recent call last):
  File "C:\ProgramData\Anaconda3\lib\site-packages\flask\app.py", line 2446, in wsgi_app
    response = self.full_dispatch_request()
  File "C:\ProgramData\Anaconda3\lib\site-packages\flask\app.py", line 1951, in full_dispatch_request
    rv = self.handle_user_exception(e)
  File "C:\ProgramData\Anaconda3\lib\site-packages\flask\app.py", line 1820, in handle_user_exception
    reraise(exc_type, exc_value, tb)
  File "C:\ProgramData\Anaconda3\lib\site-packages\flask\_compat.py", line 39, in reraise
    raise value
  File "C:\ProgramData\Anaconda3\lib\site-packages\flask\app.py", line 1949, in full_dispatch_request
    rv = self.dispatch_request()
  File "C:\ProgramData\Anaconda3\lib\site-packages\flask\app.py", line 1935, in dispatch_request
    return self.view_functions[rule.endpoint](**req.view_args)
  File "C:\ProgramData\Anaconda3\lib\site-packages\dash\dash.py", line 1072, in dispatch
    response.set_data(func(*args, outputs_list=outputs_list))
  File "C:\ProgramData\Anaconda3\lib\site-packages\dash\dash.py", line 1007, in add_context
    output_value = func(*args, **kwargs)  # %% callback invoked %%
  File "C:\Users\joeda\OneDrive\Documents\GitHub\Scisat-App\scisat_app\scisat.py", line 961, in make_count_figure
    df =data_reader(gaz_list,r'data',start_date,end_date,lat_min,lat_max,lon_min,lon_max,alt_range)
  File "C:\Users\joeda\OneDrive\Documents\GitHub\Scisat-App\scisat_app\scisat.py", line 75, in data_reader
    nc = netcdf.netcdf_file(name,'r')
  File "C:\ProgramData\Anaconda3\lib\site-packages\scipy\io\netcdf.py", line 249, in __init__
    self.fp = open(self.filename, '%sb' % omode)
FileNotFoundError: [Errno 2] No such file or directory: 'data//ACEFTS_L2_v4p1_O3.nc'
INFO:werkzeug:127.0.0.1 - - [09/Nov/2020 12:33:58] "[1m[35mPOST /scisat/_dash-update-component HTTP/1.1[0m" 500 -
INFO:werkzeug:127.0.0.1 - - [09/Nov/2020 12:33:58] "[37mPOST /scisat/_dash-update-component HTTP/1.1[0m" 200 -
ERROR:scisat_app.scisat:Exception on /_dash-update-component [POST]
Traceback (most recent call last):
  File "C:\ProgramData\Anaconda3\lib\site-packages\flask\app.py", line 2446, in wsgi_app
    response = self.full_dispatch_request()
  File "C:\ProgramData\Anaconda3\lib\site-packages\flask\app.py", line 1951, in full_dispatch_request
    rv = self.handle_user_exception(e)
  File "C:\ProgramData\Anaconda3\lib\site-packages\flask\app.py", line 1820, in handle_user_exception
    reraise(exc_type, exc_value, tb)
  File "C:\ProgramData\Anaconda3\lib\site-packages\flask\_compat.py", line 39, in reraise
    raise value
  File "C:\ProgramData\Anaconda3\lib\site-packages\flask\app.py", line 1949, in full_dispatch_request
    rv = self.dispatch_request()
  File "C:\ProgramData\Anaconda3\lib\site-packages\flask\app.py", line 1935, in dispatch_request
    return self.view_functions[rule.endpoint](**req.view_args)
  File "C:\ProgramData\Anaconda3\lib\site-packages\dash\dash.py", line 1072, in dispatch
    response.set_data(func(*args, outputs_list=outputs_list))
  File "C:\ProgramData\Anaconda3\lib\site-packages\dash\dash.py", line 1007, in add_context
    output_value = func(*args, **kwargs)  # %% callback invoked %%
  File "C:\Users\joeda\OneDrive\Documents\GitHub\Scisat-App\scisat_app\scisat.py", line 656, in update_filtering_text
    df =data_reader(gaz_list,r'data',start_date,end_date,lat_min,lat_max,lon_min,lon_max,alt_range)
  File "C:\Users\joeda\OneDrive\Documents\GitHub\Scisat-App\scisat_app\scisat.py", line 75, in data_reader
    nc = netcdf.netcdf_file(name,'r')
  File "C:\ProgramData\Anaconda3\lib\site-packages\scipy\io\netcdf.py", line 249, in __init__
    self.fp = open(self.filename, '%sb' % omode)
FileNotFoundError: [Errno 2] No such file or directory: 'data//ACEFTS_L2_v4p1_O3.nc'
INFO:werkzeug:127.0.0.1 - - [09/Nov/2020 12:33:58] "[1m[35mPOST /scisat/_dash-update-component HTTP/1.1[0m" 500 -
INFO:werkzeug:127.0.0.1 - - [09/Nov/2020 12:34:02] "[37mGET /scisat/assets/compiled.css?m=1595963752.208345 HTTP/1.1[0m" 200 -
INFO:werkzeug:127.0.0.1 - - [09/Nov/2020 12:34:02] "[37mGET /scisat/assets/compiled.css?m=1595963752.208345 HTTP/1.1[0m" 200 -
INFO:werkzeug: * Running on http://0.0.0.0:8888/ (Press CTRL+C to quit)
INFO:werkzeug:127.0.0.1 - - [09/Nov/2020 12:36:26] "[37mGET /scisat/ HTTP/1.1[0m" 200 -
INFO:werkzeug:127.0.0.1 - - [09/Nov/2020 12:36:26] "[37mGET /scisat/_dash-component-suites/dash_renderer/polyfill@7.v1_5_1m1593873890.8.7.min.js HTTP/1.1[0m" 200 -
INFO:werkzeug:127.0.0.1 - - [09/Nov/2020 12:36:26] "[37mGET /scisat/_dash-component-suites/dash_renderer/react@16.v1_5_1m1593873890.13.0.min.js HTTP/1.1[0m" 200 -
INFO:werkzeug:127.0.0.1 - - [09/Nov/2020 12:36:26] "[37mGET /scisat/_dash-component-suites/dash_renderer/react-dom@16.v1_5_1m1593873890.13.0.min.js HTTP/1.1[0m" 200 -
INFO:werkzeug:127.0.0.1 - - [09/Nov/2020 12:36:26] "[37mGET /scisat/_dash-component-suites/dash_renderer/prop-types@15.v1_5_1m1593873890.7.2.min.js HTTP/1.1[0m" 200 -
INFO:werkzeug:127.0.0.1 - - [09/Nov/2020 12:36:26] "[37mGET /scisat/_dash-component-suites/dash_dangerously_set_inner_html/bundle.v0_0_2m1593870401.js HTTP/1.1[0m" 200 -
INFO:werkzeug:127.0.0.1 - - [09/Nov/2020 12:36:26] "[37mGET /scisat/_dash-component-suites/dash_html_components/dash_html_components.v1_0_3m1593873891.min.js HTTP/1.1[0m" 200 -
INFO:werkzeug:127.0.0.1 - - [09/Nov/2020 12:36:26] "[37mGET /scisat/_dash-component-suites/dash_core_components/dash_core_components.v1_10_1m1593873890.min.js HTTP/1.1[0m" 200 -
INFO:werkzeug:127.0.0.1 - - [09/Nov/2020 12:36:26] "[37mGET /scisat/_dash-component-suites/dash_core_components/dash_core_components-shared.v1_10_1m1593873890.js HTTP/1.1[0m" 200 -
INFO:werkzeug:127.0.0.1 - - [09/Nov/2020 12:36:26] "[37mGET /scisat/_dash-component-suites/dash_renderer/dash_renderer.v1_5_1m1593873890.min.js HTTP/1.1[0m" 200 -
INFO:werkzeug:127.0.0.1 - - [09/Nov/2020 12:36:27] "[37mGET /scisat/_dash-layout HTTP/1.1[0m" 200 -
INFO:werkzeug:127.0.0.1 - - [09/Nov/2020 12:36:27] "[37mGET /scisat/_dash-dependencies HTTP/1.1[0m" 200 -
ERROR:scisat_app.scisat:Exception on /_dash-update-component [POST]
Traceback (most recent call last):
  File "C:\ProgramData\Anaconda3\lib\site-packages\flask\app.py", line 2446, in wsgi_app
    response = self.full_dispatch_request()
  File "C:\ProgramData\Anaconda3\lib\site-packages\flask\app.py", line 1951, in full_dispatch_request
    rv = self.handle_user_exception(e)
  File "C:\ProgramData\Anaconda3\lib\site-packages\flask\app.py", line 1820, in handle_user_exception
    reraise(exc_type, exc_value, tb)
  File "C:\ProgramData\Anaconda3\lib\site-packages\flask\_compat.py", line 39, in reraise
    raise value
  File "C:\ProgramData\Anaconda3\lib\site-packages\flask\app.py", line 1949, in full_dispatch_request
    rv = self.dispatch_request()
  File "C:\ProgramData\Anaconda3\lib\site-packages\flask\app.py", line 1935, in dispatch_request
    return self.view_functions[rule.endpoint](**req.view_args)
  File "C:\ProgramData\Anaconda3\lib\site-packages\dash\dash.py", line 1072, in dispatch
    response.set_data(func(*args, outputs_list=outputs_list))
  File "C:\ProgramData\Anaconda3\lib\site-packages\dash\dash.py", line 1007, in add_context
    output_value = func(*args, **kwargs)  # %% callback invoked %%
  File "C:\Users\joeda\OneDrive\Documents\GitHub\Scisat-App\scisat_app\scisat.py", line 671, in update_picker
    df =data_reader(gaz_list,r'data')
  File "C:\Users\joeda\OneDrive\Documents\GitHub\Scisat-App\scisat_app\scisat.py", line 75, in data_reader
    nc = netcdf.netcdf_file(name,'r')
  File "C:\ProgramData\Anaconda3\lib\site-packages\scipy\io\netcdf.py", line 249, in __init__
    self.fp = open(self.filename, '%sb' % omode)
FileNotFoundError: [Errno 2] No such file or directory: 'data//ACEFTS_L2_v4p1_O3.nc'
INFO:werkzeug:127.0.0.1 - - [09/Nov/2020 12:36:27] "[1m[35mPOST /scisat/_dash-update-component HTTP/1.1[0m" 500 -
ERROR:scisat_app.scisat:Exception on /_dash-update-component [POST]
Traceback (most recent call last):
  File "C:\ProgramData\Anaconda3\lib\site-packages\flask\app.py", line 2446, in wsgi_app
    response = self.full_dispatch_request()
  File "C:\ProgramData\Anaconda3\lib\site-packages\flask\app.py", line 1951, in full_dispatch_request
    rv = self.handle_user_exception(e)
  File "C:\ProgramData\Anaconda3\lib\site-packages\flask\app.py", line 1820, in handle_user_exception
    reraise(exc_type, exc_value, tb)
  File "C:\ProgramData\Anaconda3\lib\site-packages\flask\_compat.py", line 39, in reraise
    raise value
  File "C:\ProgramData\Anaconda3\lib\site-packages\flask\app.py", line 1949, in full_dispatch_request
    rv = self.dispatch_request()
  File "C:\ProgramData\Anaconda3\lib\site-packages\flask\app.py", line 1935, in dispatch_request
    return self.view_functions[rule.endpoint](**req.view_args)
  File "C:\ProgramData\Anaconda3\lib\site-packages\dash\dash.py", line 1072, in dispatch
    response.set_data(func(*args, outputs_list=outputs_list))
  File "C:\ProgramData\Anaconda3\lib\site-packages\dash\dash.py", line 1007, in add_context
    output_value = func(*args, **kwargs)  # %% callback invoked %%
  File "C:\Users\joeda\OneDrive\Documents\GitHub\Scisat-App\scisat_app\scisat.py", line 1677, in update_language_button
    language = session['language']
  File "C:\ProgramData\Anaconda3\lib\site-packages\werkzeug\local.py", line 378, in <lambda>
    __getitem__ = lambda x, i: x._get_current_object()[i]
  File "C:\ProgramData\Anaconda3\lib\site-packages\flask\sessions.py", line 84, in __getitem__
    return super(SecureCookieSession, self).__getitem__(key)
KeyError: 'language'
INFO:werkzeug:127.0.0.1 - - [09/Nov/2020 12:36:27] "[1m[35mPOST /scisat/_dash-update-component HTTP/1.1[0m" 500 -
INFO:werkzeug:127.0.0.1 - - [09/Nov/2020 12:36:27] "[37mPOST /scisat/_dash-update-component HTTP/1.1[0m" 200 -
INFO:werkzeug:127.0.0.1 - - [09/Nov/2020 12:36:27] "[37mPOST /scisat/_dash-update-component HTTP/1.1[0m" 200 -
INFO:werkzeug:127.0.0.1 - - [09/Nov/2020 12:36:27] "[36mGET /scisat/assets/csa-logo.png HTTP/1.1[0m" 304 -
INFO:werkzeug:127.0.0.1 - - [09/Nov/2020 12:36:27] "[37mPOST /scisat/_dash-update-component HTTP/1.1[0m" 200 -
INFO:werkzeug:127.0.0.1 - - [09/Nov/2020 12:36:28] "[37mPOST /scisat/_dash-update-component HTTP/1.1[0m" 200 -
ERROR:scisat_app.scisat:Exception on /_dash-update-component [POST]
Traceback (most recent call last):
  File "C:\ProgramData\Anaconda3\lib\site-packages\flask\app.py", line 2446, in wsgi_app
    response = self.full_dispatch_request()
  File "C:\ProgramData\Anaconda3\lib\site-packages\flask\app.py", line 1951, in full_dispatch_request
    rv = self.handle_user_exception(e)
  File "C:\ProgramData\Anaconda3\lib\site-packages\flask\app.py", line 1820, in handle_user_exception
    reraise(exc_type, exc_value, tb)
  File "C:\ProgramData\Anaconda3\lib\site-packages\flask\_compat.py", line 39, in reraise
    raise value
  File "C:\ProgramData\Anaconda3\lib\site-packages\flask\app.py", line 1949, in full_dispatch_request
    rv = self.dispatch_request()
  File "C:\ProgramData\Anaconda3\lib\site-packages\flask\app.py", line 1935, in dispatch_request
    return self.view_functions[rule.endpoint](**req.view_args)
  File "C:\ProgramData\Anaconda3\lib\site-packages\dash\dash.py", line 1072, in dispatch
    response.set_data(func(*args, outputs_list=outputs_list))
  File "C:\ProgramData\Anaconda3\lib\site-packages\dash\dash.py", line 1007, in add_context
    output_value = func(*args, **kwargs)  # %% callback invoked %%
  File "C:\Users\joeda\OneDrive\Documents\GitHub\Scisat-App\scisat_app\scisat.py", line 1190, in make_viz_chart
    df =data_reader(gaz_list,r'data',start_date,end_date,lat_min,lat_max,lon_min,lon_max,alt_range)
  File "C:\Users\joeda\OneDrive\Documents\GitHub\Scisat-App\scisat_app\scisat.py", line 75, in data_reader
    nc = netcdf.netcdf_file(name,'r')
  File "C:\ProgramData\Anaconda3\lib\site-packages\scipy\io\netcdf.py", line 249, in __init__
    self.fp = open(self.filename, '%sb' % omode)
FileNotFoundError: [Errno 2] No such file or directory: 'data//ACEFTS_L2_v4p1_O3.nc'
INFO:werkzeug:127.0.0.1 - - [09/Nov/2020 12:36:28] "[1m[35mPOST /scisat/_dash-update-component HTTP/1.1[0m" 500 -
ERROR:scisat_app.scisat:Exception on /_dash-update-component [POST]
Traceback (most recent call last):
  File "C:\ProgramData\Anaconda3\lib\site-packages\flask\app.py", line 2446, in wsgi_app
    response = self.full_dispatch_request()
  File "C:\ProgramData\Anaconda3\lib\site-packages\flask\app.py", line 1951, in full_dispatch_request
    rv = self.handle_user_exception(e)
  File "C:\ProgramData\Anaconda3\lib\site-packages\flask\app.py", line 1820, in handle_user_exception
    reraise(exc_type, exc_value, tb)
  File "C:\ProgramData\Anaconda3\lib\site-packages\flask\_compat.py", line 39, in reraise
    raise value
  File "C:\ProgramData\Anaconda3\lib\site-packages\flask\app.py", line 1949, in full_dispatch_request
    rv = self.dispatch_request()
  File "C:\ProgramData\Anaconda3\lib\site-packages\flask\app.py", line 1935, in dispatch_request
    return self.view_functions[rule.endpoint](**req.view_args)
  File "C:\ProgramData\Anaconda3\lib\site-packages\dash\dash.py", line 1072, in dispatch
    response.set_data(func(*args, outputs_list=outputs_list))
  File "C:\ProgramData\Anaconda3\lib\site-packages\dash\dash.py", line 1007, in add_context
    output_value = func(*args, **kwargs)  # %% callback invoked %%
  File "C:\Users\joeda\OneDrive\Documents\GitHub\Scisat-App\scisat_app\scisat.py", line 1075, in generate_geo_map
    df = data_reader(gaz_list,r'data',start_date,end_date,lat_min,lat_max,lon_min,lon_max,alt_range)
  File "C:\Users\joeda\OneDrive\Documents\GitHub\Scisat-App\scisat_app\scisat.py", line 75, in data_reader
    nc = netcdf.netcdf_file(name,'r')
  File "C:\ProgramData\Anaconda3\lib\site-packages\scipy\io\netcdf.py", line 249, in __init__
    self.fp = open(self.filename, '%sb' % omode)
FileNotFoundError: [Errno 2] No such file or directory: 'data//ACEFTS_L2_v4p1_O3.nc'
INFO:werkzeug:127.0.0.1 - - [09/Nov/2020 12:36:28] "[1m[35mPOST /scisat/_dash-update-component HTTP/1.1[0m" 500 -
ERROR:scisat_app.scisat:Exception on /_dash-update-component [POST]
Traceback (most recent call last):
  File "C:\ProgramData\Anaconda3\lib\site-packages\flask\app.py", line 2446, in wsgi_app
    response = self.full_dispatch_request()
  File "C:\ProgramData\Anaconda3\lib\site-packages\flask\app.py", line 1951, in full_dispatch_request
    rv = self.handle_user_exception(e)
  File "C:\ProgramData\Anaconda3\lib\site-packages\flask\app.py", line 1820, in handle_user_exception
    reraise(exc_type, exc_value, tb)
  File "C:\ProgramData\Anaconda3\lib\site-packages\flask\_compat.py", line 39, in reraise
    raise value
  File "C:\ProgramData\Anaconda3\lib\site-packages\flask\app.py", line 1949, in full_dispatch_request
    rv = self.dispatch_request()
  File "C:\ProgramData\Anaconda3\lib\site-packages\flask\app.py", line 1935, in dispatch_request
    return self.view_functions[rule.endpoint](**req.view_args)
  File "C:\ProgramData\Anaconda3\lib\site-packages\dash\dash.py", line 1072, in dispatch
    response.set_data(func(*args, outputs_list=outputs_list))
  File "C:\ProgramData\Anaconda3\lib\site-packages\dash\dash.py", line 1007, in add_context
    output_value = func(*args, **kwargs)  # %% callback invoked %%
  File "C:\Users\joeda\OneDrive\Documents\GitHub\Scisat-App\scisat_app\scisat.py", line 961, in make_count_figure
    df =data_reader(gaz_list,r'data',start_date,end_date,lat_min,lat_max,lon_min,lon_max,alt_range)
  File "C:\Users\joeda\OneDrive\Documents\GitHub\Scisat-App\scisat_app\scisat.py", line 75, in data_reader
    nc = netcdf.netcdf_file(name,'r')
  File "C:\ProgramData\Anaconda3\lib\site-packages\scipy\io\netcdf.py", line 249, in __init__
    self.fp = open(self.filename, '%sb' % omode)
FileNotFoundError: [Errno 2] No such file or directory: 'data//ACEFTS_L2_v4p1_O3.nc'
INFO:werkzeug:127.0.0.1 - - [09/Nov/2020 12:36:28] "[1m[35mPOST /scisat/_dash-update-component HTTP/1.1[0m" 500 -
INFO:werkzeug:127.0.0.1 - - [09/Nov/2020 12:36:28] "[37mPOST /scisat/_dash-update-component HTTP/1.1[0m" 200 -
ERROR:scisat_app.scisat:Exception on /_dash-update-component [POST]
Traceback (most recent call last):
  File "C:\ProgramData\Anaconda3\lib\site-packages\flask\app.py", line 2446, in wsgi_app
    response = self.full_dispatch_request()
  File "C:\ProgramData\Anaconda3\lib\site-packages\flask\app.py", line 1951, in full_dispatch_request
    rv = self.handle_user_exception(e)
  File "C:\ProgramData\Anaconda3\lib\site-packages\flask\app.py", line 1820, in handle_user_exception
    reraise(exc_type, exc_value, tb)
  File "C:\ProgramData\Anaconda3\lib\site-packages\flask\_compat.py", line 39, in reraise
    raise value
  File "C:\ProgramData\Anaconda3\lib\site-packages\flask\app.py", line 1949, in full_dispatch_request
    rv = self.dispatch_request()
  File "C:\ProgramData\Anaconda3\lib\site-packages\flask\app.py", line 1935, in dispatch_request
    return self.view_functions[rule.endpoint](**req.view_args)
  File "C:\ProgramData\Anaconda3\lib\site-packages\dash\dash.py", line 1072, in dispatch
    response.set_data(func(*args, outputs_list=outputs_list))
  File "C:\ProgramData\Anaconda3\lib\site-packages\dash\dash.py", line 1007, in add_context
    output_value = func(*args, **kwargs)  # %% callback invoked %%
  File "C:\Users\joeda\OneDrive\Documents\GitHub\Scisat-App\scisat_app\scisat.py", line 656, in update_filtering_text
    df =data_reader(gaz_list,r'data',start_date,end_date,lat_min,lat_max,lon_min,lon_max,alt_range)
  File "C:\Users\joeda\OneDrive\Documents\GitHub\Scisat-App\scisat_app\scisat.py", line 75, in data_reader
    nc = netcdf.netcdf_file(name,'r')
  File "C:\ProgramData\Anaconda3\lib\site-packages\scipy\io\netcdf.py", line 249, in __init__
    self.fp = open(self.filename, '%sb' % omode)
FileNotFoundError: [Errno 2] No such file or directory: 'data//ACEFTS_L2_v4p1_O3.nc'
INFO:werkzeug:127.0.0.1 - - [09/Nov/2020 12:36:28] "[1m[35mPOST /scisat/_dash-update-component HTTP/1.1[0m" 500 -
INFO:werkzeug: * Running on http://0.0.0.0:8888/ (Press CTRL+C to quit)
INFO:werkzeug:127.0.0.1 - - [09/Nov/2020 12:38:55] "[37mGET /scisat/ HTTP/1.1[0m" 200 -
INFO:werkzeug:127.0.0.1 - - [09/Nov/2020 12:38:55] "[37mGET /scisat/_dash-component-suites/dash_renderer/polyfill@7.v1_5_1m1593873890.8.7.min.js HTTP/1.1[0m" 200 -
INFO:werkzeug:127.0.0.1 - - [09/Nov/2020 12:38:55] "[37mGET /scisat/_dash-component-suites/dash_renderer/react@16.v1_5_1m1593873890.13.0.min.js HTTP/1.1[0m" 200 -
INFO:werkzeug:127.0.0.1 - - [09/Nov/2020 12:38:55] "[37mGET /scisat/_dash-component-suites/dash_renderer/react-dom@16.v1_5_1m1593873890.13.0.min.js HTTP/1.1[0m" 200 -
INFO:werkzeug:127.0.0.1 - - [09/Nov/2020 12:38:55] "[37mGET /scisat/_dash-component-suites/dash_renderer/prop-types@15.v1_5_1m1593873890.7.2.min.js HTTP/1.1[0m" 200 -
INFO:werkzeug:127.0.0.1 - - [09/Nov/2020 12:38:55] "[37mGET /scisat/_dash-component-suites/dash_dangerously_set_inner_html/bundle.v0_0_2m1593870401.js HTTP/1.1[0m" 200 -
INFO:werkzeug:127.0.0.1 - - [09/Nov/2020 12:38:55] "[37mGET /scisat/_dash-component-suites/dash_html_components/dash_html_components.v1_0_3m1593873891.min.js HTTP/1.1[0m" 200 -
INFO:werkzeug:127.0.0.1 - - [09/Nov/2020 12:38:55] "[37mGET /scisat/_dash-component-suites/dash_core_components/dash_core_components.v1_10_1m1593873890.min.js HTTP/1.1[0m" 200 -
INFO:werkzeug:127.0.0.1 - - [09/Nov/2020 12:38:55] "[37mGET /scisat/_dash-component-suites/dash_core_components/dash_core_components-shared.v1_10_1m1593873890.js HTTP/1.1[0m" 200 -
INFO:werkzeug:127.0.0.1 - - [09/Nov/2020 12:38:55] "[37mGET /scisat/_dash-component-suites/dash_renderer/dash_renderer.v1_5_1m1593873890.min.js HTTP/1.1[0m" 200 -
INFO:werkzeug:127.0.0.1 - - [09/Nov/2020 12:38:55] "[37mGET /scisat/_dash-layout HTTP/1.1[0m" 200 -
INFO:werkzeug:127.0.0.1 - - [09/Nov/2020 12:38:55] "[37mGET /scisat/_dash-dependencies HTTP/1.1[0m" 200 -
ERROR:scisat_app.scisat:Exception on /_dash-update-component [POST]
Traceback (most recent call last):
  File "C:\ProgramData\Anaconda3\lib\site-packages\flask\app.py", line 2446, in wsgi_app
    response = self.full_dispatch_request()
  File "C:\ProgramData\Anaconda3\lib\site-packages\flask\app.py", line 1951, in full_dispatch_request
    rv = self.handle_user_exception(e)
  File "C:\ProgramData\Anaconda3\lib\site-packages\flask\app.py", line 1820, in handle_user_exception
    reraise(exc_type, exc_value, tb)
  File "C:\ProgramData\Anaconda3\lib\site-packages\flask\_compat.py", line 39, in reraise
    raise value
  File "C:\ProgramData\Anaconda3\lib\site-packages\flask\app.py", line 1949, in full_dispatch_request
    rv = self.dispatch_request()
  File "C:\ProgramData\Anaconda3\lib\site-packages\flask\app.py", line 1935, in dispatch_request
    return self.view_functions[rule.endpoint](**req.view_args)
  File "C:\ProgramData\Anaconda3\lib\site-packages\dash\dash.py", line 1072, in dispatch
    response.set_data(func(*args, outputs_list=outputs_list))
  File "C:\ProgramData\Anaconda3\lib\site-packages\dash\dash.py", line 1007, in add_context
    output_value = func(*args, **kwargs)  # %% callback invoked %%
  File "C:\Users\joeda\OneDrive\Documents\GitHub\Scisat-App\scisat_app\scisat.py", line 671, in update_picker
    df =data_reader(gaz_list,r'data')
  File "C:\Users\joeda\OneDrive\Documents\GitHub\Scisat-App\scisat_app\scisat.py", line 75, in data_reader
    nc = netcdf.netcdf_file(name,'r')
  File "C:\ProgramData\Anaconda3\lib\site-packages\scipy\io\netcdf.py", line 249, in __init__
    self.fp = open(self.filename, '%sb' % omode)
FileNotFoundError: [Errno 2] No such file or directory: 'data//ACEFTS_L2_v4p1_O3.nc'
INFO:werkzeug:127.0.0.1 - - [09/Nov/2020 12:38:55] "[1m[35mPOST /scisat/_dash-update-component HTTP/1.1[0m" 500 -
ERROR:scisat_app.scisat:Exception on /_dash-update-component [POST]
Traceback (most recent call last):
  File "C:\ProgramData\Anaconda3\lib\site-packages\flask\app.py", line 2446, in wsgi_app
    response = self.full_dispatch_request()
  File "C:\ProgramData\Anaconda3\lib\site-packages\flask\app.py", line 1951, in full_dispatch_request
    rv = self.handle_user_exception(e)
  File "C:\ProgramData\Anaconda3\lib\site-packages\flask\app.py", line 1820, in handle_user_exception
    reraise(exc_type, exc_value, tb)
  File "C:\ProgramData\Anaconda3\lib\site-packages\flask\_compat.py", line 39, in reraise
    raise value
  File "C:\ProgramData\Anaconda3\lib\site-packages\flask\app.py", line 1949, in full_dispatch_request
    rv = self.dispatch_request()
  File "C:\ProgramData\Anaconda3\lib\site-packages\flask\app.py", line 1935, in dispatch_request
    return self.view_functions[rule.endpoint](**req.view_args)
  File "C:\ProgramData\Anaconda3\lib\site-packages\dash\dash.py", line 1072, in dispatch
    response.set_data(func(*args, outputs_list=outputs_list))
  File "C:\ProgramData\Anaconda3\lib\site-packages\dash\dash.py", line 1007, in add_context
    output_value = func(*args, **kwargs)  # %% callback invoked %%
  File "C:\Users\joeda\OneDrive\Documents\GitHub\Scisat-App\scisat_app\scisat.py", line 1677, in update_language_button
    language = session['language']
  File "C:\ProgramData\Anaconda3\lib\site-packages\werkzeug\local.py", line 378, in <lambda>
    __getitem__ = lambda x, i: x._get_current_object()[i]
  File "C:\ProgramData\Anaconda3\lib\site-packages\flask\sessions.py", line 84, in __getitem__
    return super(SecureCookieSession, self).__getitem__(key)
KeyError: 'language'
INFO:werkzeug:127.0.0.1 - - [09/Nov/2020 12:38:55] "[1m[35mPOST /scisat/_dash-update-component HTTP/1.1[0m" 500 -
INFO:werkzeug:127.0.0.1 - - [09/Nov/2020 12:38:55] "[37mPOST /scisat/_dash-update-component HTTP/1.1[0m" 200 -
INFO:werkzeug:127.0.0.1 - - [09/Nov/2020 12:38:55] "[37mPOST /scisat/_dash-update-component HTTP/1.1[0m" 200 -
INFO:werkzeug:127.0.0.1 - - [09/Nov/2020 12:38:55] "[36mGET /scisat/assets/csa-logo.png HTTP/1.1[0m" 304 -
INFO:werkzeug:127.0.0.1 - - [09/Nov/2020 12:38:56] "[37mPOST /scisat/_dash-update-component HTTP/1.1[0m" 200 -
INFO:werkzeug:127.0.0.1 - - [09/Nov/2020 12:38:56] "[37mPOST /scisat/_dash-update-component HTTP/1.1[0m" 200 -
ERROR:scisat_app.scisat:Exception on /_dash-update-component [POST]
Traceback (most recent call last):
  File "C:\ProgramData\Anaconda3\lib\site-packages\flask\app.py", line 2446, in wsgi_app
    response = self.full_dispatch_request()
  File "C:\ProgramData\Anaconda3\lib\site-packages\flask\app.py", line 1951, in full_dispatch_request
    rv = self.handle_user_exception(e)
  File "C:\ProgramData\Anaconda3\lib\site-packages\flask\app.py", line 1820, in handle_user_exception
    reraise(exc_type, exc_value, tb)
  File "C:\ProgramData\Anaconda3\lib\site-packages\flask\_compat.py", line 39, in reraise
    raise value
  File "C:\ProgramData\Anaconda3\lib\site-packages\flask\app.py", line 1949, in full_dispatch_request
    rv = self.dispatch_request()
  File "C:\ProgramData\Anaconda3\lib\site-packages\flask\app.py", line 1935, in dispatch_request
    return self.view_functions[rule.endpoint](**req.view_args)
  File "C:\ProgramData\Anaconda3\lib\site-packages\dash\dash.py", line 1072, in dispatch
    response.set_data(func(*args, outputs_list=outputs_list))
  File "C:\ProgramData\Anaconda3\lib\site-packages\dash\dash.py", line 1007, in add_context
    output_value = func(*args, **kwargs)  # %% callback invoked %%
  File "C:\Users\joeda\OneDrive\Documents\GitHub\Scisat-App\scisat_app\scisat.py", line 1190, in make_viz_chart
    df =data_reader(gaz_list,r'data',start_date,end_date,lat_min,lat_max,lon_min,lon_max,alt_range)
  File "C:\Users\joeda\OneDrive\Documents\GitHub\Scisat-App\scisat_app\scisat.py", line 75, in data_reader
    nc = netcdf.netcdf_file(name,'r')
  File "C:\ProgramData\Anaconda3\lib\site-packages\scipy\io\netcdf.py", line 249, in __init__
    self.fp = open(self.filename, '%sb' % omode)
FileNotFoundError: [Errno 2] No such file or directory: 'data//ACEFTS_L2_v4p1_O3.nc'
INFO:werkzeug:127.0.0.1 - - [09/Nov/2020 12:38:56] "[1m[35mPOST /scisat/_dash-update-component HTTP/1.1[0m" 500 -
ERROR:scisat_app.scisat:Exception on /_dash-update-component [POST]
Traceback (most recent call last):
  File "C:\ProgramData\Anaconda3\lib\site-packages\flask\app.py", line 2446, in wsgi_app
    response = self.full_dispatch_request()
  File "C:\ProgramData\Anaconda3\lib\site-packages\flask\app.py", line 1951, in full_dispatch_request
    rv = self.handle_user_exception(e)
  File "C:\ProgramData\Anaconda3\lib\site-packages\flask\app.py", line 1820, in handle_user_exception
    reraise(exc_type, exc_value, tb)
  File "C:\ProgramData\Anaconda3\lib\site-packages\flask\_compat.py", line 39, in reraise
    raise value
  File "C:\ProgramData\Anaconda3\lib\site-packages\flask\app.py", line 1949, in full_dispatch_request
    rv = self.dispatch_request()
  File "C:\ProgramData\Anaconda3\lib\site-packages\flask\app.py", line 1935, in dispatch_request
    return self.view_functions[rule.endpoint](**req.view_args)
  File "C:\ProgramData\Anaconda3\lib\site-packages\dash\dash.py", line 1072, in dispatch
    response.set_data(func(*args, outputs_list=outputs_list))
  File "C:\ProgramData\Anaconda3\lib\site-packages\dash\dash.py", line 1007, in add_context
    output_value = func(*args, **kwargs)  # %% callback invoked %%
  File "C:\Users\joeda\OneDrive\Documents\GitHub\Scisat-App\scisat_app\scisat.py", line 1075, in generate_geo_map
    df = data_reader(gaz_list,r'data',start_date,end_date,lat_min,lat_max,lon_min,lon_max,alt_range)
  File "C:\Users\joeda\OneDrive\Documents\GitHub\Scisat-App\scisat_app\scisat.py", line 75, in data_reader
    nc = netcdf.netcdf_file(name,'r')
  File "C:\ProgramData\Anaconda3\lib\site-packages\scipy\io\netcdf.py", line 249, in __init__
    self.fp = open(self.filename, '%sb' % omode)
FileNotFoundError: [Errno 2] No such file or directory: 'data//ACEFTS_L2_v4p1_O3.nc'
INFO:werkzeug:127.0.0.1 - - [09/Nov/2020 12:38:56] "[1m[35mPOST /scisat/_dash-update-component HTTP/1.1[0m" 500 -
ERROR:scisat_app.scisat:Exception on /_dash-update-component [POST]
Traceback (most recent call last):
  File "C:\ProgramData\Anaconda3\lib\site-packages\flask\app.py", line 2446, in wsgi_app
    response = self.full_dispatch_request()
  File "C:\ProgramData\Anaconda3\lib\site-packages\flask\app.py", line 1951, in full_dispatch_request
    rv = self.handle_user_exception(e)
  File "C:\ProgramData\Anaconda3\lib\site-packages\flask\app.py", line 1820, in handle_user_exception
    reraise(exc_type, exc_value, tb)
  File "C:\ProgramData\Anaconda3\lib\site-packages\flask\_compat.py", line 39, in reraise
    raise value
  File "C:\ProgramData\Anaconda3\lib\site-packages\flask\app.py", line 1949, in full_dispatch_request
    rv = self.dispatch_request()
  File "C:\ProgramData\Anaconda3\lib\site-packages\flask\app.py", line 1935, in dispatch_request
    return self.view_functions[rule.endpoint](**req.view_args)
  File "C:\ProgramData\Anaconda3\lib\site-packages\dash\dash.py", line 1072, in dispatch
    response.set_data(func(*args, outputs_list=outputs_list))
  File "C:\ProgramData\Anaconda3\lib\site-packages\dash\dash.py", line 1007, in add_context
    output_value = func(*args, **kwargs)  # %% callback invoked %%
  File "C:\Users\joeda\OneDrive\Documents\GitHub\Scisat-App\scisat_app\scisat.py", line 961, in make_count_figure
    df =data_reader(gaz_list,r'data',start_date,end_date,lat_min,lat_max,lon_min,lon_max,alt_range)
  File "C:\Users\joeda\OneDrive\Documents\GitHub\Scisat-App\scisat_app\scisat.py", line 75, in data_reader
    nc = netcdf.netcdf_file(name,'r')
  File "C:\ProgramData\Anaconda3\lib\site-packages\scipy\io\netcdf.py", line 249, in __init__
    self.fp = open(self.filename, '%sb' % omode)
FileNotFoundError: [Errno 2] No such file or directory: 'data//ACEFTS_L2_v4p1_O3.nc'
INFO:werkzeug:127.0.0.1 - - [09/Nov/2020 12:38:56] "[1m[35mPOST /scisat/_dash-update-component HTTP/1.1[0m" 500 -
INFO:werkzeug:127.0.0.1 - - [09/Nov/2020 12:38:56] "[37mPOST /scisat/_dash-update-component HTTP/1.1[0m" 200 -
ERROR:scisat_app.scisat:Exception on /_dash-update-component [POST]
Traceback (most recent call last):
  File "C:\ProgramData\Anaconda3\lib\site-packages\flask\app.py", line 2446, in wsgi_app
    response = self.full_dispatch_request()
  File "C:\ProgramData\Anaconda3\lib\site-packages\flask\app.py", line 1951, in full_dispatch_request
    rv = self.handle_user_exception(e)
  File "C:\ProgramData\Anaconda3\lib\site-packages\flask\app.py", line 1820, in handle_user_exception
    reraise(exc_type, exc_value, tb)
  File "C:\ProgramData\Anaconda3\lib\site-packages\flask\_compat.py", line 39, in reraise
    raise value
  File "C:\ProgramData\Anaconda3\lib\site-packages\flask\app.py", line 1949, in full_dispatch_request
    rv = self.dispatch_request()
  File "C:\ProgramData\Anaconda3\lib\site-packages\flask\app.py", line 1935, in dispatch_request
    return self.view_functions[rule.endpoint](**req.view_args)
  File "C:\ProgramData\Anaconda3\lib\site-packages\dash\dash.py", line 1072, in dispatch
    response.set_data(func(*args, outputs_list=outputs_list))
  File "C:\ProgramData\Anaconda3\lib\site-packages\dash\dash.py", line 1007, in add_context
    output_value = func(*args, **kwargs)  # %% callback invoked %%
  File "C:\Users\joeda\OneDrive\Documents\GitHub\Scisat-App\scisat_app\scisat.py", line 656, in update_filtering_text
    df =data_reader(gaz_list,r'data',start_date,end_date,lat_min,lat_max,lon_min,lon_max,alt_range)
  File "C:\Users\joeda\OneDrive\Documents\GitHub\Scisat-App\scisat_app\scisat.py", line 75, in data_reader
    nc = netcdf.netcdf_file(name,'r')
  File "C:\ProgramData\Anaconda3\lib\site-packages\scipy\io\netcdf.py", line 249, in __init__
    self.fp = open(self.filename, '%sb' % omode)
FileNotFoundError: [Errno 2] No such file or directory: 'data//ACEFTS_L2_v4p1_O3.nc'
INFO:werkzeug:127.0.0.1 - - [09/Nov/2020 12:38:56] "[1m[35mPOST /scisat/_dash-update-component HTTP/1.1[0m" 500 -
INFO:werkzeug:127.0.0.1 - - [09/Nov/2020 12:39:03] "[37mGET /scisat/assets/compiled.css?m=1595963752.208345 HTTP/1.1[0m" 200 -
INFO:werkzeug:127.0.0.1 - - [09/Nov/2020 12:39:03] "[37mGET /scisat/assets/compiled.css?m=1595963752.208345 HTTP/1.1[0m" 200 -
INFO:werkzeug: * Running on http://0.0.0.0:8888/ (Press CTRL+C to quit)
INFO:werkzeug:127.0.0.1 - - [09/Nov/2020 12:44:11] "[37mGET /scisat/ HTTP/1.1[0m" 200 -
INFO:werkzeug:127.0.0.1 - - [09/Nov/2020 12:44:12] "[37mGET /scisat/_dash-component-suites/dash_renderer/polyfill@7.v1_5_1m1593873890.8.7.min.js HTTP/1.1[0m" 200 -
INFO:werkzeug:127.0.0.1 - - [09/Nov/2020 12:44:12] "[37mGET /scisat/_dash-component-suites/dash_renderer/react@16.v1_5_1m1593873890.13.0.min.js HTTP/1.1[0m" 200 -
INFO:werkzeug:127.0.0.1 - - [09/Nov/2020 12:44:12] "[37mGET /scisat/_dash-component-suites/dash_renderer/react-dom@16.v1_5_1m1593873890.13.0.min.js HTTP/1.1[0m" 200 -
INFO:werkzeug:127.0.0.1 - - [09/Nov/2020 12:44:12] "[37mGET /scisat/_dash-component-suites/dash_renderer/prop-types@15.v1_5_1m1593873890.7.2.min.js HTTP/1.1[0m" 200 -
INFO:werkzeug:127.0.0.1 - - [09/Nov/2020 12:44:12] "[37mGET /scisat/_dash-component-suites/dash_dangerously_set_inner_html/bundle.v0_0_2m1593870401.js HTTP/1.1[0m" 200 -
INFO:werkzeug:127.0.0.1 - - [09/Nov/2020 12:44:12] "[37mGET /scisat/_dash-component-suites/dash_html_components/dash_html_components.v1_0_3m1593873891.min.js HTTP/1.1[0m" 200 -
INFO:werkzeug:127.0.0.1 - - [09/Nov/2020 12:44:12] "[37mGET /scisat/_dash-component-suites/dash_core_components/dash_core_components.v1_10_1m1593873890.min.js HTTP/1.1[0m" 200 -
INFO:werkzeug:127.0.0.1 - - [09/Nov/2020 12:44:12] "[37mGET /scisat/_dash-component-suites/dash_core_components/dash_core_components-shared.v1_10_1m1593873890.js HTTP/1.1[0m" 200 -
INFO:werkzeug:127.0.0.1 - - [09/Nov/2020 12:44:12] "[37mGET /scisat/_dash-component-suites/dash_renderer/dash_renderer.v1_5_1m1593873890.min.js HTTP/1.1[0m" 200 -
INFO:werkzeug:127.0.0.1 - - [09/Nov/2020 12:44:12] "[37mGET /scisat/_dash-layout HTTP/1.1[0m" 200 -
INFO:werkzeug:127.0.0.1 - - [09/Nov/2020 12:44:12] "[37mGET /scisat/_dash-dependencies HTTP/1.1[0m" 200 -
ERROR:scisat_app.scisat:Exception on /_dash-update-component [POST]
Traceback (most recent call last):
  File "C:\ProgramData\Anaconda3\lib\site-packages\flask\app.py", line 2446, in wsgi_app
    response = self.full_dispatch_request()
  File "C:\ProgramData\Anaconda3\lib\site-packages\flask\app.py", line 1951, in full_dispatch_request
    rv = self.handle_user_exception(e)
  File "C:\ProgramData\Anaconda3\lib\site-packages\flask\app.py", line 1820, in handle_user_exception
    reraise(exc_type, exc_value, tb)
  File "C:\ProgramData\Anaconda3\lib\site-packages\flask\_compat.py", line 39, in reraise
    raise value
  File "C:\ProgramData\Anaconda3\lib\site-packages\flask\app.py", line 1949, in full_dispatch_request
    rv = self.dispatch_request()
  File "C:\ProgramData\Anaconda3\lib\site-packages\flask\app.py", line 1935, in dispatch_request
    return self.view_functions[rule.endpoint](**req.view_args)
  File "C:\ProgramData\Anaconda3\lib\site-packages\dash\dash.py", line 1072, in dispatch
    response.set_data(func(*args, outputs_list=outputs_list))
  File "C:\ProgramData\Anaconda3\lib\site-packages\dash\dash.py", line 1007, in add_context
    output_value = func(*args, **kwargs)  # %% callback invoked %%
  File "C:\Users\joeda\OneDrive\Documents\GitHub\Scisat-App\scisat_app\scisat.py", line 671, in update_picker
    df =data_reader(gaz_list,r'data')
  File "C:\Users\joeda\OneDrive\Documents\GitHub\Scisat-App\scisat_app\scisat.py", line 75, in data_reader
    nc = netcdf.netcdf_file(name,'r')
  File "C:\ProgramData\Anaconda3\lib\site-packages\scipy\io\netcdf.py", line 249, in __init__
    self.fp = open(self.filename, '%sb' % omode)
FileNotFoundError: [Errno 2] No such file or directory: 'data//ACEFTS_L2_v4p1_O3.nc'
INFO:werkzeug:127.0.0.1 - - [09/Nov/2020 12:44:12] "[1m[35mPOST /scisat/_dash-update-component HTTP/1.1[0m" 500 -
ERROR:scisat_app.scisat:Exception on /_dash-update-component [POST]
Traceback (most recent call last):
  File "C:\ProgramData\Anaconda3\lib\site-packages\flask\app.py", line 2446, in wsgi_app
    response = self.full_dispatch_request()
  File "C:\ProgramData\Anaconda3\lib\site-packages\flask\app.py", line 1951, in full_dispatch_request
    rv = self.handle_user_exception(e)
  File "C:\ProgramData\Anaconda3\lib\site-packages\flask\app.py", line 1820, in handle_user_exception
    reraise(exc_type, exc_value, tb)
  File "C:\ProgramData\Anaconda3\lib\site-packages\flask\_compat.py", line 39, in reraise
    raise value
  File "C:\ProgramData\Anaconda3\lib\site-packages\flask\app.py", line 1949, in full_dispatch_request
    rv = self.dispatch_request()
  File "C:\ProgramData\Anaconda3\lib\site-packages\flask\app.py", line 1935, in dispatch_request
    return self.view_functions[rule.endpoint](**req.view_args)
  File "C:\ProgramData\Anaconda3\lib\site-packages\dash\dash.py", line 1072, in dispatch
    response.set_data(func(*args, outputs_list=outputs_list))
  File "C:\ProgramData\Anaconda3\lib\site-packages\dash\dash.py", line 1007, in add_context
    output_value = func(*args, **kwargs)  # %% callback invoked %%
  File "C:\Users\joeda\OneDrive\Documents\GitHub\Scisat-App\scisat_app\scisat.py", line 1677, in update_language_button
    language = session['language']
  File "C:\ProgramData\Anaconda3\lib\site-packages\werkzeug\local.py", line 378, in <lambda>
    __getitem__ = lambda x, i: x._get_current_object()[i]
  File "C:\ProgramData\Anaconda3\lib\site-packages\flask\sessions.py", line 84, in __getitem__
    return super(SecureCookieSession, self).__getitem__(key)
KeyError: 'language'
INFO:werkzeug:127.0.0.1 - - [09/Nov/2020 12:44:12] "[1m[35mPOST /scisat/_dash-update-component HTTP/1.1[0m" 500 -
INFO:werkzeug:127.0.0.1 - - [09/Nov/2020 12:44:12] "[37mPOST /scisat/_dash-update-component HTTP/1.1[0m" 200 -
INFO:werkzeug:127.0.0.1 - - [09/Nov/2020 12:44:12] "[37mPOST /scisat/_dash-update-component HTTP/1.1[0m" 200 -
INFO:werkzeug:127.0.0.1 - - [09/Nov/2020 12:44:12] "[37mGET /scisat/assets/csa-logo.png HTTP/1.1[0m" 200 -
INFO:werkzeug:127.0.0.1 - - [09/Nov/2020 12:44:12] "[37mGET /scisat/_dash-component-suites/dash_core_components/async-dropdown.v1_10_1m1592438751.js HTTP/1.1[0m" 200 -
INFO:werkzeug:127.0.0.1 - - [09/Nov/2020 12:44:12] "[37mGET /scisat/_dash-component-suites/dash_core_components/async-graph.v1_10_1m1592438751.js HTTP/1.1[0m" 200 -
INFO:werkzeug:127.0.0.1 - - [09/Nov/2020 12:44:12] "[37mGET /scisat/_favicon.ico?v=1.16.3 HTTP/1.1[0m" 200 -
INFO:werkzeug:127.0.0.1 - - [09/Nov/2020 12:44:13] "[37mPOST /scisat/_dash-update-component HTTP/1.1[0m" 200 -
INFO:werkzeug:127.0.0.1 - - [09/Nov/2020 12:44:13] "[37mPOST /scisat/_dash-update-component HTTP/1.1[0m" 200 -
ERROR:scisat_app.scisat:Exception on /_dash-update-component [POST]
Traceback (most recent call last):
  File "C:\ProgramData\Anaconda3\lib\site-packages\flask\app.py", line 2446, in wsgi_app
    response = self.full_dispatch_request()
  File "C:\ProgramData\Anaconda3\lib\site-packages\flask\app.py", line 1951, in full_dispatch_request
    rv = self.handle_user_exception(e)
  File "C:\ProgramData\Anaconda3\lib\site-packages\flask\app.py", line 1820, in handle_user_exception
    reraise(exc_type, exc_value, tb)
  File "C:\ProgramData\Anaconda3\lib\site-packages\flask\_compat.py", line 39, in reraise
    raise value
  File "C:\ProgramData\Anaconda3\lib\site-packages\flask\app.py", line 1949, in full_dispatch_request
    rv = self.dispatch_request()
  File "C:\ProgramData\Anaconda3\lib\site-packages\flask\app.py", line 1935, in dispatch_request
    return self.view_functions[rule.endpoint](**req.view_args)
  File "C:\ProgramData\Anaconda3\lib\site-packages\dash\dash.py", line 1072, in dispatch
    response.set_data(func(*args, outputs_list=outputs_list))
  File "C:\ProgramData\Anaconda3\lib\site-packages\dash\dash.py", line 1007, in add_context
    output_value = func(*args, **kwargs)  # %% callback invoked %%
  File "C:\Users\joeda\OneDrive\Documents\GitHub\Scisat-App\scisat_app\scisat.py", line 1190, in make_viz_chart
    df =data_reader(gaz_list,r'data',start_date,end_date,lat_min,lat_max,lon_min,lon_max,alt_range)
  File "C:\Users\joeda\OneDrive\Documents\GitHub\Scisat-App\scisat_app\scisat.py", line 75, in data_reader
    nc = netcdf.netcdf_file(name,'r')
  File "C:\ProgramData\Anaconda3\lib\site-packages\scipy\io\netcdf.py", line 249, in __init__
    self.fp = open(self.filename, '%sb' % omode)
FileNotFoundError: [Errno 2] No such file or directory: 'data//ACEFTS_L2_v4p1_O3.nc'
INFO:werkzeug:127.0.0.1 - - [09/Nov/2020 12:44:13] "[1m[35mPOST /scisat/_dash-update-component HTTP/1.1[0m" 500 -
ERROR:scisat_app.scisat:Exception on /_dash-update-component [POST]
Traceback (most recent call last):
  File "C:\ProgramData\Anaconda3\lib\site-packages\flask\app.py", line 2446, in wsgi_app
    response = self.full_dispatch_request()
  File "C:\ProgramData\Anaconda3\lib\site-packages\flask\app.py", line 1951, in full_dispatch_request
    rv = self.handle_user_exception(e)
  File "C:\ProgramData\Anaconda3\lib\site-packages\flask\app.py", line 1820, in handle_user_exception
    reraise(exc_type, exc_value, tb)
  File "C:\ProgramData\Anaconda3\lib\site-packages\flask\_compat.py", line 39, in reraise
    raise value
  File "C:\ProgramData\Anaconda3\lib\site-packages\flask\app.py", line 1949, in full_dispatch_request
    rv = self.dispatch_request()
  File "C:\ProgramData\Anaconda3\lib\site-packages\flask\app.py", line 1935, in dispatch_request
    return self.view_functions[rule.endpoint](**req.view_args)
  File "C:\ProgramData\Anaconda3\lib\site-packages\dash\dash.py", line 1072, in dispatch
    response.set_data(func(*args, outputs_list=outputs_list))
  File "C:\ProgramData\Anaconda3\lib\site-packages\dash\dash.py", line 1007, in add_context
    output_value = func(*args, **kwargs)  # %% callback invoked %%
  File "C:\Users\joeda\OneDrive\Documents\GitHub\Scisat-App\scisat_app\scisat.py", line 1075, in generate_geo_map
    df = data_reader(gaz_list,r'data',start_date,end_date,lat_min,lat_max,lon_min,lon_max,alt_range)
  File "C:\Users\joeda\OneDrive\Documents\GitHub\Scisat-App\scisat_app\scisat.py", line 75, in data_reader
    nc = netcdf.netcdf_file(name,'r')
  File "C:\ProgramData\Anaconda3\lib\site-packages\scipy\io\netcdf.py", line 249, in __init__
    self.fp = open(self.filename, '%sb' % omode)
FileNotFoundError: [Errno 2] No such file or directory: 'data//ACEFTS_L2_v4p1_O3.nc'
INFO:werkzeug:127.0.0.1 - - [09/Nov/2020 12:44:13] "[1m[35mPOST /scisat/_dash-update-component HTTP/1.1[0m" 500 -
ERROR:scisat_app.scisat:Exception on /_dash-update-component [POST]
Traceback (most recent call last):
  File "C:\ProgramData\Anaconda3\lib\site-packages\flask\app.py", line 2446, in wsgi_app
    response = self.full_dispatch_request()
  File "C:\ProgramData\Anaconda3\lib\site-packages\flask\app.py", line 1951, in full_dispatch_request
    rv = self.handle_user_exception(e)
  File "C:\ProgramData\Anaconda3\lib\site-packages\flask\app.py", line 1820, in handle_user_exception
    reraise(exc_type, exc_value, tb)
  File "C:\ProgramData\Anaconda3\lib\site-packages\flask\_compat.py", line 39, in reraise
    raise value
  File "C:\ProgramData\Anaconda3\lib\site-packages\flask\app.py", line 1949, in full_dispatch_request
    rv = self.dispatch_request()
  File "C:\ProgramData\Anaconda3\lib\site-packages\flask\app.py", line 1935, in dispatch_request
    return self.view_functions[rule.endpoint](**req.view_args)
  File "C:\ProgramData\Anaconda3\lib\site-packages\dash\dash.py", line 1072, in dispatch
    response.set_data(func(*args, outputs_list=outputs_list))
  File "C:\ProgramData\Anaconda3\lib\site-packages\dash\dash.py", line 1007, in add_context
    output_value = func(*args, **kwargs)  # %% callback invoked %%
  File "C:\Users\joeda\OneDrive\Documents\GitHub\Scisat-App\scisat_app\scisat.py", line 961, in make_count_figure
    df =data_reader(gaz_list,r'data',start_date,end_date,lat_min,lat_max,lon_min,lon_max,alt_range)
  File "C:\Users\joeda\OneDrive\Documents\GitHub\Scisat-App\scisat_app\scisat.py", line 75, in data_reader
    nc = netcdf.netcdf_file(name,'r')
  File "C:\ProgramData\Anaconda3\lib\site-packages\scipy\io\netcdf.py", line 249, in __init__
    self.fp = open(self.filename, '%sb' % omode)
FileNotFoundError: [Errno 2] No such file or directory: 'data//ACEFTS_L2_v4p1_O3.nc'
INFO:werkzeug:127.0.0.1 - - [09/Nov/2020 12:44:13] "[1m[35mPOST /scisat/_dash-update-component HTTP/1.1[0m" 500 -
INFO:werkzeug:127.0.0.1 - - [09/Nov/2020 12:44:13] "[37mPOST /scisat/_dash-update-component HTTP/1.1[0m" 200 -
ERROR:scisat_app.scisat:Exception on /_dash-update-component [POST]
Traceback (most recent call last):
  File "C:\ProgramData\Anaconda3\lib\site-packages\flask\app.py", line 2446, in wsgi_app
    response = self.full_dispatch_request()
  File "C:\ProgramData\Anaconda3\lib\site-packages\flask\app.py", line 1951, in full_dispatch_request
    rv = self.handle_user_exception(e)
  File "C:\ProgramData\Anaconda3\lib\site-packages\flask\app.py", line 1820, in handle_user_exception
    reraise(exc_type, exc_value, tb)
  File "C:\ProgramData\Anaconda3\lib\site-packages\flask\_compat.py", line 39, in reraise
    raise value
  File "C:\ProgramData\Anaconda3\lib\site-packages\flask\app.py", line 1949, in full_dispatch_request
    rv = self.dispatch_request()
  File "C:\ProgramData\Anaconda3\lib\site-packages\flask\app.py", line 1935, in dispatch_request
    return self.view_functions[rule.endpoint](**req.view_args)
  File "C:\ProgramData\Anaconda3\lib\site-packages\dash\dash.py", line 1072, in dispatch
    response.set_data(func(*args, outputs_list=outputs_list))
  File "C:\ProgramData\Anaconda3\lib\site-packages\dash\dash.py", line 1007, in add_context
    output_value = func(*args, **kwargs)  # %% callback invoked %%
  File "C:\Users\joeda\OneDrive\Documents\GitHub\Scisat-App\scisat_app\scisat.py", line 656, in update_filtering_text
    df =data_reader(gaz_list,r'data',start_date,end_date,lat_min,lat_max,lon_min,lon_max,alt_range)
  File "C:\Users\joeda\OneDrive\Documents\GitHub\Scisat-App\scisat_app\scisat.py", line 75, in data_reader
    nc = netcdf.netcdf_file(name,'r')
  File "C:\ProgramData\Anaconda3\lib\site-packages\scipy\io\netcdf.py", line 249, in __init__
    self.fp = open(self.filename, '%sb' % omode)
FileNotFoundError: [Errno 2] No such file or directory: 'data//ACEFTS_L2_v4p1_O3.nc'
INFO:werkzeug:127.0.0.1 - - [09/Nov/2020 12:44:13] "[1m[35mPOST /scisat/_dash-update-component HTTP/1.1[0m" 500 -
INFO:werkzeug:127.0.0.1 - - [09/Nov/2020 12:44:18] "[37mGET /scisat/assets/compiled.css?m=1595963752.208345 HTTP/1.1[0m" 200 -
INFO:werkzeug: * Running on http://0.0.0.0:8888/ (Press CTRL+C to quit)
INFO:werkzeug:127.0.0.1 - - [09/Nov/2020 12:54:07] "[37mGET /scisat/ HTTP/1.1[0m" 200 -
INFO:werkzeug:127.0.0.1 - - [09/Nov/2020 12:54:07] "[37mGET /scisat/_dash-layout HTTP/1.1[0m" 200 -
INFO:werkzeug:127.0.0.1 - - [09/Nov/2020 12:54:07] "[37mGET /scisat/_dash-dependencies HTTP/1.1[0m" 200 -
ERROR:scisat_app.scisat:Exception on /_dash-update-component [POST]
Traceback (most recent call last):
  File "C:\ProgramData\Anaconda3\lib\site-packages\flask\app.py", line 2446, in wsgi_app
    response = self.full_dispatch_request()
  File "C:\ProgramData\Anaconda3\lib\site-packages\flask\app.py", line 1951, in full_dispatch_request
    rv = self.handle_user_exception(e)
  File "C:\ProgramData\Anaconda3\lib\site-packages\flask\app.py", line 1820, in handle_user_exception
    reraise(exc_type, exc_value, tb)
  File "C:\ProgramData\Anaconda3\lib\site-packages\flask\_compat.py", line 39, in reraise
    raise value
  File "C:\ProgramData\Anaconda3\lib\site-packages\flask\app.py", line 1949, in full_dispatch_request
    rv = self.dispatch_request()
  File "C:\ProgramData\Anaconda3\lib\site-packages\flask\app.py", line 1935, in dispatch_request
    return self.view_functions[rule.endpoint](**req.view_args)
  File "C:\ProgramData\Anaconda3\lib\site-packages\dash\dash.py", line 1072, in dispatch
    response.set_data(func(*args, outputs_list=outputs_list))
  File "C:\ProgramData\Anaconda3\lib\site-packages\dash\dash.py", line 1007, in add_context
    output_value = func(*args, **kwargs)  # %% callback invoked %%
  File "C:\Users\joeda\OneDrive\Documents\GitHub\Scisat-App\scisat_app\scisat.py", line 671, in update_picker
    df =data_reader(gaz_list,r'data')
  File "C:\Users\joeda\OneDrive\Documents\GitHub\Scisat-App\scisat_app\scisat.py", line 75, in data_reader
    nc = netcdf.netcdf_file(name,'r')
  File "C:\ProgramData\Anaconda3\lib\site-packages\scipy\io\netcdf.py", line 249, in __init__
    self.fp = open(self.filename, '%sb' % omode)
FileNotFoundError: [Errno 2] No such file or directory: 'data//ACEFTS_L2_v4p1_O3.nc'
INFO:werkzeug:127.0.0.1 - - [09/Nov/2020 12:54:08] "[1m[35mPOST /scisat/_dash-update-component HTTP/1.1[0m" 500 -
ERROR:scisat_app.scisat:Exception on /_dash-update-component [POST]
Traceback (most recent call last):
  File "C:\ProgramData\Anaconda3\lib\site-packages\flask\app.py", line 2446, in wsgi_app
    response = self.full_dispatch_request()
  File "C:\ProgramData\Anaconda3\lib\site-packages\flask\app.py", line 1951, in full_dispatch_request
    rv = self.handle_user_exception(e)
  File "C:\ProgramData\Anaconda3\lib\site-packages\flask\app.py", line 1820, in handle_user_exception
    reraise(exc_type, exc_value, tb)
  File "C:\ProgramData\Anaconda3\lib\site-packages\flask\_compat.py", line 39, in reraise
    raise value
  File "C:\ProgramData\Anaconda3\lib\site-packages\flask\app.py", line 1949, in full_dispatch_request
    rv = self.dispatch_request()
  File "C:\ProgramData\Anaconda3\lib\site-packages\flask\app.py", line 1935, in dispatch_request
    return self.view_functions[rule.endpoint](**req.view_args)
  File "C:\ProgramData\Anaconda3\lib\site-packages\dash\dash.py", line 1072, in dispatch
    response.set_data(func(*args, outputs_list=outputs_list))
  File "C:\ProgramData\Anaconda3\lib\site-packages\dash\dash.py", line 1007, in add_context
    output_value = func(*args, **kwargs)  # %% callback invoked %%
  File "C:\Users\joeda\OneDrive\Documents\GitHub\Scisat-App\scisat_app\scisat.py", line 1677, in update_language_button
    language = session['language']
  File "C:\ProgramData\Anaconda3\lib\site-packages\werkzeug\local.py", line 378, in <lambda>
    __getitem__ = lambda x, i: x._get_current_object()[i]
  File "C:\ProgramData\Anaconda3\lib\site-packages\flask\sessions.py", line 84, in __getitem__
    return super(SecureCookieSession, self).__getitem__(key)
KeyError: 'language'
INFO:werkzeug:127.0.0.1 - - [09/Nov/2020 12:54:08] "[1m[35mPOST /scisat/_dash-update-component HTTP/1.1[0m" 500 -
INFO:werkzeug:127.0.0.1 - - [09/Nov/2020 12:54:08] "[37mPOST /scisat/_dash-update-component HTTP/1.1[0m" 200 -
INFO:werkzeug:127.0.0.1 - - [09/Nov/2020 12:54:08] "[37mPOST /scisat/_dash-update-component HTTP/1.1[0m" 200 -
INFO:werkzeug:127.0.0.1 - - [09/Nov/2020 12:54:08] "[37mGET /scisat/_dash-component-suites/dash_core_components/async-dropdown.v1_10_1m1592438751.js HTTP/1.1[0m" 200 -
INFO:werkzeug:127.0.0.1 - - [09/Nov/2020 12:54:08] "[37mGET /scisat/_dash-component-suites/dash_core_components/async-graph.v1_10_1m1592438751.js HTTP/1.1[0m" 200 -
INFO:werkzeug:127.0.0.1 - - [09/Nov/2020 12:54:08] "[37mGET /scisat/_dash-component-suites/dash_core_components/async-slider.v1_10_1m1592438751.js HTTP/1.1[0m" 200 -
INFO:werkzeug:127.0.0.1 - - [09/Nov/2020 12:54:08] "[37mGET /scisat/_favicon.ico?v=1.16.3 HTTP/1.1[0m" 200 -
INFO:werkzeug:127.0.0.1 - - [09/Nov/2020 12:54:08] "[37mPOST /scisat/_dash-update-component HTTP/1.1[0m" 200 -
INFO:werkzeug:127.0.0.1 - - [09/Nov/2020 12:54:08] "[37mPOST /scisat/_dash-update-component HTTP/1.1[0m" 200 -
ERROR:scisat_app.scisat:Exception on /_dash-update-component [POST]
Traceback (most recent call last):
  File "C:\ProgramData\Anaconda3\lib\site-packages\flask\app.py", line 2446, in wsgi_app
    response = self.full_dispatch_request()
  File "C:\ProgramData\Anaconda3\lib\site-packages\flask\app.py", line 1951, in full_dispatch_request
    rv = self.handle_user_exception(e)
  File "C:\ProgramData\Anaconda3\lib\site-packages\flask\app.py", line 1820, in handle_user_exception
    reraise(exc_type, exc_value, tb)
  File "C:\ProgramData\Anaconda3\lib\site-packages\flask\_compat.py", line 39, in reraise
    raise value
  File "C:\ProgramData\Anaconda3\lib\site-packages\flask\app.py", line 1949, in full_dispatch_request
    rv = self.dispatch_request()
  File "C:\ProgramData\Anaconda3\lib\site-packages\flask\app.py", line 1935, in dispatch_request
    return self.view_functions[rule.endpoint](**req.view_args)
  File "C:\ProgramData\Anaconda3\lib\site-packages\dash\dash.py", line 1072, in dispatch
    response.set_data(func(*args, outputs_list=outputs_list))
  File "C:\ProgramData\Anaconda3\lib\site-packages\dash\dash.py", line 1007, in add_context
    output_value = func(*args, **kwargs)  # %% callback invoked %%
  File "C:\Users\joeda\OneDrive\Documents\GitHub\Scisat-App\scisat_app\scisat.py", line 1190, in make_viz_chart
    df =data_reader(gaz_list,r'data',start_date,end_date,lat_min,lat_max,lon_min,lon_max,alt_range)
  File "C:\Users\joeda\OneDrive\Documents\GitHub\Scisat-App\scisat_app\scisat.py", line 75, in data_reader
    nc = netcdf.netcdf_file(name,'r')
  File "C:\ProgramData\Anaconda3\lib\site-packages\scipy\io\netcdf.py", line 249, in __init__
    self.fp = open(self.filename, '%sb' % omode)
FileNotFoundError: [Errno 2] No such file or directory: 'data//ACEFTS_L2_v4p1_O3.nc'
INFO:werkzeug:127.0.0.1 - - [09/Nov/2020 12:54:09] "[1m[35mPOST /scisat/_dash-update-component HTTP/1.1[0m" 500 -
ERROR:scisat_app.scisat:Exception on /_dash-update-component [POST]
Traceback (most recent call last):
  File "C:\ProgramData\Anaconda3\lib\site-packages\flask\app.py", line 2446, in wsgi_app
    response = self.full_dispatch_request()
  File "C:\ProgramData\Anaconda3\lib\site-packages\flask\app.py", line 1951, in full_dispatch_request
    rv = self.handle_user_exception(e)
  File "C:\ProgramData\Anaconda3\lib\site-packages\flask\app.py", line 1820, in handle_user_exception
    reraise(exc_type, exc_value, tb)
  File "C:\ProgramData\Anaconda3\lib\site-packages\flask\_compat.py", line 39, in reraise
    raise value
  File "C:\ProgramData\Anaconda3\lib\site-packages\flask\app.py", line 1949, in full_dispatch_request
    rv = self.dispatch_request()
  File "C:\ProgramData\Anaconda3\lib\site-packages\flask\app.py", line 1935, in dispatch_request
    return self.view_functions[rule.endpoint](**req.view_args)
  File "C:\ProgramData\Anaconda3\lib\site-packages\dash\dash.py", line 1072, in dispatch
    response.set_data(func(*args, outputs_list=outputs_list))
  File "C:\ProgramData\Anaconda3\lib\site-packages\dash\dash.py", line 1007, in add_context
    output_value = func(*args, **kwargs)  # %% callback invoked %%
  File "C:\Users\joeda\OneDrive\Documents\GitHub\Scisat-App\scisat_app\scisat.py", line 1075, in generate_geo_map
    df = data_reader(gaz_list,r'data',start_date,end_date,lat_min,lat_max,lon_min,lon_max,alt_range)
  File "C:\Users\joeda\OneDrive\Documents\GitHub\Scisat-App\scisat_app\scisat.py", line 75, in data_reader
    nc = netcdf.netcdf_file(name,'r')
  File "C:\ProgramData\Anaconda3\lib\site-packages\scipy\io\netcdf.py", line 249, in __init__
    self.fp = open(self.filename, '%sb' % omode)
FileNotFoundError: [Errno 2] No such file or directory: 'data//ACEFTS_L2_v4p1_O3.nc'
INFO:werkzeug:127.0.0.1 - - [09/Nov/2020 12:54:09] "[1m[35mPOST /scisat/_dash-update-component HTTP/1.1[0m" 500 -
ERROR:scisat_app.scisat:Exception on /_dash-update-component [POST]
Traceback (most recent call last):
  File "C:\ProgramData\Anaconda3\lib\site-packages\flask\app.py", line 2446, in wsgi_app
    response = self.full_dispatch_request()
  File "C:\ProgramData\Anaconda3\lib\site-packages\flask\app.py", line 1951, in full_dispatch_request
    rv = self.handle_user_exception(e)
  File "C:\ProgramData\Anaconda3\lib\site-packages\flask\app.py", line 1820, in handle_user_exception
    reraise(exc_type, exc_value, tb)
  File "C:\ProgramData\Anaconda3\lib\site-packages\flask\_compat.py", line 39, in reraise
    raise value
  File "C:\ProgramData\Anaconda3\lib\site-packages\flask\app.py", line 1949, in full_dispatch_request
    rv = self.dispatch_request()
  File "C:\ProgramData\Anaconda3\lib\site-packages\flask\app.py", line 1935, in dispatch_request
    return self.view_functions[rule.endpoint](**req.view_args)
  File "C:\ProgramData\Anaconda3\lib\site-packages\dash\dash.py", line 1072, in dispatch
    response.set_data(func(*args, outputs_list=outputs_list))
  File "C:\ProgramData\Anaconda3\lib\site-packages\dash\dash.py", line 1007, in add_context
    output_value = func(*args, **kwargs)  # %% callback invoked %%
  File "C:\Users\joeda\OneDrive\Documents\GitHub\Scisat-App\scisat_app\scisat.py", line 961, in make_count_figure
    df =data_reader(gaz_list,r'data',start_date,end_date,lat_min,lat_max,lon_min,lon_max,alt_range)
  File "C:\Users\joeda\OneDrive\Documents\GitHub\Scisat-App\scisat_app\scisat.py", line 75, in data_reader
    nc = netcdf.netcdf_file(name,'r')
  File "C:\ProgramData\Anaconda3\lib\site-packages\scipy\io\netcdf.py", line 249, in __init__
    self.fp = open(self.filename, '%sb' % omode)
FileNotFoundError: [Errno 2] No such file or directory: 'data//ACEFTS_L2_v4p1_O3.nc'
INFO:werkzeug:127.0.0.1 - - [09/Nov/2020 12:54:09] "[1m[35mPOST /scisat/_dash-update-component HTTP/1.1[0m" 500 -
INFO:werkzeug:127.0.0.1 - - [09/Nov/2020 12:54:09] "[37mPOST /scisat/_dash-update-component HTTP/1.1[0m" 200 -
ERROR:scisat_app.scisat:Exception on /_dash-update-component [POST]
Traceback (most recent call last):
  File "C:\ProgramData\Anaconda3\lib\site-packages\flask\app.py", line 2446, in wsgi_app
    response = self.full_dispatch_request()
  File "C:\ProgramData\Anaconda3\lib\site-packages\flask\app.py", line 1951, in full_dispatch_request
    rv = self.handle_user_exception(e)
  File "C:\ProgramData\Anaconda3\lib\site-packages\flask\app.py", line 1820, in handle_user_exception
    reraise(exc_type, exc_value, tb)
  File "C:\ProgramData\Anaconda3\lib\site-packages\flask\_compat.py", line 39, in reraise
    raise value
  File "C:\ProgramData\Anaconda3\lib\site-packages\flask\app.py", line 1949, in full_dispatch_request
    rv = self.dispatch_request()
  File "C:\ProgramData\Anaconda3\lib\site-packages\flask\app.py", line 1935, in dispatch_request
    return self.view_functions[rule.endpoint](**req.view_args)
  File "C:\ProgramData\Anaconda3\lib\site-packages\dash\dash.py", line 1072, in dispatch
    response.set_data(func(*args, outputs_list=outputs_list))
  File "C:\ProgramData\Anaconda3\lib\site-packages\dash\dash.py", line 1007, in add_context
    output_value = func(*args, **kwargs)  # %% callback invoked %%
  File "C:\Users\joeda\OneDrive\Documents\GitHub\Scisat-App\scisat_app\scisat.py", line 656, in update_filtering_text
    df =data_reader(gaz_list,r'data',start_date,end_date,lat_min,lat_max,lon_min,lon_max,alt_range)
  File "C:\Users\joeda\OneDrive\Documents\GitHub\Scisat-App\scisat_app\scisat.py", line 75, in data_reader
    nc = netcdf.netcdf_file(name,'r')
  File "C:\ProgramData\Anaconda3\lib\site-packages\scipy\io\netcdf.py", line 249, in __init__
    self.fp = open(self.filename, '%sb' % omode)
FileNotFoundError: [Errno 2] No such file or directory: 'data//ACEFTS_L2_v4p1_O3.nc'
INFO:werkzeug:127.0.0.1 - - [09/Nov/2020 12:54:09] "[1m[35mPOST /scisat/_dash-update-component HTTP/1.1[0m" 500 -
INFO:werkzeug:127.0.0.1 - - [09/Nov/2020 12:54:51] "[37mGET / HTTP/1.1[0m" 200 -
INFO:werkzeug:127.0.0.1 - - [09/Nov/2020 12:54:51] "[33mGET /favicon.ico HTTP/1.1[0m" 404 -
INFO:werkzeug:127.0.0.1 - - [09/Nov/2020 12:54:57] "[37mGET /scisat/ HTTP/1.1[0m" 200 -
INFO:werkzeug:127.0.0.1 - - [09/Nov/2020 12:54:58] "[37mGET /scisat/_dash-layout HTTP/1.1[0m" 200 -
INFO:werkzeug:127.0.0.1 - - [09/Nov/2020 12:54:58] "[37mGET /scisat/_dash-dependencies HTTP/1.1[0m" 200 -
ERROR:scisat_app.scisat:Exception on /_dash-update-component [POST]
Traceback (most recent call last):
  File "C:\ProgramData\Anaconda3\lib\site-packages\flask\app.py", line 2446, in wsgi_app
    response = self.full_dispatch_request()
  File "C:\ProgramData\Anaconda3\lib\site-packages\flask\app.py", line 1951, in full_dispatch_request
    rv = self.handle_user_exception(e)
  File "C:\ProgramData\Anaconda3\lib\site-packages\flask\app.py", line 1820, in handle_user_exception
    reraise(exc_type, exc_value, tb)
  File "C:\ProgramData\Anaconda3\lib\site-packages\flask\_compat.py", line 39, in reraise
    raise value
  File "C:\ProgramData\Anaconda3\lib\site-packages\flask\app.py", line 1949, in full_dispatch_request
    rv = self.dispatch_request()
  File "C:\ProgramData\Anaconda3\lib\site-packages\flask\app.py", line 1935, in dispatch_request
    return self.view_functions[rule.endpoint](**req.view_args)
  File "C:\ProgramData\Anaconda3\lib\site-packages\dash\dash.py", line 1072, in dispatch
    response.set_data(func(*args, outputs_list=outputs_list))
  File "C:\ProgramData\Anaconda3\lib\site-packages\dash\dash.py", line 1007, in add_context
    output_value = func(*args, **kwargs)  # %% callback invoked %%
  File "C:\Users\joeda\OneDrive\Documents\GitHub\Scisat-App\scisat_app\scisat.py", line 671, in update_picker
    df =data_reader(gaz_list,r'data')
  File "C:\Users\joeda\OneDrive\Documents\GitHub\Scisat-App\scisat_app\scisat.py", line 75, in data_reader
    nc = netcdf.netcdf_file(name,'r')
  File "C:\ProgramData\Anaconda3\lib\site-packages\scipy\io\netcdf.py", line 249, in __init__
    self.fp = open(self.filename, '%sb' % omode)
FileNotFoundError: [Errno 2] No such file or directory: 'data//ACEFTS_L2_v4p1_O3.nc'
INFO:werkzeug:127.0.0.1 - - [09/Nov/2020 12:54:58] "[1m[35mPOST /scisat/_dash-update-component HTTP/1.1[0m" 500 -
ERROR:scisat_app.scisat:Exception on /_dash-update-component [POST]
Traceback (most recent call last):
  File "C:\ProgramData\Anaconda3\lib\site-packages\flask\app.py", line 2446, in wsgi_app
    response = self.full_dispatch_request()
  File "C:\ProgramData\Anaconda3\lib\site-packages\flask\app.py", line 1951, in full_dispatch_request
    rv = self.handle_user_exception(e)
  File "C:\ProgramData\Anaconda3\lib\site-packages\flask\app.py", line 1820, in handle_user_exception
    reraise(exc_type, exc_value, tb)
  File "C:\ProgramData\Anaconda3\lib\site-packages\flask\_compat.py", line 39, in reraise
    raise value
  File "C:\ProgramData\Anaconda3\lib\site-packages\flask\app.py", line 1949, in full_dispatch_request
    rv = self.dispatch_request()
  File "C:\ProgramData\Anaconda3\lib\site-packages\flask\app.py", line 1935, in dispatch_request
    return self.view_functions[rule.endpoint](**req.view_args)
  File "C:\ProgramData\Anaconda3\lib\site-packages\dash\dash.py", line 1072, in dispatch
    response.set_data(func(*args, outputs_list=outputs_list))
  File "C:\ProgramData\Anaconda3\lib\site-packages\dash\dash.py", line 1007, in add_context
    output_value = func(*args, **kwargs)  # %% callback invoked %%
  File "C:\Users\joeda\OneDrive\Documents\GitHub\Scisat-App\scisat_app\scisat.py", line 1677, in update_language_button
    language = session['language']
  File "C:\ProgramData\Anaconda3\lib\site-packages\werkzeug\local.py", line 378, in <lambda>
    __getitem__ = lambda x, i: x._get_current_object()[i]
  File "C:\ProgramData\Anaconda3\lib\site-packages\flask\sessions.py", line 84, in __getitem__
    return super(SecureCookieSession, self).__getitem__(key)
KeyError: 'language'
INFO:werkzeug:127.0.0.1 - - [09/Nov/2020 12:54:58] "[1m[35mPOST /scisat/_dash-update-component HTTP/1.1[0m" 500 -
INFO:werkzeug:127.0.0.1 - - [09/Nov/2020 12:54:58] "[37mPOST /scisat/_dash-update-component HTTP/1.1[0m" 200 -
INFO:werkzeug:127.0.0.1 - - [09/Nov/2020 12:54:58] "[37mPOST /scisat/_dash-update-component HTTP/1.1[0m" 200 -
INFO:werkzeug:127.0.0.1 - - [09/Nov/2020 12:54:59] "[37mPOST /scisat/_dash-update-component HTTP/1.1[0m" 200 -
INFO:werkzeug:127.0.0.1 - - [09/Nov/2020 12:54:59] "[37mGET /scisat/_favicon.ico?v=1.16.3 HTTP/1.1[0m" 200 -
INFO:werkzeug:127.0.0.1 - - [09/Nov/2020 12:54:59] "[37mPOST /scisat/_dash-update-component HTTP/1.1[0m" 200 -
ERROR:scisat_app.scisat:Exception on /_dash-update-component [POST]
Traceback (most recent call last):
  File "C:\ProgramData\Anaconda3\lib\site-packages\flask\app.py", line 2446, in wsgi_app
    response = self.full_dispatch_request()
  File "C:\ProgramData\Anaconda3\lib\site-packages\flask\app.py", line 1951, in full_dispatch_request
    rv = self.handle_user_exception(e)
  File "C:\ProgramData\Anaconda3\lib\site-packages\flask\app.py", line 1820, in handle_user_exception
    reraise(exc_type, exc_value, tb)
  File "C:\ProgramData\Anaconda3\lib\site-packages\flask\_compat.py", line 39, in reraise
    raise value
  File "C:\ProgramData\Anaconda3\lib\site-packages\flask\app.py", line 1949, in full_dispatch_request
    rv = self.dispatch_request()
  File "C:\ProgramData\Anaconda3\lib\site-packages\flask\app.py", line 1935, in dispatch_request
    return self.view_functions[rule.endpoint](**req.view_args)
  File "C:\ProgramData\Anaconda3\lib\site-packages\dash\dash.py", line 1072, in dispatch
    response.set_data(func(*args, outputs_list=outputs_list))
  File "C:\ProgramData\Anaconda3\lib\site-packages\dash\dash.py", line 1007, in add_context
    output_value = func(*args, **kwargs)  # %% callback invoked %%
  File "C:\Users\joeda\OneDrive\Documents\GitHub\Scisat-App\scisat_app\scisat.py", line 1190, in make_viz_chart
    df =data_reader(gaz_list,r'data',start_date,end_date,lat_min,lat_max,lon_min,lon_max,alt_range)
  File "C:\Users\joeda\OneDrive\Documents\GitHub\Scisat-App\scisat_app\scisat.py", line 75, in data_reader
    nc = netcdf.netcdf_file(name,'r')
  File "C:\ProgramData\Anaconda3\lib\site-packages\scipy\io\netcdf.py", line 249, in __init__
    self.fp = open(self.filename, '%sb' % omode)
FileNotFoundError: [Errno 2] No such file or directory: 'data//ACEFTS_L2_v4p1_O3.nc'
INFO:werkzeug:127.0.0.1 - - [09/Nov/2020 12:54:59] "[1m[35mPOST /scisat/_dash-update-component HTTP/1.1[0m" 500 -
ERROR:scisat_app.scisat:Exception on /_dash-update-component [POST]
Traceback (most recent call last):
  File "C:\ProgramData\Anaconda3\lib\site-packages\flask\app.py", line 2446, in wsgi_app
    response = self.full_dispatch_request()
  File "C:\ProgramData\Anaconda3\lib\site-packages\flask\app.py", line 1951, in full_dispatch_request
    rv = self.handle_user_exception(e)
  File "C:\ProgramData\Anaconda3\lib\site-packages\flask\app.py", line 1820, in handle_user_exception
    reraise(exc_type, exc_value, tb)
  File "C:\ProgramData\Anaconda3\lib\site-packages\flask\_compat.py", line 39, in reraise
    raise value
  File "C:\ProgramData\Anaconda3\lib\site-packages\flask\app.py", line 1949, in full_dispatch_request
    rv = self.dispatch_request()
  File "C:\ProgramData\Anaconda3\lib\site-packages\flask\app.py", line 1935, in dispatch_request
    return self.view_functions[rule.endpoint](**req.view_args)
  File "C:\ProgramData\Anaconda3\lib\site-packages\dash\dash.py", line 1072, in dispatch
    response.set_data(func(*args, outputs_list=outputs_list))
  File "C:\ProgramData\Anaconda3\lib\site-packages\dash\dash.py", line 1007, in add_context
    output_value = func(*args, **kwargs)  # %% callback invoked %%
  File "C:\Users\joeda\OneDrive\Documents\GitHub\Scisat-App\scisat_app\scisat.py", line 1075, in generate_geo_map
    df = data_reader(gaz_list,r'data',start_date,end_date,lat_min,lat_max,lon_min,lon_max,alt_range)
  File "C:\Users\joeda\OneDrive\Documents\GitHub\Scisat-App\scisat_app\scisat.py", line 75, in data_reader
    nc = netcdf.netcdf_file(name,'r')
  File "C:\ProgramData\Anaconda3\lib\site-packages\scipy\io\netcdf.py", line 249, in __init__
    self.fp = open(self.filename, '%sb' % omode)
FileNotFoundError: [Errno 2] No such file or directory: 'data//ACEFTS_L2_v4p1_O3.nc'
INFO:werkzeug:127.0.0.1 - - [09/Nov/2020 12:54:59] "[1m[35mPOST /scisat/_dash-update-component HTTP/1.1[0m" 500 -
ERROR:scisat_app.scisat:Exception on /_dash-update-component [POST]
Traceback (most recent call last):
  File "C:\ProgramData\Anaconda3\lib\site-packages\flask\app.py", line 2446, in wsgi_app
    response = self.full_dispatch_request()
  File "C:\ProgramData\Anaconda3\lib\site-packages\flask\app.py", line 1951, in full_dispatch_request
    rv = self.handle_user_exception(e)
  File "C:\ProgramData\Anaconda3\lib\site-packages\flask\app.py", line 1820, in handle_user_exception
    reraise(exc_type, exc_value, tb)
  File "C:\ProgramData\Anaconda3\lib\site-packages\flask\_compat.py", line 39, in reraise
    raise value
  File "C:\ProgramData\Anaconda3\lib\site-packages\flask\app.py", line 1949, in full_dispatch_request
    rv = self.dispatch_request()
  File "C:\ProgramData\Anaconda3\lib\site-packages\flask\app.py", line 1935, in dispatch_request
    return self.view_functions[rule.endpoint](**req.view_args)
  File "C:\ProgramData\Anaconda3\lib\site-packages\dash\dash.py", line 1072, in dispatch
    response.set_data(func(*args, outputs_list=outputs_list))
  File "C:\ProgramData\Anaconda3\lib\site-packages\dash\dash.py", line 1007, in add_context
    output_value = func(*args, **kwargs)  # %% callback invoked %%
  File "C:\Users\joeda\OneDrive\Documents\GitHub\Scisat-App\scisat_app\scisat.py", line 961, in make_count_figure
    df =data_reader(gaz_list,r'data',start_date,end_date,lat_min,lat_max,lon_min,lon_max,alt_range)
  File "C:\Users\joeda\OneDrive\Documents\GitHub\Scisat-App\scisat_app\scisat.py", line 75, in data_reader
    nc = netcdf.netcdf_file(name,'r')
  File "C:\ProgramData\Anaconda3\lib\site-packages\scipy\io\netcdf.py", line 249, in __init__
    self.fp = open(self.filename, '%sb' % omode)
FileNotFoundError: [Errno 2] No such file or directory: 'data//ACEFTS_L2_v4p1_O3.nc'
INFO:werkzeug:127.0.0.1 - - [09/Nov/2020 12:54:59] "[1m[35mPOST /scisat/_dash-update-component HTTP/1.1[0m" 500 -
INFO:werkzeug:127.0.0.1 - - [09/Nov/2020 12:54:59] "[37mPOST /scisat/_dash-update-component HTTP/1.1[0m" 200 -
ERROR:scisat_app.scisat:Exception on /_dash-update-component [POST]
Traceback (most recent call last):
  File "C:\ProgramData\Anaconda3\lib\site-packages\flask\app.py", line 2446, in wsgi_app
    response = self.full_dispatch_request()
  File "C:\ProgramData\Anaconda3\lib\site-packages\flask\app.py", line 1951, in full_dispatch_request
    rv = self.handle_user_exception(e)
  File "C:\ProgramData\Anaconda3\lib\site-packages\flask\app.py", line 1820, in handle_user_exception
    reraise(exc_type, exc_value, tb)
  File "C:\ProgramData\Anaconda3\lib\site-packages\flask\_compat.py", line 39, in reraise
    raise value
  File "C:\ProgramData\Anaconda3\lib\site-packages\flask\app.py", line 1949, in full_dispatch_request
    rv = self.dispatch_request()
  File "C:\ProgramData\Anaconda3\lib\site-packages\flask\app.py", line 1935, in dispatch_request
    return self.view_functions[rule.endpoint](**req.view_args)
  File "C:\ProgramData\Anaconda3\lib\site-packages\dash\dash.py", line 1072, in dispatch
    response.set_data(func(*args, outputs_list=outputs_list))
  File "C:\ProgramData\Anaconda3\lib\site-packages\dash\dash.py", line 1007, in add_context
    output_value = func(*args, **kwargs)  # %% callback invoked %%
  File "C:\Users\joeda\OneDrive\Documents\GitHub\Scisat-App\scisat_app\scisat.py", line 656, in update_filtering_text
    df =data_reader(gaz_list,r'data',start_date,end_date,lat_min,lat_max,lon_min,lon_max,alt_range)
  File "C:\Users\joeda\OneDrive\Documents\GitHub\Scisat-App\scisat_app\scisat.py", line 75, in data_reader
    nc = netcdf.netcdf_file(name,'r')
  File "C:\ProgramData\Anaconda3\lib\site-packages\scipy\io\netcdf.py", line 249, in __init__
    self.fp = open(self.filename, '%sb' % omode)
FileNotFoundError: [Errno 2] No such file or directory: 'data//ACEFTS_L2_v4p1_O3.nc'
INFO:werkzeug:127.0.0.1 - - [09/Nov/2020 12:54:59] "[1m[35mPOST /scisat/_dash-update-component HTTP/1.1[0m" 500 -
INFO:werkzeug:127.0.0.1 - - [09/Nov/2020 12:56:10] "[37mGET /scisat/ HTTP/1.1[0m" 200 -
INFO:werkzeug:127.0.0.1 - - [09/Nov/2020 12:56:10] "[37mGET /scisat/_dash-component-suites/dash_renderer/polyfill@7.v1_5_1m1593873890.8.7.min.js HTTP/1.1[0m" 200 -
INFO:werkzeug:127.0.0.1 - - [09/Nov/2020 12:56:10] "[37mGET /scisat/_dash-component-suites/dash_renderer/react@16.v1_5_1m1593873890.13.0.min.js HTTP/1.1[0m" 200 -
INFO:werkzeug:127.0.0.1 - - [09/Nov/2020 12:56:10] "[37mGET /scisat/_dash-component-suites/dash_renderer/react-dom@16.v1_5_1m1593873890.13.0.min.js HTTP/1.1[0m" 200 -
INFO:werkzeug:127.0.0.1 - - [09/Nov/2020 12:56:10] "[37mGET /scisat/_dash-component-suites/dash_renderer/prop-types@15.v1_5_1m1593873890.7.2.min.js HTTP/1.1[0m" 200 -
INFO:werkzeug:127.0.0.1 - - [09/Nov/2020 12:56:10] "[37mGET /scisat/_dash-component-suites/dash_dangerously_set_inner_html/bundle.v0_0_2m1593870401.js HTTP/1.1[0m" 200 -
INFO:werkzeug:127.0.0.1 - - [09/Nov/2020 12:56:10] "[37mGET /scisat/_dash-component-suites/dash_html_components/dash_html_components.v1_0_3m1593873891.min.js HTTP/1.1[0m" 200 -
INFO:werkzeug:127.0.0.1 - - [09/Nov/2020 12:56:10] "[37mGET /scisat/_dash-component-suites/dash_core_components/dash_core_components.v1_10_1m1593873890.min.js HTTP/1.1[0m" 200 -
INFO:werkzeug:127.0.0.1 - - [09/Nov/2020 12:56:11] "[37mGET /scisat/_dash-layout HTTP/1.1[0m" 200 -
INFO:werkzeug:127.0.0.1 - - [09/Nov/2020 12:56:11] "[37mGET /scisat/_dash-dependencies HTTP/1.1[0m" 200 -
ERROR:scisat_app.scisat:Exception on /_dash-update-component [POST]
Traceback (most recent call last):
  File "C:\ProgramData\Anaconda3\lib\site-packages\flask\app.py", line 2446, in wsgi_app
    response = self.full_dispatch_request()
  File "C:\ProgramData\Anaconda3\lib\site-packages\flask\app.py", line 1951, in full_dispatch_request
    rv = self.handle_user_exception(e)
  File "C:\ProgramData\Anaconda3\lib\site-packages\flask\app.py", line 1820, in handle_user_exception
    reraise(exc_type, exc_value, tb)
  File "C:\ProgramData\Anaconda3\lib\site-packages\flask\_compat.py", line 39, in reraise
    raise value
  File "C:\ProgramData\Anaconda3\lib\site-packages\flask\app.py", line 1949, in full_dispatch_request
    rv = self.dispatch_request()
  File "C:\ProgramData\Anaconda3\lib\site-packages\flask\app.py", line 1935, in dispatch_request
    return self.view_functions[rule.endpoint](**req.view_args)
  File "C:\ProgramData\Anaconda3\lib\site-packages\dash\dash.py", line 1072, in dispatch
    response.set_data(func(*args, outputs_list=outputs_list))
  File "C:\ProgramData\Anaconda3\lib\site-packages\dash\dash.py", line 1007, in add_context
    output_value = func(*args, **kwargs)  # %% callback invoked %%
  File "C:\Users\joeda\OneDrive\Documents\GitHub\Scisat-App\scisat_app\scisat.py", line 671, in update_picker
    df =data_reader(gaz_list,r'data')
  File "C:\Users\joeda\OneDrive\Documents\GitHub\Scisat-App\scisat_app\scisat.py", line 75, in data_reader
    nc = netcdf.netcdf_file(name,'r')
  File "C:\ProgramData\Anaconda3\lib\site-packages\scipy\io\netcdf.py", line 249, in __init__
    self.fp = open(self.filename, '%sb' % omode)
FileNotFoundError: [Errno 2] No such file or directory: 'data//ACEFTS_L2_v4p1_O3.nc'
INFO:werkzeug:127.0.0.1 - - [09/Nov/2020 12:56:11] "[1m[35mPOST /scisat/_dash-update-component HTTP/1.1[0m" 500 -
ERROR:scisat_app.scisat:Exception on /_dash-update-component [POST]
Traceback (most recent call last):
  File "C:\ProgramData\Anaconda3\lib\site-packages\flask\app.py", line 2446, in wsgi_app
    response = self.full_dispatch_request()
  File "C:\ProgramData\Anaconda3\lib\site-packages\flask\app.py", line 1951, in full_dispatch_request
    rv = self.handle_user_exception(e)
  File "C:\ProgramData\Anaconda3\lib\site-packages\flask\app.py", line 1820, in handle_user_exception
    reraise(exc_type, exc_value, tb)
  File "C:\ProgramData\Anaconda3\lib\site-packages\flask\_compat.py", line 39, in reraise
    raise value
  File "C:\ProgramData\Anaconda3\lib\site-packages\flask\app.py", line 1949, in full_dispatch_request
    rv = self.dispatch_request()
  File "C:\ProgramData\Anaconda3\lib\site-packages\flask\app.py", line 1935, in dispatch_request
    return self.view_functions[rule.endpoint](**req.view_args)
  File "C:\ProgramData\Anaconda3\lib\site-packages\dash\dash.py", line 1072, in dispatch
    response.set_data(func(*args, outputs_list=outputs_list))
  File "C:\ProgramData\Anaconda3\lib\site-packages\dash\dash.py", line 1007, in add_context
    output_value = func(*args, **kwargs)  # %% callback invoked %%
  File "C:\Users\joeda\OneDrive\Documents\GitHub\Scisat-App\scisat_app\scisat.py", line 1677, in update_language_button
    language = session['language']
  File "C:\ProgramData\Anaconda3\lib\site-packages\werkzeug\local.py", line 378, in <lambda>
    __getitem__ = lambda x, i: x._get_current_object()[i]
  File "C:\ProgramData\Anaconda3\lib\site-packages\flask\sessions.py", line 84, in __getitem__
    return super(SecureCookieSession, self).__getitem__(key)
KeyError: 'language'
INFO:werkzeug:127.0.0.1 - - [09/Nov/2020 12:56:11] "[1m[35mPOST /scisat/_dash-update-component HTTP/1.1[0m" 500 -
INFO:werkzeug:127.0.0.1 - - [09/Nov/2020 12:56:11] "[37mPOST /scisat/_dash-update-component HTTP/1.1[0m" 200 -
INFO:werkzeug:127.0.0.1 - - [09/Nov/2020 12:56:11] "[37mPOST /scisat/_dash-update-component HTTP/1.1[0m" 200 -
INFO:werkzeug:127.0.0.1 - - [09/Nov/2020 12:56:11] "[37mGET /scisat/_favicon.ico?v=1.16.3 HTTP/1.1[0m" 200 -
INFO:werkzeug:127.0.0.1 - - [09/Nov/2020 12:56:11] "[37mPOST /scisat/_dash-update-component HTTP/1.1[0m" 200 -
INFO:werkzeug:127.0.0.1 - - [09/Nov/2020 12:56:12] "[37mPOST /scisat/_dash-update-component HTTP/1.1[0m" 200 -
ERROR:scisat_app.scisat:Exception on /_dash-update-component [POST]
Traceback (most recent call last):
  File "C:\ProgramData\Anaconda3\lib\site-packages\flask\app.py", line 2446, in wsgi_app
    response = self.full_dispatch_request()
  File "C:\ProgramData\Anaconda3\lib\site-packages\flask\app.py", line 1951, in full_dispatch_request
    rv = self.handle_user_exception(e)
  File "C:\ProgramData\Anaconda3\lib\site-packages\flask\app.py", line 1820, in handle_user_exception
    reraise(exc_type, exc_value, tb)
  File "C:\ProgramData\Anaconda3\lib\site-packages\flask\_compat.py", line 39, in reraise
    raise value
  File "C:\ProgramData\Anaconda3\lib\site-packages\flask\app.py", line 1949, in full_dispatch_request
    rv = self.dispatch_request()
  File "C:\ProgramData\Anaconda3\lib\site-packages\flask\app.py", line 1935, in dispatch_request
    return self.view_functions[rule.endpoint](**req.view_args)
  File "C:\ProgramData\Anaconda3\lib\site-packages\dash\dash.py", line 1072, in dispatch
    response.set_data(func(*args, outputs_list=outputs_list))
  File "C:\ProgramData\Anaconda3\lib\site-packages\dash\dash.py", line 1007, in add_context
    output_value = func(*args, **kwargs)  # %% callback invoked %%
  File "C:\Users\joeda\OneDrive\Documents\GitHub\Scisat-App\scisat_app\scisat.py", line 1190, in make_viz_chart
    df =data_reader(gaz_list,r'data',start_date,end_date,lat_min,lat_max,lon_min,lon_max,alt_range)
  File "C:\Users\joeda\OneDrive\Documents\GitHub\Scisat-App\scisat_app\scisat.py", line 75, in data_reader
    nc = netcdf.netcdf_file(name,'r')
  File "C:\ProgramData\Anaconda3\lib\site-packages\scipy\io\netcdf.py", line 249, in __init__
    self.fp = open(self.filename, '%sb' % omode)
FileNotFoundError: [Errno 2] No such file or directory: 'data//ACEFTS_L2_v4p1_O3.nc'
INFO:werkzeug:127.0.0.1 - - [09/Nov/2020 12:56:12] "[1m[35mPOST /scisat/_dash-update-component HTTP/1.1[0m" 500 -
ERROR:scisat_app.scisat:Exception on /_dash-update-component [POST]
Traceback (most recent call last):
  File "C:\ProgramData\Anaconda3\lib\site-packages\flask\app.py", line 2446, in wsgi_app
    response = self.full_dispatch_request()
  File "C:\ProgramData\Anaconda3\lib\site-packages\flask\app.py", line 1951, in full_dispatch_request
    rv = self.handle_user_exception(e)
  File "C:\ProgramData\Anaconda3\lib\site-packages\flask\app.py", line 1820, in handle_user_exception
    reraise(exc_type, exc_value, tb)
  File "C:\ProgramData\Anaconda3\lib\site-packages\flask\_compat.py", line 39, in reraise
    raise value
  File "C:\ProgramData\Anaconda3\lib\site-packages\flask\app.py", line 1949, in full_dispatch_request
    rv = self.dispatch_request()
  File "C:\ProgramData\Anaconda3\lib\site-packages\flask\app.py", line 1935, in dispatch_request
    return self.view_functions[rule.endpoint](**req.view_args)
  File "C:\ProgramData\Anaconda3\lib\site-packages\dash\dash.py", line 1072, in dispatch
    response.set_data(func(*args, outputs_list=outputs_list))
  File "C:\ProgramData\Anaconda3\lib\site-packages\dash\dash.py", line 1007, in add_context
    output_value = func(*args, **kwargs)  # %% callback invoked %%
  File "C:\Users\joeda\OneDrive\Documents\GitHub\Scisat-App\scisat_app\scisat.py", line 1075, in generate_geo_map
    df = data_reader(gaz_list,r'data',start_date,end_date,lat_min,lat_max,lon_min,lon_max,alt_range)
  File "C:\Users\joeda\OneDrive\Documents\GitHub\Scisat-App\scisat_app\scisat.py", line 75, in data_reader
    nc = netcdf.netcdf_file(name,'r')
  File "C:\ProgramData\Anaconda3\lib\site-packages\scipy\io\netcdf.py", line 249, in __init__
    self.fp = open(self.filename, '%sb' % omode)
FileNotFoundError: [Errno 2] No such file or directory: 'data//ACEFTS_L2_v4p1_O3.nc'
INFO:werkzeug:127.0.0.1 - - [09/Nov/2020 12:56:12] "[1m[35mPOST /scisat/_dash-update-component HTTP/1.1[0m" 500 -
ERROR:scisat_app.scisat:Exception on /_dash-update-component [POST]
Traceback (most recent call last):
  File "C:\ProgramData\Anaconda3\lib\site-packages\flask\app.py", line 2446, in wsgi_app
    response = self.full_dispatch_request()
  File "C:\ProgramData\Anaconda3\lib\site-packages\flask\app.py", line 1951, in full_dispatch_request
    rv = self.handle_user_exception(e)
  File "C:\ProgramData\Anaconda3\lib\site-packages\flask\app.py", line 1820, in handle_user_exception
    reraise(exc_type, exc_value, tb)
  File "C:\ProgramData\Anaconda3\lib\site-packages\flask\_compat.py", line 39, in reraise
    raise value
  File "C:\ProgramData\Anaconda3\lib\site-packages\flask\app.py", line 1949, in full_dispatch_request
    rv = self.dispatch_request()
  File "C:\ProgramData\Anaconda3\lib\site-packages\flask\app.py", line 1935, in dispatch_request
    return self.view_functions[rule.endpoint](**req.view_args)
  File "C:\ProgramData\Anaconda3\lib\site-packages\dash\dash.py", line 1072, in dispatch
    response.set_data(func(*args, outputs_list=outputs_list))
  File "C:\ProgramData\Anaconda3\lib\site-packages\dash\dash.py", line 1007, in add_context
    output_value = func(*args, **kwargs)  # %% callback invoked %%
  File "C:\Users\joeda\OneDrive\Documents\GitHub\Scisat-App\scisat_app\scisat.py", line 961, in make_count_figure
    df =data_reader(gaz_list,r'data',start_date,end_date,lat_min,lat_max,lon_min,lon_max,alt_range)
  File "C:\Users\joeda\OneDrive\Documents\GitHub\Scisat-App\scisat_app\scisat.py", line 75, in data_reader
    nc = netcdf.netcdf_file(name,'r')
  File "C:\ProgramData\Anaconda3\lib\site-packages\scipy\io\netcdf.py", line 249, in __init__
    self.fp = open(self.filename, '%sb' % omode)
FileNotFoundError: [Errno 2] No such file or directory: 'data//ACEFTS_L2_v4p1_O3.nc'
INFO:werkzeug:127.0.0.1 - - [09/Nov/2020 12:56:12] "[1m[35mPOST /scisat/_dash-update-component HTTP/1.1[0m" 500 -
INFO:werkzeug:127.0.0.1 - - [09/Nov/2020 12:56:12] "[37mPOST /scisat/_dash-update-component HTTP/1.1[0m" 200 -
ERROR:scisat_app.scisat:Exception on /_dash-update-component [POST]
Traceback (most recent call last):
  File "C:\ProgramData\Anaconda3\lib\site-packages\flask\app.py", line 2446, in wsgi_app
    response = self.full_dispatch_request()
  File "C:\ProgramData\Anaconda3\lib\site-packages\flask\app.py", line 1951, in full_dispatch_request
    rv = self.handle_user_exception(e)
  File "C:\ProgramData\Anaconda3\lib\site-packages\flask\app.py", line 1820, in handle_user_exception
    reraise(exc_type, exc_value, tb)
  File "C:\ProgramData\Anaconda3\lib\site-packages\flask\_compat.py", line 39, in reraise
    raise value
  File "C:\ProgramData\Anaconda3\lib\site-packages\flask\app.py", line 1949, in full_dispatch_request
    rv = self.dispatch_request()
  File "C:\ProgramData\Anaconda3\lib\site-packages\flask\app.py", line 1935, in dispatch_request
    return self.view_functions[rule.endpoint](**req.view_args)
  File "C:\ProgramData\Anaconda3\lib\site-packages\dash\dash.py", line 1072, in dispatch
    response.set_data(func(*args, outputs_list=outputs_list))
  File "C:\ProgramData\Anaconda3\lib\site-packages\dash\dash.py", line 1007, in add_context
    output_value = func(*args, **kwargs)  # %% callback invoked %%
  File "C:\Users\joeda\OneDrive\Documents\GitHub\Scisat-App\scisat_app\scisat.py", line 656, in update_filtering_text
    df =data_reader(gaz_list,r'data',start_date,end_date,lat_min,lat_max,lon_min,lon_max,alt_range)
  File "C:\Users\joeda\OneDrive\Documents\GitHub\Scisat-App\scisat_app\scisat.py", line 75, in data_reader
    nc = netcdf.netcdf_file(name,'r')
  File "C:\ProgramData\Anaconda3\lib\site-packages\scipy\io\netcdf.py", line 249, in __init__
    self.fp = open(self.filename, '%sb' % omode)
FileNotFoundError: [Errno 2] No such file or directory: 'data//ACEFTS_L2_v4p1_O3.nc'
INFO:werkzeug:127.0.0.1 - - [09/Nov/2020 12:56:12] "[1m[35mPOST /scisat/_dash-update-component HTTP/1.1[0m" 500 -
INFO:werkzeug: * Running on http://0.0.0.0:8888/ (Press CTRL+C to quit)
INFO:werkzeug:127.0.0.1 - - [09/Nov/2020 12:56:27] "[37mGET /scisat/ HTTP/1.1[0m" 200 -
INFO:werkzeug:127.0.0.1 - - [09/Nov/2020 12:56:27] "[37mGET /scisat/_dash-component-suites/dash_renderer/polyfill@7.v1_5_1m1593873890.8.7.min.js HTTP/1.1[0m" 200 -
INFO:werkzeug:127.0.0.1 - - [09/Nov/2020 12:56:27] "[37mGET /scisat/_dash-component-suites/dash_renderer/react@16.v1_5_1m1593873890.13.0.min.js HTTP/1.1[0m" 200 -
INFO:werkzeug:127.0.0.1 - - [09/Nov/2020 12:56:27] "[37mGET /scisat/_dash-component-suites/dash_renderer/react-dom@16.v1_5_1m1593873890.13.0.min.js HTTP/1.1[0m" 200 -
INFO:werkzeug:127.0.0.1 - - [09/Nov/2020 12:56:27] "[37mGET /scisat/_dash-component-suites/dash_renderer/prop-types@15.v1_5_1m1593873890.7.2.min.js HTTP/1.1[0m" 200 -
INFO:werkzeug:127.0.0.1 - - [09/Nov/2020 12:56:27] "[37mGET /scisat/_dash-component-suites/dash_dangerously_set_inner_html/bundle.v0_0_2m1593870401.js HTTP/1.1[0m" 200 -
INFO:werkzeug:127.0.0.1 - - [09/Nov/2020 12:56:27] "[37mGET /scisat/_dash-component-suites/dash_html_components/dash_html_components.v1_0_3m1593873891.min.js HTTP/1.1[0m" 200 -
INFO:werkzeug:127.0.0.1 - - [09/Nov/2020 12:56:27] "[37mGET /scisat/_dash-component-suites/dash_core_components/dash_core_components.v1_10_1m1593873890.min.js HTTP/1.1[0m" 200 -
INFO:werkzeug:127.0.0.1 - - [09/Nov/2020 12:56:27] "[37mGET /scisat/_dash-component-suites/dash_core_components/dash_core_components-shared.v1_10_1m1593873890.js HTTP/1.1[0m" 200 -
INFO:werkzeug:127.0.0.1 - - [09/Nov/2020 12:56:27] "[37mGET /scisat/_dash-component-suites/dash_renderer/dash_renderer.v1_5_1m1593873890.min.js HTTP/1.1[0m" 200 -
INFO:werkzeug:127.0.0.1 - - [09/Nov/2020 12:56:28] "[37mGET /scisat/_dash-layout HTTP/1.1[0m" 200 -
INFO:werkzeug:127.0.0.1 - - [09/Nov/2020 12:56:28] "[37mGET /scisat/_dash-dependencies HTTP/1.1[0m" 200 -
INFO:werkzeug:127.0.0.1 - - [09/Nov/2020 12:56:28] "[37mGET /scisat/assets/favicon.ico?m=1604944546.4277616 HTTP/1.1[0m" 200 -
ERROR:scisat_app.scisat:Exception on /_dash-update-component [POST]
Traceback (most recent call last):
  File "C:\ProgramData\Anaconda3\lib\site-packages\flask\app.py", line 2446, in wsgi_app
    response = self.full_dispatch_request()
  File "C:\ProgramData\Anaconda3\lib\site-packages\flask\app.py", line 1951, in full_dispatch_request
    rv = self.handle_user_exception(e)
  File "C:\ProgramData\Anaconda3\lib\site-packages\flask\app.py", line 1820, in handle_user_exception
    reraise(exc_type, exc_value, tb)
  File "C:\ProgramData\Anaconda3\lib\site-packages\flask\_compat.py", line 39, in reraise
    raise value
  File "C:\ProgramData\Anaconda3\lib\site-packages\flask\app.py", line 1949, in full_dispatch_request
    rv = self.dispatch_request()
  File "C:\ProgramData\Anaconda3\lib\site-packages\flask\app.py", line 1935, in dispatch_request
    return self.view_functions[rule.endpoint](**req.view_args)
  File "C:\ProgramData\Anaconda3\lib\site-packages\dash\dash.py", line 1072, in dispatch
    response.set_data(func(*args, outputs_list=outputs_list))
  File "C:\ProgramData\Anaconda3\lib\site-packages\dash\dash.py", line 1007, in add_context
    output_value = func(*args, **kwargs)  # %% callback invoked %%
  File "C:\Users\joeda\OneDrive\Documents\GitHub\Scisat-App\scisat_app\scisat.py", line 671, in update_picker
    df =data_reader(gaz_list,r'data')
  File "C:\Users\joeda\OneDrive\Documents\GitHub\Scisat-App\scisat_app\scisat.py", line 75, in data_reader
    nc = netcdf.netcdf_file(name,'r')
  File "C:\ProgramData\Anaconda3\lib\site-packages\scipy\io\netcdf.py", line 249, in __init__
    self.fp = open(self.filename, '%sb' % omode)
FileNotFoundError: [Errno 2] No such file or directory: 'data//ACEFTS_L2_v4p1_O3.nc'
INFO:werkzeug:127.0.0.1 - - [09/Nov/2020 12:56:28] "[1m[35mPOST /scisat/_dash-update-component HTTP/1.1[0m" 500 -
ERROR:scisat_app.scisat:Exception on /_dash-update-component [POST]
Traceback (most recent call last):
  File "C:\ProgramData\Anaconda3\lib\site-packages\flask\app.py", line 2446, in wsgi_app
    response = self.full_dispatch_request()
  File "C:\ProgramData\Anaconda3\lib\site-packages\flask\app.py", line 1951, in full_dispatch_request
    rv = self.handle_user_exception(e)
  File "C:\ProgramData\Anaconda3\lib\site-packages\flask\app.py", line 1820, in handle_user_exception
    reraise(exc_type, exc_value, tb)
  File "C:\ProgramData\Anaconda3\lib\site-packages\flask\_compat.py", line 39, in reraise
    raise value
  File "C:\ProgramData\Anaconda3\lib\site-packages\flask\app.py", line 1949, in full_dispatch_request
    rv = self.dispatch_request()
  File "C:\ProgramData\Anaconda3\lib\site-packages\flask\app.py", line 1935, in dispatch_request
    return self.view_functions[rule.endpoint](**req.view_args)
  File "C:\ProgramData\Anaconda3\lib\site-packages\dash\dash.py", line 1072, in dispatch
    response.set_data(func(*args, outputs_list=outputs_list))
  File "C:\ProgramData\Anaconda3\lib\site-packages\dash\dash.py", line 1007, in add_context
    output_value = func(*args, **kwargs)  # %% callback invoked %%
  File "C:\Users\joeda\OneDrive\Documents\GitHub\Scisat-App\scisat_app\scisat.py", line 1677, in update_language_button
    language = session['language']
  File "C:\ProgramData\Anaconda3\lib\site-packages\werkzeug\local.py", line 378, in <lambda>
    __getitem__ = lambda x, i: x._get_current_object()[i]
  File "C:\ProgramData\Anaconda3\lib\site-packages\flask\sessions.py", line 84, in __getitem__
    return super(SecureCookieSession, self).__getitem__(key)
KeyError: 'language'
INFO:werkzeug:127.0.0.1 - - [09/Nov/2020 12:56:28] "[1m[35mPOST /scisat/_dash-update-component HTTP/1.1[0m" 500 -
INFO:werkzeug:127.0.0.1 - - [09/Nov/2020 12:56:28] "[37mPOST /scisat/_dash-update-component HTTP/1.1[0m" 200 -
INFO:werkzeug:127.0.0.1 - - [09/Nov/2020 12:56:28] "[37mPOST /scisat/_dash-update-component HTTP/1.1[0m" 200 -
INFO:werkzeug:127.0.0.1 - - [09/Nov/2020 12:56:28] "[37mGET /scisat/assets/csa-logo.png HTTP/1.1[0m" 200 -
INFO:werkzeug:127.0.0.1 - - [09/Nov/2020 12:56:28] "[37mPOST /scisat/_dash-update-component HTTP/1.1[0m" 200 -
INFO:werkzeug:127.0.0.1 - - [09/Nov/2020 12:56:29] "[37mPOST /scisat/_dash-update-component HTTP/1.1[0m" 200 -
ERROR:scisat_app.scisat:Exception on /_dash-update-component [POST]
Traceback (most recent call last):
  File "C:\ProgramData\Anaconda3\lib\site-packages\flask\app.py", line 2446, in wsgi_app
    response = self.full_dispatch_request()
  File "C:\ProgramData\Anaconda3\lib\site-packages\flask\app.py", line 1951, in full_dispatch_request
    rv = self.handle_user_exception(e)
  File "C:\ProgramData\Anaconda3\lib\site-packages\flask\app.py", line 1820, in handle_user_exception
    reraise(exc_type, exc_value, tb)
  File "C:\ProgramData\Anaconda3\lib\site-packages\flask\_compat.py", line 39, in reraise
    raise value
  File "C:\ProgramData\Anaconda3\lib\site-packages\flask\app.py", line 1949, in full_dispatch_request
    rv = self.dispatch_request()
  File "C:\ProgramData\Anaconda3\lib\site-packages\flask\app.py", line 1935, in dispatch_request
    return self.view_functions[rule.endpoint](**req.view_args)
  File "C:\ProgramData\Anaconda3\lib\site-packages\dash\dash.py", line 1072, in dispatch
    response.set_data(func(*args, outputs_list=outputs_list))
  File "C:\ProgramData\Anaconda3\lib\site-packages\dash\dash.py", line 1007, in add_context
    output_value = func(*args, **kwargs)  # %% callback invoked %%
  File "C:\Users\joeda\OneDrive\Documents\GitHub\Scisat-App\scisat_app\scisat.py", line 1190, in make_viz_chart
    df =data_reader(gaz_list,r'data',start_date,end_date,lat_min,lat_max,lon_min,lon_max,alt_range)
  File "C:\Users\joeda\OneDrive\Documents\GitHub\Scisat-App\scisat_app\scisat.py", line 75, in data_reader
    nc = netcdf.netcdf_file(name,'r')
  File "C:\ProgramData\Anaconda3\lib\site-packages\scipy\io\netcdf.py", line 249, in __init__
    self.fp = open(self.filename, '%sb' % omode)
FileNotFoundError: [Errno 2] No such file or directory: 'data//ACEFTS_L2_v4p1_O3.nc'
INFO:werkzeug:127.0.0.1 - - [09/Nov/2020 12:56:29] "[1m[35mPOST /scisat/_dash-update-component HTTP/1.1[0m" 500 -
ERROR:scisat_app.scisat:Exception on /_dash-update-component [POST]
Traceback (most recent call last):
  File "C:\ProgramData\Anaconda3\lib\site-packages\flask\app.py", line 2446, in wsgi_app
    response = self.full_dispatch_request()
  File "C:\ProgramData\Anaconda3\lib\site-packages\flask\app.py", line 1951, in full_dispatch_request
    rv = self.handle_user_exception(e)
  File "C:\ProgramData\Anaconda3\lib\site-packages\flask\app.py", line 1820, in handle_user_exception
    reraise(exc_type, exc_value, tb)
  File "C:\ProgramData\Anaconda3\lib\site-packages\flask\_compat.py", line 39, in reraise
    raise value
  File "C:\ProgramData\Anaconda3\lib\site-packages\flask\app.py", line 1949, in full_dispatch_request
    rv = self.dispatch_request()
  File "C:\ProgramData\Anaconda3\lib\site-packages\flask\app.py", line 1935, in dispatch_request
    return self.view_functions[rule.endpoint](**req.view_args)
  File "C:\ProgramData\Anaconda3\lib\site-packages\dash\dash.py", line 1072, in dispatch
    response.set_data(func(*args, outputs_list=outputs_list))
  File "C:\ProgramData\Anaconda3\lib\site-packages\dash\dash.py", line 1007, in add_context
    output_value = func(*args, **kwargs)  # %% callback invoked %%
  File "C:\Users\joeda\OneDrive\Documents\GitHub\Scisat-App\scisat_app\scisat.py", line 1075, in generate_geo_map
    df = data_reader(gaz_list,r'data',start_date,end_date,lat_min,lat_max,lon_min,lon_max,alt_range)
  File "C:\Users\joeda\OneDrive\Documents\GitHub\Scisat-App\scisat_app\scisat.py", line 75, in data_reader
    nc = netcdf.netcdf_file(name,'r')
  File "C:\ProgramData\Anaconda3\lib\site-packages\scipy\io\netcdf.py", line 249, in __init__
    self.fp = open(self.filename, '%sb' % omode)
FileNotFoundError: [Errno 2] No such file or directory: 'data//ACEFTS_L2_v4p1_O3.nc'
INFO:werkzeug:127.0.0.1 - - [09/Nov/2020 12:56:29] "[1m[35mPOST /scisat/_dash-update-component HTTP/1.1[0m" 500 -
ERROR:scisat_app.scisat:Exception on /_dash-update-component [POST]
Traceback (most recent call last):
  File "C:\ProgramData\Anaconda3\lib\site-packages\flask\app.py", line 2446, in wsgi_app
    response = self.full_dispatch_request()
  File "C:\ProgramData\Anaconda3\lib\site-packages\flask\app.py", line 1951, in full_dispatch_request
    rv = self.handle_user_exception(e)
  File "C:\ProgramData\Anaconda3\lib\site-packages\flask\app.py", line 1820, in handle_user_exception
    reraise(exc_type, exc_value, tb)
  File "C:\ProgramData\Anaconda3\lib\site-packages\flask\_compat.py", line 39, in reraise
    raise value
  File "C:\ProgramData\Anaconda3\lib\site-packages\flask\app.py", line 1949, in full_dispatch_request
    rv = self.dispatch_request()
  File "C:\ProgramData\Anaconda3\lib\site-packages\flask\app.py", line 1935, in dispatch_request
    return self.view_functions[rule.endpoint](**req.view_args)
  File "C:\ProgramData\Anaconda3\lib\site-packages\dash\dash.py", line 1072, in dispatch
    response.set_data(func(*args, outputs_list=outputs_list))
  File "C:\ProgramData\Anaconda3\lib\site-packages\dash\dash.py", line 1007, in add_context
    output_value = func(*args, **kwargs)  # %% callback invoked %%
  File "C:\Users\joeda\OneDrive\Documents\GitHub\Scisat-App\scisat_app\scisat.py", line 961, in make_count_figure
    df =data_reader(gaz_list,r'data',start_date,end_date,lat_min,lat_max,lon_min,lon_max,alt_range)
  File "C:\Users\joeda\OneDrive\Documents\GitHub\Scisat-App\scisat_app\scisat.py", line 75, in data_reader
    nc = netcdf.netcdf_file(name,'r')
  File "C:\ProgramData\Anaconda3\lib\site-packages\scipy\io\netcdf.py", line 249, in __init__
    self.fp = open(self.filename, '%sb' % omode)
FileNotFoundError: [Errno 2] No such file or directory: 'data//ACEFTS_L2_v4p1_O3.nc'
INFO:werkzeug:127.0.0.1 - - [09/Nov/2020 12:56:29] "[1m[35mPOST /scisat/_dash-update-component HTTP/1.1[0m" 500 -
INFO:werkzeug:127.0.0.1 - - [09/Nov/2020 12:56:29] "[37mPOST /scisat/_dash-update-component HTTP/1.1[0m" 200 -
ERROR:scisat_app.scisat:Exception on /_dash-update-component [POST]
Traceback (most recent call last):
  File "C:\ProgramData\Anaconda3\lib\site-packages\flask\app.py", line 2446, in wsgi_app
    response = self.full_dispatch_request()
  File "C:\ProgramData\Anaconda3\lib\site-packages\flask\app.py", line 1951, in full_dispatch_request
    rv = self.handle_user_exception(e)
  File "C:\ProgramData\Anaconda3\lib\site-packages\flask\app.py", line 1820, in handle_user_exception
    reraise(exc_type, exc_value, tb)
  File "C:\ProgramData\Anaconda3\lib\site-packages\flask\_compat.py", line 39, in reraise
    raise value
  File "C:\ProgramData\Anaconda3\lib\site-packages\flask\app.py", line 1949, in full_dispatch_request
    rv = self.dispatch_request()
  File "C:\ProgramData\Anaconda3\lib\site-packages\flask\app.py", line 1935, in dispatch_request
    return self.view_functions[rule.endpoint](**req.view_args)
  File "C:\ProgramData\Anaconda3\lib\site-packages\dash\dash.py", line 1072, in dispatch
    response.set_data(func(*args, outputs_list=outputs_list))
  File "C:\ProgramData\Anaconda3\lib\site-packages\dash\dash.py", line 1007, in add_context
    output_value = func(*args, **kwargs)  # %% callback invoked %%
  File "C:\Users\joeda\OneDrive\Documents\GitHub\Scisat-App\scisat_app\scisat.py", line 656, in update_filtering_text
    df =data_reader(gaz_list,r'data',start_date,end_date,lat_min,lat_max,lon_min,lon_max,alt_range)
  File "C:\Users\joeda\OneDrive\Documents\GitHub\Scisat-App\scisat_app\scisat.py", line 75, in data_reader
    nc = netcdf.netcdf_file(name,'r')
  File "C:\ProgramData\Anaconda3\lib\site-packages\scipy\io\netcdf.py", line 249, in __init__
    self.fp = open(self.filename, '%sb' % omode)
FileNotFoundError: [Errno 2] No such file or directory: 'data//ACEFTS_L2_v4p1_O3.nc'
INFO:werkzeug:127.0.0.1 - - [09/Nov/2020 12:56:29] "[1m[35mPOST /scisat/_dash-update-component HTTP/1.1[0m" 500 -
